Workbook

Sheet INFORME CAMPAÑA 24-25
D10: INFORME DE CAMPAÑA DE LA SITUACIÓN DE MERCADO DEL SECTOR DEL ACEITE DE OLIVA
G15: CAMPAÑA 2024/25
G18: Datos a 30 de septiembre de 2025 con fecha de cierre a 7 de mayo de 2026
A24: El Sistema de Información de los Mercados Oleícolas (SIMO) es un sistema de información en base informática, gestionado por el MAPA a través de la Agencia de Información y Control Alimentarios (AICA), que contiene el censo nacional de instalaciones y operadores oleícolas y la información de mercados resultante de las declaraciones obligatorias establecidas en el Real Decreto 861/2018, de 13 de julio. El presente INFORME MENSUAL pone a disposición de la totalidad del sector olivarero los datos consolidados de mercado de aceite de oliva, aceite de orujo de oliva y aceituna de mesa relativos al mes anterior al que se realiza esta publicación.
A36: Aviso legal: Esta información puede ser utilizada en parte o en su integridad, sin necesidad de autorización expresa, siempre que se cite la fuente de los documentos objeto de la reutilización.
A38: Elaboración: Subdirección General de Cultivos Herbáceos, Industriales y Aceite de Oliva. Dirección General de Producciones y Mercados Agrarios. Ministerio de Agricultura, Pesca y Alimentación.
A42: Título: Informe Mensual de Situación de Mercado del Aceite de Oliva y la Aceituna de Mesa.
A43: NIPO: 003-25-020-0
A44: Catálogo de Publicaciones de la Administración General del Estado: https://cpage.mpr.gob.es/

Sheet 01_BALANCE EXISTENCIAS FÍSICAS
D2: 01_BALANCE DE EXISTENCIAS FÍSICAS
B6: MES | C6: EXIST. INICIALES | D6: PRODUCCION | E6: IMPORTACIONES | F6: CONSUMO INTERIOR | G6: EXPORTACIONES | H6: EXIST. FINALES
B8: OCTUBRE | C8: 186.86893 | D8: 36.869638 | E8: 15.916 | F8: 38.408902 | G8: 60.278 | H8: 140.94939
B9: NOVIEMBRE | C9: 140.94939 | D9: 266.67029 | E9: 23.576 | F9: 40.438747 | G9: 59.937 | H9: 330.81993
B10: DICIEMBRE | C10: 330.81993 | D10: 596.431 | E10: 30.592 | F10: 54.22504 | G10: 69.723 | H10: 833.89489
B11: ENERO | C11: 833.89489 | D11: 351.4809 | E11: 17.385 | F11: 49.430284 | G11: 89.304 | H11: 1064.0265
B12: FEBRERO | C12: 1064.0265 | D12: 154.0704 | E12: 19.042 | F12: 40.568917 | G12: 90.628 | H12: 1105.942
B13: MARZO | C13: 1105.942 | D13: 12.203774 | E13: 22.052 | F13: 43.606514 | G13: 96.981 | H13: 999.61025
B14: ABRIL | C14: 999.61025 | D14: 3.1651061 | E14: 16.635 | F14: 35.672966 | G14: 98.778 | H14: 884.95939
B15: MAYO | C15: 884.95939 | D15: 0.22164383 | E15: 15.277 | F15: 36.885764 | G15: 99.324 | H15: 764.24827
B16: JUNIO | C16: 764.24827 | E16: 14.541 | F16: 37.95556 | G16: 94.483 | H16: 646.35071
B17: JULIO | C17: 646.35071 | E17: 13.11 | F17: 37.73618 | G17: 110.997 | H17: 510.72753
B18: AGOSTO | C18: 510.72753 | E18: 6.765 | F18: 35.51266 | G18: 76.051 | H18: 405.92887
B19: SEPTIEMBRE | C19: 405.92887 | E19: 11.168 | F19: 32.3375 | G19: 95.087 | H19: 289.67237
D20: =+SUM(D8:D19) -> 1421.1127 | E20: =+SUM(E8:E19) -> 206.059 | F20: =+SUM(F8:F19) -> 482.77903 | G20: =+SUM(G8:G19) -> 1041.571
C22: DATOS PROVISIONALES | F22: TOTAL MERCADO: | G22: =F20+G20 -> 1524.35
B24: EXPORTACIONES | E24: EXPORTACIONES
C25: EXPORTACIONES | E25: PAÍSES TERCEROS | F25: UE
F26: ITALIA | G26: OTROS
B27: OCTUBRE | C27: 60.278 | E27: 24.628 | F27: 15.303 | G27: 20.347
B28: NOVIEMBRE | C28: 59.937 | E28: 24.653 | F28: 18.091 | G28: 17.193
B29: DICIEMBRE | C29: 69.723 | E29: 25.108 | F29: 26.024 | G29: 18.591
B30: ENERO | C30: 89.304 | E30: 32.066 | F30: 33.999 | G30: 23.239
B31: FEBRERO | C31: 90.628 | E31: 35.656 | F31: 31.253 | G31: 23.719
B32: MARZO | C32: 96.981 | E32: 41.824 | F32: 33.686 | G32: 21.471
B33: ABRIL | C33: 98.778 | E33: 40.891 | F33: 30.201 | G33: 27.686
B34: MAYO | C34: 99.324 | E34: 41.137 | F34: 29.777 | G34: 28.41
B35: JUNIO | C35: 94.483 | E35: 39.954 | F35: 26.467 | G35: 28.062
B36: JULIO | C36: 110.997 | E36: 43.427 | F36: 37.361 | G36: 30.209
B37: AGOSTO | C37: 76.051 | E37: 27.872 | F37: 23.861 | G37: 24.318
B38: SEPTIEMBRE | C38: 95.087 | E38: 38.944 | F38: 26.324 | G38: 29.819
C39: =+SUM(C27:C38) -> 1041.571 | E39: =+SUM(E27:E38) -> 416.16 | F39: =+SUM(F27:F38) -> 332.347 | G39: =+SUM(G27:G38) -> 293.064
E40: =SUM(E39:G39) -> 1041.571
B43: TOTAL MERCADO INTERIOR APARENTE | E43: IMPORTACIONES
C44: TOTAL | E44: PAÍSES TERCEROS | F44: UE
F45: ITALIA | G45: OTROS
B46: OCTUBRE | C46: 38.408902 | E46: 7.909 | F46: 0.927 | G46: 7.08
B47: NOVIEMBRE | C47: 40.438747 | E47: 2.871 | F47: 0.319 | G47: 20.386
B48: DICIEMBRE | C48: 54.22504 | E48: 6.03 | F48: 3.023 | G48: 21.539
B49: ENERO | C49: 49.430284 | E49: 6.986 | F49: 0.813 | G49: 9.586
...

Sheet 02_CUADRYGRÁF.COMP.ÚLT.5 CAMP.
D2: 02_CUADROS Y GRÁFICOS COMPARATIVOS
C6: PRODUCCIÓN | I6: PRODUCCIÓN
C7: 2020/21 | D7: 2021/22 | E7: 2022/23 | F7: 2023/24 | G7: 2024/25
B8: OCTUBRE | C8: 38.3 | D8: 51.3461 | E8: 30.6714 | F8: 38.6693 | G8: 36.869638
B9: NOVIEMBRE | C9: 244.7 | D9: 288.1698 | E9: 169.0176 | F9: 230.0143 | G9: 266.67029
B10: DICIEMBRE | C10: 475.3 | D10: 542.71 | E10: 238.8635 | F10: 328.4806 | G10: 596.431
B11: ENERO | C11: 352.1 | D11: 471.1874 | E11: 182.3524 | F11: 188.1869 | G11: 351.4809
B12: FEBRERO | C12: 227.4 | D12: 108.8072 | E12: 36.0774 | F12: 53.142 | G12: 154.0704
B13: MARZO | C13: 44.6 | D13: 20.7576 | E13: 8.0173 | F13: 14.0971 | G13: 12.203774
B14: ABRIL | C14: 3.1 | D14: 7.1167 | E14: 0.9722 | F14: 2.7941 | G14: 3.1651061
B15: MAYO | C15: 4.5 | D15: 2.9136 | E15: 0.0409 | F15: 0.1924 | G15: 0.22164383
B16: JUNIO
B17: JULIO
B18: AGOSTO
B19: SEPTIEMBRE
C20: =+SUM(C8:C19) -> 1390 | D20: =+SUM(D8:D19) -> 1493.0084 | E20: =+SUM(E8:E19) -> 666.0127 | F20: =+SUM(F8:F19) -> 855.5767 | G20: =+SUM(G8:G19) -> 1421.1127
C23: IMPORTACIONES | I23: IMPORTACIONES
C24: 2020/21 | D24: 2021/22 | E24: 2022/23 | F24: 2023/24 | G24: 2024/25
B25: OCTUBRE | C25: 18.4 | D25: 12.69769 | E25: 13.250511 | F25: 14.465849 | G25: 15.916
B26: NOVIEMBRE | C26: 20.1 | D26: 18.94698 | E26: 22.196355 | F26: 28.280685 | G26: 23.576
B27: DICIEMBRE | C27: 20.9 | D27: 35.59424 | E27: 35.413639 | F27: 26.757532 | G27: 30.592
B28: ENERO | C28: 11.7 | D28: 12.83714 | E28: 13.040041 | F28: 18.214635 | G28: 17.385
B29: FEBRERO | C29: 16.7 | D29: 17.4196 | E29: 19.216602 | F29: 20.514472 | G29: 19.042
B30: MARZO | C30: 17.8 | D30: 12.03758 | E30: 17.429422 | F30: 21.408031 | G30: 22.052
B31: ABRIL | C31: 15.5 | D31: 21.93187 | E31: 10.323654 | F31: 23.6309 | G31: 16.635
B32: MAYO | C32: 13.3 | D32: 20.42955 | E32: 14.328993 | F32: 20.321337 | G32: 15.277
B33: JUNIO | C33: 13.3 | D33: 16.47469 | E33: 16.168545 | F33: 17.351097 | G33: 14.541
B34: JULIO | C34: 10.5 | D34: 12.6548 | E34: 19.188001 | F34: 21.684971 | G34: 13.11
B35: AGOSTO | C35: 8.5 | D35: 20.24787 | E35: 14.861437 | F35: 15.398776 | G35: 6.765
B36: SEPTIEMBRE | C36: 16.2 | D36: 11.52141 | E36: 19.744252 | F36: 15.20674 | G36: 11.168
C37: =+SUM(C25:C36) -> 182.9 | D37: =+SUM(D25:D36) -> 212.79342 | E37: =+SUM(E25:E36) -> 215.16145 | F37: =+SUM(F25:F36) -> 243.23502 | G37: =+SUM(G25:G36) -> 206.059
C40: EXPORTACIONES | I40: EXPORTACIONES
C41: 2020/21 | D41: 2021/22 | E41: 2022/23 | F41: 2023/24 | G41: 2024/25
B42: OCTUBRE | C42: 95.7 | D42: 83.49778 | E42: 88.527712 | F42: 55.755136 | G42: 60.278
B43: NOVIEMBRE | C43: 95.7 | D43: 83.40845 | E43: 67.690599 | F43: 52.714599 | G43: 59.937
B44: DICIEMBRE | C44: 83.5 | D44: 81.42683 | E44: 63.56878 | F44: 59.829063 | G44: 69.723
B45: ENERO | C45: 82.5 | D45: 73.74592 | E45: 55.971191 | F45: 69.545024 | G45: 89.304
B46: FEBRERO | C46: 104.2 | D46: 88.32957 | E46: 48.263341 | F46: 64.995784 | G46: 90.628
B47: MARZO | C47: 106.8 | D47: 78.29797 | E47: 64.195956 | F47: 60.61064 | G47: 96.981
B48: ABRIL | C48: 99.4 | D48: 107.33327 | E48: 51.589896 | F48: 74.409194 | G48: 98.778
...

Sheet 03_CUADRYGRÁF.COMP.5 ÚLT.CAMP.
G2: 03_CUADROS Y GRÁFICOS COMPARATIVOS
F6: EXISTENCIAS EN ALMAZARAS Y PATRIMONIO | L6: EXISTENCIAS EN ALMAZARAS Y PATRIMONIO
F7: 2020/21 | G7: 2021/22 | H7: 2022/23 | I7: 2023/24 | J7: 2024/25
E8: OCTUBRE | F8: 195.2081 | G8: 171.77332 | H8: 155.70437 | I8: 82.32439 | J8: 54.82129
E9: NOVIEMBRE | F9: 328.364 | G9: 345.36574 | H9: 234.30274 | I9: 236.68863 | J9: 236.50213
E10: DICIEMBRE | F10: 666.362 | G10: 740.3346 | H10: 396.56389 | I10: 471.98805 | J10: 697.73919
E11: ENERO | F11: 873.1831 | G11: 1055.0071 | H11: 503.45074 | I11: 554.38471 | J11: 888.37991
E12: FEBRERO | F12: 937.9141 | G12: 1024.6867 | H12: 474.38193 | I12: 527.90193 | J12: 905.64439
E13: MARZO | F13: 824.0668 | G13: 931.13413 | H13: 409.40063 | I13: 474.62288 | J13: 788.05705
E14: ABRIL | F14: 689.4427 | G14: 796.21762 | H14: 350.80297 | I14: 399.02365 | J14: 678.02169
E15: MAYO | F15: 566.951 | G15: 664.7652 | H15: 271.39996 | I15: 320.47839 | J15: 563.77397
E16: JUNIO | F16: 470.0952 | G16: 534.84076 | H16: 211.13154 | I16: 252.31005 | J16: 449.60961
E17: JULIO | F17: 383.9202 | G17: 425.1501 | H17: 159.67197 | I17: 189.36771 | J17: 321.44963
E18: AGOSTO | F18: 315.073 | G18: 331.1421 | H18: 125.4556 | I18: 139.47251 | J18: 239.81247
E19: SEPTIEMBRE | F19: 213.12287 | G19: 227.69511 | H19: 84.41313 | I19: 78.30593 | J19: 141.15647
F23: EXISTENCIAS EN ENVASADORAS Y PATRIMONIO | L23: EXISTENCIAS EN ENVASADORAS Y PATRIMONIO
F24: 2020/21 | G24: 2021/22 | H24: 2022/23 | I24: 2023/24 | J24: 2024/25
E25: OCTUBRE | F25: 205.66723 | G25: 192.8152 | H25: 212.1038 | I25: 137.9716 | J25: 86.1281
E26: NOVIEMBRE | F26: 191.05083 | G26: 195.1934 | H26: 217.5282 | I26: 142.2327 | J26: 94.3178
E27: DICIEMBRE | F27: 203.1015 | G27: 245.3619 | H27: 242.4611 | I27: 165.082 | J27: 136.1557
E28: ENERO | F28: 234.8726 | G28: 286.8885 | H28: 260.6573 | I28: 180.8159 | J28: 175.6466
E29: FEBRERO | F29: 260.6456 | G29: 310.8052 | H29: 266.7058 | I29: 184.7597 | J29: 200.2976
E30: MARZO | F30: 278.49414 | G30: 288.1855 | H30: 262.414 | I30: 183.4505 | J30: 211.5532
E31: ABRIL | F31: 287.84617 | G31: 288.609 | H31: 259.055 | I31: 177.3172 | J31: 206.9377
E32: MAYO | F32: 290.054 | G32: 284.6648 | H32: 260.2675 | I32: 170.4718 | J32: 200.4743
E33: JUNIO | F33: 279.3005 | G33: 274.2026 | H33: 245.4191 | I33: 162.5891 | J33: 196.7411
E34: JULIO | F34: 256.5209 | G34: 272.5664 | H34: 223.768 | I34: 152.9032 | J34: 189.2779
E35: AGOSTO | F35: 230.7868 | G35: 249.8163 | H35: 195.6963 | I35: 132.1592 | J35: 166.1164
E36: SEPTIEMBRE | F36: 210.5 | G36: 226.9114 | H36: 163.8269 | I36: 108.563 | J36: 148.5159
F40: EXISTENCIAS TOTALES | L40: EXISTENCIAS TOTALES
F41: 2020/21 | G41: 2021/22 | H41: 2022/23 | I41: 2023/24 | J41: 2024/25
E42: OCTUBRE | F42: 400.87533 | G42: 364.58852 | H42: 367.80817 | I42: 220.29599 | J42: 140.94939
E43: NOVIEMBRE | F43: 519.41483 | G43: 540.55914 | H43: 451.83094 | I43: 378.92133 | J43: 330.81993
E44: DICIEMBRE | F44: 869.4635 | G44: 985.6965 | H44: 639.02499 | I44: 637.07005 | J44: 833.89489
E45: ENERO | F45: 1108.0557 | G45: 1341.8956 | H45: 764.10804 | I45: 735.20061 | J45: 1064.0265
E46: FEBRERO | F46: 1198.5597 | G46: 1335.4919 | H46: 741.08773 | I46: 712.66163 | J46: 1105.942
E47: MARZO | F47: 1102.5609 | G47: 1219.3196 | H47: 671.81463 | I47: 658.07338 | J47: 999.61025
E48: ABRIL | F48: 977.28887 | G48: 1084.8266 | H48: 609.85797 | I48: 576.34085 | J48: 884.95939
E49: MAYO | F49: 857.005 | G49: 949.43 | H49: 531.66746 | I49: 490.95019 | J49: 764.24827
E50: JUNIO | F50: 749.3957 | G50: 809.04336 | H50: 456.55064 | I50: 414.89915 | J50: 646.35071
...

Sheet 04_CUADROS ACUMULADOS
E2: 04_CUADROS ACUMULADOS
D6: PRODUCCIÓN ACUMULADA
D7: 2020/21 | E7: 2021/22 | F7: 2022/23 | G7: 2023/24 | H7: 2024/25 | I7: % 2024/25 s. 2023/24 | J7: % 2024/25 s. Media tres | K7: % 2024/25 s. Media cuatro
C8: OCTUBRE | D8: 38.3 | E8: 51.3461 | F8: 30.6714 | G8: 38.6693 | H8: 36.869638 | I8: =IF(ISNUMBER(H8),H8/G8-1,"") -> -0.046539812 | J8: =IF(ISNUMBER(H8),H8/AVERAGE(E8:G8)-1,"") -> -0.083504458 | K8: =IF(ISNUMBER(H8),H8/AVERAGE(D8:G8)-1,"") -> -0.072384926
C9: NOVIEMBRE | D9: 283 | E9: 339.5159 | F9: 199.689 | G9: 268.6836 | H9: 303.53993 | I9: =IF(ISNUMBER(H9),H9/G9-1,"") -> 0.12973001 | J9: =IF(ISNUMBER(H9),H9/AVERAGE(E9:G9)-1,"") -> 0.12716022 | K9: =IF(ISNUMBER(H9),H9/AVERAGE(D9:G9)-1,"") -> 0.11300073
C10: DICIEMBRE | D10: 758.3 | E10: 882.2259 | F10: 438.5525 | G10: 597.1642 | H10: 899.97093 | I10: =IF(ISNUMBER(H10),H10/G10-1,"") -> 0.50707448 | J10: =IF(ISNUMBER(H10),H10/AVERAGE(E10:G10)-1,"") -> 0.40771302 | K10: =IF(ISNUMBER(H10),H10/AVERAGE(D10:G10)-1,"") -> 0.34512607
C11: ENERO | D11: 1110.4 | E11: 1353.4133 | F11: 620.9049 | G11: 785.3511 | H11: 1251.4518 | I11: =IF(ISNUMBER(H11),H11/G11-1,"") -> 0.59349344 | J11: =IF(ISNUMBER(H11),H11/AVERAGE(E11:G11)-1,"") -> 0.36043673 | K11: =IF(ISNUMBER(H11),H11/AVERAGE(D11:G11)-1,"") -> 0.2934671
C12: FEBRERO | D12: 1337.8 | E12: 1462.2205 | F12: 656.9823 | G12: 838.4931 | H12: 1405.5222 | I12: =IF(ISNUMBER(H12),H12/G12-1,"") -> 0.67624781 | J12: =IF(ISNUMBER(H12),H12/AVERAGE(E12:G12)-1,"") -> 0.42562549 | K12: =IF(ISNUMBER(H12),H12/AVERAGE(D12:G12)-1,"") -> 0.30883349
C13: MARZO | D13: 1382.4 | E13: 1482.9781 | F13: 664.9996 | G13: 852.5902 | H13: 1417.726 | I13: =IF(ISNUMBER(H13),H13/G13-1,"") -> 0.66284576 | J13: =IF(ISNUMBER(H13),H13/AVERAGE(E13:G13)-1,"") -> 0.41745768 | K13: =IF(ISNUMBER(H13),H13/AVERAGE(D13:G13)-1,"") -> 0.29385022
C14: ABRIL | D14: 1385.5 | E14: 1490.0948 | F14: 665.9718 | G14: 855.3843 | H14: 1420.8911 | I14: =IF(ISNUMBER(H14),H14/G14-1,"") -> 0.66111432 | J14: =IF(ISNUMBER(H14),H14/AVERAGE(E14:G14)-1,"") -> 0.41548823 | K14: =IF(ISNUMBER(H14),H14/AVERAGE(D14:G14)-1,"") -> 0.29261494
C15: MAYO | D15: 1390 | E15: 1493.0084 | F15: 666.0127 | G15: 855.5767 | H15: 1421.1127 | I15: =IF(ISNUMBER(H15),H15/G15-1,"") -> 0.66099983 | J15: =IF(ISNUMBER(H15),H15/AVERAGE(E15:G15)-1,"") -> 0.4142312 | K15: =IF(ISNUMBER(H15),H15/AVERAGE(D15:G15)-1,"") -> 0.29057209
C16: JUNIO | D16: 1390 | E16: 1493.0084 | F16: 666.0127 | G16: 855.5767 | H16: 1421.1127 | I16: =IF(ISNUMBER(H16),H16/G16-1,"") -> 0.66099983 | J16: =IF(ISNUMBER(H16),H16/AVERAGE(E16:G16)-1,"") -> 0.4142312 | K16: =IF(ISNUMBER(H16),H16/AVERAGE(D16:G16)-1,"") -> 0.29057209
C17: JULIO | D17: 1390 | E17: 1493.0084 | F17: 666.0127 | G17: 855.5767 | H17: 1421.1127 | I17: =IF(ISNUMBER(H17),H17/G17-1,"") -> 0.66099983 | J17: =IF(ISNUMBER(H17),H17/AVERAGE(E17:G17)-1,"") -> 0.4142312 | K17: =IF(ISNUMBER(H17),H17/AVERAGE(D17:G17)-1,"") -> 0.29057209
C18: AGOSTO | D18: 1390 | E18: 1493.0084 | F18: 666.0127 | G18: 855.5767 | H18: 1421.1127 | I18: =IF(ISNUMBER(H18),H18/G18-1,"") -> 0.66099983 | J18: =IF(ISNUMBER(H18),H18/AVERAGE(E18:G18)-1,"") -> 0.4142312 | K18: =IF(ISNUMBER(H18),H18/AVERAGE(D18:G18)-1,"") -> 0.29057209
C19: SEPTIEMBRE | D19: 1390 | E19: 1493.0084 | F19: 666.0127 | G19: 855.5767 | H19: 1421.1127 | I19: =IF(ISNUMBER(H19),H19/G19-1,"") -> 0.66099983 | J19: =IF(ISNUMBER(H19),H19/AVERAGE(E19:G19)-1,"") -> 0.4142312 | K19: =IF(ISNUMBER(H19),H19/AVERAGE(D19:G19)-1,"") -> 0.29057209
D22: IMPORTACIÓN ACUMULADA
D23: 2020/21 | E23: 2021/22 | F23: 2022/23 | G23: 2023/24 | H23: 2024/25 | I23: % 2024/25 s. 2023/24 | J23: % 2024/25 s. Media tres | K23: % 2024/25 s. Media cuatro
C24: OCTUBRE | D24: 18.4 | E24: 12.69769 | F24: 13.250511 | G24: 14.465849 | H24: 15.916 | I24: =IF(ISNUMBER(H24),H24/G24-1,"") -> 0.10024652 | J24: =IF(ISNUMBER(H24),H24/AVERAGE(E24:G24)-1,"") -> 0.18147031 | K24: =IF(ISNUMBER(H24),H24/AVERAGE(D24:G24)-1,"") -> 0.082462439
C25: NOVIEMBRE | D25: 38.5 | E25: 31.64467 | F25: 35.446866 | G25: 42.746534 | H25: 39.492 | I25: =IF(ISNUMBER(H25),H25/G25-1,"") -> -0.076135623 | J25: =IF(ISNUMBER(H25),H25/AVERAGE(E25:G25)-1,"") -> 0.078642405 | K25: =IF(ISNUMBER(H25),H25/AVERAGE(D25:G25)-1,"") -> 0.064918803
C26: DICIEMBRE | D26: 59.4 | E26: 67.23891 | F26: 70.860505 | G26: 69.504066 | H26: 70.084 | I26: =IF(ISNUMBER(H26),H26/G26-1,"") -> 0.008343886 | J26: =IF(ISNUMBER(H26),H26/AVERAGE(E26:G26)-1,"") -> 0.012757585 | K26: =IF(ISNUMBER(H26),H26/AVERAGE(D26:G26)-1,"") -> 0.049933877
C27: ENERO | D27: 71.1 | E27: 80.07605 | F27: 83.900546 | G27: 87.718701 | H27: 87.469 | I27: =IF(ISNUMBER(H27),H27/G27-1,"") -> -0.0028466108 | J27: =IF(ISNUMBER(H27),H27/AVERAGE(E27:G27)-1,"") -> 0.042558217 | K27: =IF(ISNUMBER(H27),H27/AVERAGE(D27:G27)-1,"") -> 0.083894354
C28: FEBRERO | D28: 87.8 | E28: 97.49565 | F28: 103.11715 | G28: 108.23317 | H28: 106.511 | I28: =IF(ISNUMBER(H28),H28/G28-1,"") -> -0.015911693 | J28: =IF(ISNUMBER(H28),H28/AVERAGE(E28:G28)-1,"") -> 0.034603103 | K28: =IF(ISNUMBER(H28),H28/AVERAGE(D28:G28)-1,"") -> 0.074116545
C29: MARZO | D29: 105.6 | E29: 109.53323 | F29: 120.54657 | G29: 129.6412 | H29: 128.563 | I29: =IF(ISNUMBER(H29),H29/G29-1,"") -> -0.0083168311 | J29: =IF(ISNUMBER(H29),H29/AVERAGE(E29:G29)-1,"") -> 0.072189268 | K29: =IF(ISNUMBER(H29),H29/AVERAGE(D29:G29)-1,"") -> 0.10515536
C30: ABRIL | D30: 121.1 | E30: 131.4651 | F30: 130.87022 | G30: 153.2721 | H30: 145.198 | I30: =IF(ISNUMBER(H30),H30/G30-1,"") -> -0.052678236 | J30: =IF(ISNUMBER(H30),H30/AVERAGE(E30:G30)-1,"") -> 0.048090026 | K30: =IF(ISNUMBER(H30),H30/AVERAGE(D30:G30)-1,"") -> 0.082138927
C31: MAYO | D31: 134.4 | E31: 151.89465 | F31: 145.19922 | G31: 173.59344 | H31: 160.475 | I31: =IF(ISNUMBER(H31),H31/G31-1,"") -> -0.075569912 | J31: =IF(ISNUMBER(H31),H31/AVERAGE(E31:G31)-1,"") -> 0.022812793 | K31: =IF(ISNUMBER(H31),H31/AVERAGE(D31:G31)-1,"") -> 0.060838645
C32: JUNIO | D32: 147.7 | E32: 168.36934 | F32: 161.36776 | G32: 190.94454 | H32: 175.016 | I32: =IF(ISNUMBER(H32),H32/G32-1,"") -> -0.08341971 | J32: =IF(ISNUMBER(H32),H32/AVERAGE(E32:G32)-1,"") -> 0.0083858536 | K32: =IF(ISNUMBER(H32),H32/AVERAGE(D32:G32)-1,"") -> 0.047401601
C33: JULIO | D33: 158.2 | E33: 181.02414 | F33: 180.55576 | G33: 212.62951 | H33: 188.126 | I33: =IF(ISNUMBER(H33),H33/G33-1,"") -> -0.1152404 | J33: =IF(ISNUMBER(H33),H33/AVERAGE(E33:G33)-1,"") -> -0.017121649 | K33: =IF(ISNUMBER(H33),H33/AVERAGE(D33:G33)-1,"") -> 0.027436278
C34: AGOSTO | D34: 166.7 | E34: 201.27201 | F34: 195.4172 | G34: 228.02828 | H34: 194.891 | I34: =IF(ISNUMBER(H34),H34/G34-1,"") -> -0.14532094 | J34: =IF(ISNUMBER(H34),H34/AVERAGE(E34:G34)-1,"") -> -0.064100166 | K34: =IF(ISNUMBER(H34),H34/AVERAGE(D34:G34)-1,"") -> -0.01497755
C35: SEPTIEMBRE | D35: 182.9 | E35: 212.79342 | F35: 215.16145 | G35: 243.23502 | H35: 206.059 | I35: =IF(ISNUMBER(H35),H35/G35-1,"") -> -0.15283993 | J35: =IF(ISNUMBER(H35),H35/AVERAGE(E35:G35)-1,"") -> -0.078983455 | K35: =IF(ISNUMBER(H35),H35/AVERAGE(D35:G35)-1,"") -> -0.034954045
D38: EXPORTACIÓN ACUMULADA
D39: 2020/21 | E39: 2021/22 | F39: 2022/23 | G39: 2023/24 | H39: 2024/25 | I39: % 2024/25 s. 2023/24 | J39: % 2024/25 s. Media tres | K39: % 2024/25 s. Media cuatro
C40: OCTUBRE | D40: 95.7 | E40: 83.49778 | F40: 88.527712 | G40: 55.755136 | H40: 60.278 | I40: =IF(ISNUMBER(H40),H40/G40-1,"") -> 0.081120132 | J40: =IF(ISNUMBER(H40),H40/AVERAGE(E40:G40)-1,"") -> -0.20610457 | K40: =IF(ISNUMBER(H40),H40/AVERAGE(D40:G40)-1,"") -> -0.25463234
C41: NOVIEMBRE | D41: 191.4 | E41: 166.90623 | F41: 156.21831 | G41: 108.46974 | H41: 120.215 | I41: =IF(ISNUMBER(H41),H41/G41-1,"") -> 0.10828149 | J41: =IF(ISNUMBER(H41),H41/AVERAGE(E41:G41)-1,"") -> -0.16438883 | K41: =IF(ISNUMBER(H41),H41/AVERAGE(D41:G41)-1,"") -> -0.228147
C42: DICIEMBRE | D42: 274.9 | E42: 248.33306 | F42: 219.78709 | G42: 168.2988 | H42: 189.938 | I42: =IF(ISNUMBER(H42),H42/G42-1,"") -> 0.12857609 | J42: =IF(ISNUMBER(H42),H42/AVERAGE(E42:G42)-1,"") -> -0.10465582 | K42: =IF(ISNUMBER(H42),H42/AVERAGE(D42:G42)-1,"") -> -0.16631603
C43: ENERO | D43: 357.4 | E43: 322.07898 | F43: 275.75828 | G43: 237.84382 | H43: 279.242 | I43: =IF(ISNUMBER(H43),H43/G43-1,"") -> 0.17405614 | J43: =IF(ISNUMBER(H43),H43/AVERAGE(E43:G43)-1,"") -> 0.0024470053 | K43: =IF(ISNUMBER(H43),H43/AVERAGE(D43:G43)-1,"") -> -0.063795399
C44: FEBRERO | D44: 461.6 | E44: 410.40855 | F44: 324.02162 | G44: 302.83961 | H44: 369.87 | I44: =IF(ISNUMBER(H44),H44/G44-1,"") -> 0.22133959 | J44: =IF(ISNUMBER(H44),H44/AVERAGE(E44:G44)-1,"") -> 0.06974099 | K44: =IF(ISNUMBER(H44),H44/AVERAGE(D44:G44)-1,"") -> -0.012936267
C45: MARZO | D45: 568.4 | E45: 488.70652 | F45: 388.21758 | G45: 363.45025 | H45: 466.851 | I45: =IF(ISNUMBER(H45),H45/G45-1,"") -> 0.28449769 | J45: =IF(ISNUMBER(H45),H45/AVERAGE(E45:G45)-1,"") -> 0.12913735 | K45: =IF(ISNUMBER(H45),H45/AVERAGE(D45:G45)-1,"") -> 0.032414024
C46: ABRIL | D46: 667.8 | E46: 596.03979 | F46: 439.80748 | G46: 437.85944 | H46: 565.629 | I46: =IF(ISNUMBER(H46),H46/G46-1,"") -> 0.29180497 | J46: =IF(ISNUMBER(H46),H46/AVERAGE(E46:G46)-1,"") -> 0.15144146 | K46: =IF(ISNUMBER(H46),H46/AVERAGE(D46:G46)-1,"") -> 0.056506615
C47: MAYO | D47: 758.1 | E47: 713.85813 | F47: 508.06014 | G47: 510.14425 | H47: 664.953 | I47: =IF(ISNUMBER(H47),H47/G47-1,"") -> 0.30346075 | J47: =IF(ISNUMBER(H47),H47/AVERAGE(E47:G47)-1,"") -> 0.1517246 | K47: =IF(ISNUMBER(H47),H47/AVERAGE(D47:G47)-1,"") -> 0.068127876
C48: JUNIO | D48: 845.9 | E48: 817.30445 | F48: 573.12506 | G48: 576.72214 | H48: 759.436 | I48: =IF(ISNUMBER(H48),H48/G48-1,"") -> 0.31681437 | J48: =IF(ISNUMBER(H48),H48/AVERAGE(E48:G48)-1,"") -> 0.15817609 | K48: =IF(ISNUMBER(H48),H48/AVERAGE(D48:G48)-1,"") -> 0.079874947
...

Sheet 05_GRÁF.COMP.MEDIA 4 ÚLT.CAMPAÑ
B2: 05_GRÁFICOS COMPARATIVOS CON LA MEDIA DE LAS ÚLTIMAS CAMPAÑAS
B6: PRODUCCIÓN | I6: IMPORTACIONES
B7: GRÁFICO PRODUCCIÓN | I7: GRÁFICO IMPORTACIONES
C8: Mes | D8: =+'04_CUADROS ACUMULADOS'!$H$7 -> 2024/25 | E8: Media 4 últimas campañas | J8: Mes | K8: =+'04_CUADROS ACUMULADOS'!$H$7 -> 2024/25 | L8: Media 4 últimas campañas
C9: Oct | D9: =+IF('02_CUADRYGRÁF.COMP.ÚLT.5 CAMP.'!G8<>0,'02_CUADRYGRÁF.COMP.ÚLT.5 CAMP.'!G8,NA()) -> 36.869638 | E9: =+AVERAGE('02_CUADRYGRÁF.COMP.ÚLT.5 CAMP.'!C8:F8) -> 39.7467 | J9: Oct | K9: =+IF('02_CUADRYGRÁF.COMP.ÚLT.5 CAMP.'!G25<>0,'02_CUADRYGRÁF.COMP.ÚLT.5 CAMP.'!G25,NA()) -> 15.916 | L9: =+AVERAGE('02_CUADRYGRÁF.COMP.ÚLT.5 CAMP.'!C25:F25) -> 14.703513
C10: Nov | D10: =+IF('02_CUADRYGRÁF.COMP.ÚLT.5 CAMP.'!G9<>0,'02_CUADRYGRÁF.COMP.ÚLT.5 CAMP.'!G9,NA()) -> 266.67029 | E10: =+AVERAGE('02_CUADRYGRÁF.COMP.ÚLT.5 CAMP.'!C9:F9) -> 232.97542 | J10: Nov | K10: =+IF('02_CUADRYGRÁF.COMP.ÚLT.5 CAMP.'!G26<>0,'02_CUADRYGRÁF.COMP.ÚLT.5 CAMP.'!G26,NA()) -> 23.576 | L10: =+AVERAGE('02_CUADRYGRÁF.COMP.ÚLT.5 CAMP.'!C26:F26) -> 22.381005
C11: Dic | D11: =+IF('02_CUADRYGRÁF.COMP.ÚLT.5 CAMP.'!G10<>0,'02_CUADRYGRÁF.COMP.ÚLT.5 CAMP.'!G10,NA()) -> 596.431 | E11: =+AVERAGE('02_CUADRYGRÁF.COMP.ÚLT.5 CAMP.'!C10:F10) -> 396.33853 | J11: Dic | K11: =+IF('02_CUADRYGRÁF.COMP.ÚLT.5 CAMP.'!G27<>0,'02_CUADRYGRÁF.COMP.ÚLT.5 CAMP.'!G27,NA()) -> 30.592 | L11: =+AVERAGE('02_CUADRYGRÁF.COMP.ÚLT.5 CAMP.'!C27:F27) -> 29.666353
C12: Ene | D12: =+IF('02_CUADRYGRÁF.COMP.ÚLT.5 CAMP.'!G11<>0,'02_CUADRYGRÁF.COMP.ÚLT.5 CAMP.'!G11,NA()) -> 351.4809 | E12: =+AVERAGE('02_CUADRYGRÁF.COMP.ÚLT.5 CAMP.'!C11:F11) -> 298.45668 | J12: Ene | K12: =+IF('02_CUADRYGRÁF.COMP.ÚLT.5 CAMP.'!G28<>0,'02_CUADRYGRÁF.COMP.ÚLT.5 CAMP.'!G28,NA()) -> 17.385 | L12: =+AVERAGE('02_CUADRYGRÁF.COMP.ÚLT.5 CAMP.'!C28:F28) -> 13.947954
C13: Feb | D13: =+IF('02_CUADRYGRÁF.COMP.ÚLT.5 CAMP.'!G12<>0,'02_CUADRYGRÁF.COMP.ÚLT.5 CAMP.'!G12,NA()) -> 154.0704 | E13: =+AVERAGE('02_CUADRYGRÁF.COMP.ÚLT.5 CAMP.'!C12:F12) -> 106.35665 | J13: Feb | K13: =+IF('02_CUADRYGRÁF.COMP.ÚLT.5 CAMP.'!G29<>0,'02_CUADRYGRÁF.COMP.ÚLT.5 CAMP.'!G29,NA()) -> 19.042 | L13: =+AVERAGE('02_CUADRYGRÁF.COMP.ÚLT.5 CAMP.'!C29:F29) -> 18.462668
C14: Mar | D14: =+IF('02_CUADRYGRÁF.COMP.ÚLT.5 CAMP.'!G13<>0,'02_CUADRYGRÁF.COMP.ÚLT.5 CAMP.'!G13,NA()) -> 12.203774 | E14: =+AVERAGE('02_CUADRYGRÁF.COMP.ÚLT.5 CAMP.'!C13:F13) -> 21.868 | J14: Mar | K14: =+IF('02_CUADRYGRÁF.COMP.ÚLT.5 CAMP.'!G30<>0,'02_CUADRYGRÁF.COMP.ÚLT.5 CAMP.'!G30,NA()) -> 22.052 | L14: =+AVERAGE('02_CUADRYGRÁF.COMP.ÚLT.5 CAMP.'!C30:F30) -> 17.168758
C15: Abr | D15: =+IF('02_CUADRYGRÁF.COMP.ÚLT.5 CAMP.'!G14<>0,'02_CUADRYGRÁF.COMP.ÚLT.5 CAMP.'!G14,NA()) -> 3.1651061 | E15: =+AVERAGE('02_CUADRYGRÁF.COMP.ÚLT.5 CAMP.'!C14:F14) -> 3.49575 | J15: Abr | K15: =+IF('02_CUADRYGRÁF.COMP.ÚLT.5 CAMP.'!G31<>0,'02_CUADRYGRÁF.COMP.ÚLT.5 CAMP.'!G31,NA()) -> 16.635 | L15: =+AVERAGE('02_CUADRYGRÁF.COMP.ÚLT.5 CAMP.'!C31:F31) -> 17.846606
C16: May | D16: =+IF('02_CUADRYGRÁF.COMP.ÚLT.5 CAMP.'!G15<>0,'02_CUADRYGRÁF.COMP.ÚLT.5 CAMP.'!G15,NA()) -> 0.22164383 | E16: =+AVERAGE('02_CUADRYGRÁF.COMP.ÚLT.5 CAMP.'!C15:F15) -> 1.911725 | J16: May | K16: =+IF('02_CUADRYGRÁF.COMP.ÚLT.5 CAMP.'!G32<>0,'02_CUADRYGRÁF.COMP.ÚLT.5 CAMP.'!G32,NA()) -> 15.277 | L16: =+AVERAGE('02_CUADRYGRÁF.COMP.ÚLT.5 CAMP.'!C32:F32) -> 17.09497
C17: Jun | J17: Jun | K17: =+IF('02_CUADRYGRÁF.COMP.ÚLT.5 CAMP.'!G33<>0,'02_CUADRYGRÁF.COMP.ÚLT.5 CAMP.'!G33,NA()) -> 14.541 | L17: =+AVERAGE('02_CUADRYGRÁF.COMP.ÚLT.5 CAMP.'!C33:F33) -> 15.823583
C18: Jul | J18: Jul | K18: =+IF('02_CUADRYGRÁF.COMP.ÚLT.5 CAMP.'!G34<>0,'02_CUADRYGRÁF.COMP.ÚLT.5 CAMP.'!G34,NA()) -> 13.11 | L18: =+AVERAGE('02_CUADRYGRÁF.COMP.ÚLT.5 CAMP.'!C34:F34) -> 16.006943
C19: Ago | J19: Ago | K19: =+IF('02_CUADRYGRÁF.COMP.ÚLT.5 CAMP.'!G35<>0,'02_CUADRYGRÁF.COMP.ÚLT.5 CAMP.'!G35,NA()) -> 6.765 | L19: =+AVERAGE('02_CUADRYGRÁF.COMP.ÚLT.5 CAMP.'!C35:F35) -> 14.752021
C20: Sep | J20: Sep | K20: =+IF('02_CUADRYGRÁF.COMP.ÚLT.5 CAMP.'!G36<>0,'02_CUADRYGRÁF.COMP.ÚLT.5 CAMP.'!G36,NA()) -> 11.168 | L20: =+AVERAGE('02_CUADRYGRÁF.COMP.ÚLT.5 CAMP.'!C36:F36) -> 15.6681
C21: Acumulado | D21: =SUMIF(D9:D20, "<>#N/D") -> 1421.1127 | E21: =SUMIF(D9:D20,"<>#N/D",E9:E20) -> 1101.1494 | J21: Acumulado | K21: =SUMIF(K9:K20, "<>#N/D") -> 206.059 | L21: =SUMIF(K9:K20,"<>#N/D",L9:L20) -> 213.52247
C22: % VARIACIÓN: | D22: =+D21/E21-1 -> 0.29057209 | J22: % VARIACIÓN: | K22: =+K21/L21-1 -> -0.034954045
B24: MERCADO INTERIOR APARENTE | I24: EXPORTACIONES
B25: GRÁFICO MERCADO INTERIOR APARENTE | I25: GRÁFICO EXPORTACIONES
C26: Mes | D26: =+'04_CUADROS ACUMULADOS'!$H$7 -> 2024/25 | E26: Media 4 últimas campañas | J26: Mes | K26: =+'04_CUADROS ACUMULADOS'!$H$7 -> 2024/25 | L26: Media 4 últimas campañas
C27: Oct | D27: =+IF('02_CUADRYGRÁF.COMP.ÚLT.5 CAMP.'!G59<>0,'02_CUADRYGRÁF.COMP.ÚLT.5 CAMP.'!G59,NA()) -> 38.408902 | E27: =+AVERAGE('02_CUADRYGRÁF.COMP.ÚLT.5 CAMP.'!C59:F59) -> 39.598295 | J27: Oct | K27: =+IF('02_CUADRYGRÁF.COMP.ÚLT.5 CAMP.'!G42<>0,'02_CUADRYGRÁF.COMP.ÚLT.5 CAMP.'!G42,NA()) -> 60.278 | L27: =+AVERAGE('02_CUADRYGRÁF.COMP.ÚLT.5 CAMP.'!C42:F42) -> 80.870157
C28: Nov | D28: =+IF('02_CUADRYGRÁF.COMP.ÚLT.5 CAMP.'!G60<>0,'02_CUADRYGRÁF.COMP.ÚLT.5 CAMP.'!G60,NA()) -> 40.438747 | E28: =+AVERAGE('02_CUADRYGRÁF.COMP.ÚLT.5 CAMP.'!C60:F60) -> 46.175236 | J28: Nov | K28: =+IF('02_CUADRYGRÁF.COMP.ÚLT.5 CAMP.'!G43<>0,'02_CUADRYGRÁF.COMP.ÚLT.5 CAMP.'!G43,NA()) -> 59.937 | L28: =+AVERAGE('02_CUADRYGRÁF.COMP.ÚLT.5 CAMP.'!C43:F43) -> 74.878412
C29: Dic | D29: =+IF('02_CUADRYGRÁF.COMP.ÚLT.5 CAMP.'!G61<>0,'02_CUADRYGRÁF.COMP.ÚLT.5 CAMP.'!G61,NA()) -> 54.22504 | E29: =+AVERAGE('02_CUADRYGRÁF.COMP.ÚLT.5 CAMP.'!C61:F61) -> 43.731409 | J29: Dic | K29: =+IF('02_CUADRYGRÁF.COMP.ÚLT.5 CAMP.'!G44<>0,'02_CUADRYGRÁF.COMP.ÚLT.5 CAMP.'!G44,NA()) -> 69.723 | L29: =+AVERAGE('02_CUADRYGRÁF.COMP.ÚLT.5 CAMP.'!C44:F44) -> 72.081168
C30: Ene | D30: =+IF('02_CUADRYGRÁF.COMP.ÚLT.5 CAMP.'!G62<>0,'02_CUADRYGRÁF.COMP.ÚLT.5 CAMP.'!G62,NA()) -> 49.430284 | E30: =+AVERAGE('02_CUADRYGRÁF.COMP.ÚLT.5 CAMP.'!C62:F62) -> 37.457295 | J30: Ene | K30: =+IF('02_CUADRYGRÁF.COMP.ÚLT.5 CAMP.'!G45<>0,'02_CUADRYGRÁF.COMP.ÚLT.5 CAMP.'!G45,NA()) -> 89.304 | L30: =+AVERAGE('02_CUADRYGRÁF.COMP.ÚLT.5 CAMP.'!C45:F45) -> 70.440534
C31: Feb | D31: =+IF('02_CUADRYGRÁF.COMP.ÚLT.5 CAMP.'!G63<>0,'02_CUADRYGRÁF.COMP.ÚLT.5 CAMP.'!G63,NA()) -> 40.568917 | E31: =+AVERAGE('02_CUADRYGRÁF.COMP.ÚLT.5 CAMP.'!C63:F63) -> 38.72437 | J31: Feb | K31: =+IF('02_CUADRYGRÁF.COMP.ÚLT.5 CAMP.'!G46<>0,'02_CUADRYGRÁF.COMP.ÚLT.5 CAMP.'!G46,NA()) -> 90.628 | L31: =+AVERAGE('02_CUADRYGRÁF.COMP.ÚLT.5 CAMP.'!C46:F46) -> 76.447174
C32: Mar | D32: =+IF('02_CUADRYGRÁF.COMP.ÚLT.5 CAMP.'!G64<>0,'02_CUADRYGRÁF.COMP.ÚLT.5 CAMP.'!G64,NA()) -> 43.606514 | E32: =+AVERAGE('02_CUADRYGRÁF.COMP.ÚLT.5 CAMP.'!C64:F64) -> 45.567182 | J32: Mar | K32: =+IF('02_CUADRYGRÁF.COMP.ÚLT.5 CAMP.'!G47<>0,'02_CUADRYGRÁF.COMP.ÚLT.5 CAMP.'!G47,NA()) -> 96.981 | L32: =+AVERAGE('02_CUADRYGRÁF.COMP.ÚLT.5 CAMP.'!C47:F47) -> 77.476141
C33: Abr | D33: =+IF('02_CUADRYGRÁF.COMP.ÚLT.5 CAMP.'!G65<>0,'02_CUADRYGRÁF.COMP.ÚLT.5 CAMP.'!G65,NA()) -> 35.672966 | E33: =+AVERAGE('02_CUADRYGRÁF.COMP.ÚLT.5 CAMP.'!C65:F65) -> 39.030983 | J33: Abr | K33: =+IF('02_CUADRYGRÁF.COMP.ÚLT.5 CAMP.'!G48<>0,'02_CUADRYGRÁF.COMP.ÚLT.5 CAMP.'!G48,NA()) -> 98.778 | L33: =+AVERAGE('02_CUADRYGRÁF.COMP.ÚLT.5 CAMP.'!C48:F48) -> 83.18309
C34: May | D34: =+IF('02_CUADRYGRÁF.COMP.ÚLT.5 CAMP.'!G66<>0,'02_CUADRYGRÁF.COMP.ÚLT.5 CAMP.'!G66,NA()) -> 36.885764 | E34: =+AVERAGE('02_CUADRYGRÁF.COMP.ÚLT.5 CAMP.'!C66:F66) -> 36.658482 | J34: May | K34: =+IF('02_CUADRYGRÁF.COMP.ÚLT.5 CAMP.'!G49<>0,'02_CUADRYGRÁF.COMP.ÚLT.5 CAMP.'!G49,NA()) -> 99.324 | L34: =+AVERAGE('02_CUADRYGRÁF.COMP.ÚLT.5 CAMP.'!C49:F49) -> 87.163953
C35: Jun | D35: =+IF('02_CUADRYGRÁF.COMP.ÚLT.5 CAMP.'!G67<>0,'02_CUADRYGRÁF.COMP.ÚLT.5 CAMP.'!G67,NA()) -> 37.95556 | E35: =+AVERAGE('02_CUADRYGRÁF.COMP.ÚLT.5 CAMP.'!C67:F67) -> 34.89425 | J35: Jun | K35: =+IF('02_CUADRYGRÁF.COMP.ÚLT.5 CAMP.'!G50<>0,'02_CUADRYGRÁF.COMP.ÚLT.5 CAMP.'!G50,NA()) -> 94.483 | L35: =+AVERAGE('02_CUADRYGRÁF.COMP.ÚLT.5 CAMP.'!C50:F50) -> 80.722283
C36: Jul | D36: =+IF('02_CUADRYGRÁF.COMP.ÚLT.5 CAMP.'!G68<>0,'02_CUADRYGRÁF.COMP.ÚLT.5 CAMP.'!G68,NA()) -> 37.73618 | E36: =+AVERAGE('02_CUADRYGRÁF.COMP.ÚLT.5 CAMP.'!C68:F68) -> 34.849258 | J36: Jul | K36: =+IF('02_CUADRYGRÁF.COMP.ÚLT.5 CAMP.'!G51<>0,'02_CUADRYGRÁF.COMP.ÚLT.5 CAMP.'!G51,NA()) -> 110.997 | L36: =+AVERAGE('02_CUADRYGRÁF.COMP.ÚLT.5 CAMP.'!C51:F51) -> 72.666577
C37: Ago | D37: =+IF('02_CUADRYGRÁF.COMP.ÚLT.5 CAMP.'!G69<>0,'02_CUADRYGRÁF.COMP.ÚLT.5 CAMP.'!G69,NA()) -> 35.51266 | E37: =+AVERAGE('02_CUADRYGRÁF.COMP.ÚLT.5 CAMP.'!C69:F69) -> 37.709521 | J37: Ago | K37: =+IF('02_CUADRYGRÁF.COMP.ÚLT.5 CAMP.'!G52<>0,'02_CUADRYGRÁF.COMP.ÚLT.5 CAMP.'!G52,NA()) -> 76.051 | L37: =+AVERAGE('02_CUADRYGRÁF.COMP.ÚLT.5 CAMP.'!C52:F52) -> 63.085518
C38: Sep | D38: =+IF('02_CUADRYGRÁF.COMP.ÚLT.5 CAMP.'!G70<>0,'02_CUADRYGRÁF.COMP.ÚLT.5 CAMP.'!G70,NA()) -> 32.3375 | E38: =+AVERAGE('02_CUADRYGRÁF.COMP.ÚLT.5 CAMP.'!C70:F70) -> 37.097425 | J38: Sep | K38: =+IF('02_CUADRYGRÁF.COMP.ÚLT.5 CAMP.'!G53<>0,'02_CUADRYGRÁF.COMP.ÚLT.5 CAMP.'!G53,NA()) -> 95.087 | L38: =+AVERAGE('02_CUADRYGRÁF.COMP.ÚLT.5 CAMP.'!C53:F53) -> 80.239794
C39: Acumulado | D39: =SUMIF(D27:D38, "<>#N/D") -> 482.77903 | E39: =SUMIF(D27:D38,"<>#N/D",E27:E38) -> 471.49371 | J39: Acumulado | K39: =SUMIF(K27:K38, "<>#N/D") -> 1041.571 | L39: =SUMIF(K27:K38,"<>#N/D",L27:L38) -> 919.2548
C40: % VARIACIÓN: | D40: =+D39/E39-1 -> 0.023935266 | I40: % VARIACION : | K40: =+K39/L39-1 -> 0.13306017
B42: EXISTENCIAS ALMAZARAS (INCLUIDO FPCO) | I42: EXISTENCIAS TOTALES
B43: GRÁFICO EXISTENCIAS ALMAZARAS (INCLUIDO FPCO) | I43: GRÁFICO EXISTENCIAS TOTALES
C44: Mes | D44: =+'04_CUADROS ACUMULADOS'!$H$7 -> 2024/25 | E44: Media 4 últimas campañas | J44: Mes | K44: =+'04_CUADROS ACUMULADOS'!$H$7 -> 2024/25 | L44: Media 4 últimas campañas
C45: Oct | D45: =+IF('03_CUADRYGRÁF.COMP.5 ÚLT.CAMP.'!J8<>0,'03_CUADRYGRÁF.COMP.5 ÚLT.CAMP.'!J8,NA()) -> 54.82129 | E45: =+AVERAGE('03_CUADRYGRÁF.COMP.5 ÚLT.CAMP.'!F8:I8) -> 151.25254 | J45: Oct | K45: =+IF('03_CUADRYGRÁF.COMP.5 ÚLT.CAMP.'!J42<>0,'03_CUADRYGRÁF.COMP.5 ÚLT.CAMP.'!J42,NA()) -> 140.94939 | L45: =+AVERAGE('03_CUADRYGRÁF.COMP.5 ÚLT.CAMP.'!F42:I42) -> 338.392
C46: Nov | D46: =+IF('03_CUADRYGRÁF.COMP.5 ÚLT.CAMP.'!J9<>0,'03_CUADRYGRÁF.COMP.5 ÚLT.CAMP.'!J9,NA()) -> 236.50213 | E46: =+AVERAGE('03_CUADRYGRÁF.COMP.5 ÚLT.CAMP.'!F9:I9) -> 286.18028 | J46: Nov | K46: =+IF('03_CUADRYGRÁF.COMP.5 ÚLT.CAMP.'!J43<>0,'03_CUADRYGRÁF.COMP.5 ÚLT.CAMP.'!J43,NA()) -> 330.81993 | L46: =+AVERAGE('03_CUADRYGRÁF.COMP.5 ÚLT.CAMP.'!F43:I43) -> 472.68156
...

Sheet 06_ALMAZARAS.BALANCE DE CAMPAÑA
C1: 06_ALMAZARAS_BALANCE DE CAMPAÑA
C4: COMUNIDAD AUTÓNOMA | D4: PROVINCIA | E4: ALMAZARAS | H4: EXISTENCIAS A 1 DE OCTUBRE | I4: ENTRADAS | K4: SALIDAS TOTALES | L4: EXISTENCIAS FINALES
E6: *Nº TOTAL | F6: **Nº DATOS | G6: **DATOS (-%) | I6: PRODUCCIÓN | J6: OTRAS E.
C7: ANDALUCÍA | D7: ALMERÍA | E7: 30 | F7: 28 | G7: 0.93333333 | H7: 593.3 | I7: 4413.9 | J7: 0 | K7: 4754.6 | L7: 252.6
D8: CÁDIZ | E8: 20 | F8: 20 | G8: 1 | H8: 1068.8 | I8: 8416.9 | J8: 0 | K8: 9223.7 | L8: 262
D9: CÓRDOBA | E9: 186 | F9: 181 | G9: 0.97311828 | H9: 12563.3 | I9: 291821.1 | J9: 22621.9 | K9: 307135.6 | L9: 19870.7
D10: GRANADA | E10: 106 | F10: 100 | G10: 0.94339623 | H10: 3109.3 | I10: 124387.4 | J10: 3356.2 | K10: 114324.5 | L10: 16528.4
D11: HUELVA | E11: 21 | F11: 20 | G11: 0.95238095 | H11: 910.6 | I11: 8388 | J11: 481.6 | K11: 7883.7 | L11: 1896.5
D12: JAÉN | E12: 332 | F12: 325 | G12: 0.97891566 | H12: 29637.5 | I12: 563094 | J12: 35458.2 | K12: 550344.2 | L12: 77845.5
D13: MÁLAGA | E13: 78 | F13: 78 | G13: 1 | H13: 1280.9 | I13: 35476.9 | J13: 26 | K13: 35605.8 | L13: 1178
D14: SEVILLA | E14: 92 | F14: 88 | G14: 0.95652174 | H14: 5485.3 | I14: 111876.4 | J14: 1220.5 | K14: 114869.1 | L14: 3713.1
D15: TOTAL: | E15: 865 | F15: 840 | G15: 0.97109827 | H15: 54649 | I15: 1147874.6 | J15: 63164.4 | K15: 1144141.2 | L15: 121546.8
C16: ARAGÓN | D16: HUESCA | E16: 27 | F16: 27 | G16: 1 | H16: 92.8 | I16: 1821.5 | J16: 0 | K16: 1828.7 | L16: 85.6
D17: TERUEL | E17: 27 | F17: 27 | G17: 1 | H17: 1110.7 | I17: 1733 | J17: 0 | K17: 2617.2 | L17: 226.5
D18: ZARAGOZA | E18: 42 | F18: 42 | G18: 1 | H18: 383.2 | I18: 3920.1 | J18: 0 | K18: 3690.2 | L18: 613.1
D19: TOTAL: | E19: 96 | F19: 96 | G19: 1 | H19: 1586.7 | I19: 7474.6 | J19: 0 | K19: 8136.1 | L19: 925.2
C20: BALEARES | D20: BALEARES | E20: 25 | F20: 23 | G20: 0.92 | H20: 68.5 | I20: 245 | J20: 0 | K20: 302.5 | L20: 11
D21: TOTAL: | E21: 25 | F21: 23 | G21: 0.92 | H21: 68.5 | I21: 245 | J21: 0 | K21: 302.5 | L21: 11
C22: COMUNIDAD VALENCIANA | D22: ALICANTE | E22: 44 | F22: 43 | G22: 0.97727273 | H22: 312.6 | I22: 3776.7 | J22: 0 | K22: 3814 | L22: 275.3
D23: CASTELLÓN | E23: 46 | F23: 44 | G23: 0.95652174 | H23: 511.8 | I23: 255 | J23: 0 | K23: 742.5 | L23: 24.3
D24: VALENCIA | E24: 52 | F24: 52 | G24: 1 | H24: 305.5 | I24: 1121.2 | J24: 0 | K24: 1328.4 | L24: 98.3
D25: TOTAL: | E25: 142 | F25: 139 | G25: 0.97887324 | H25: 1129.9 | I25: 5152.9 | J25: 0 | K25: 5884.9 | L25: 397.9
C26: CANARIAS | D26: LAS PALMAS | E26: 2 | F26: 2 | G26: 1 | H26: 0 | I26: 0 | J26: 0 | K26: 0 | L26: 0
D27: STA. CRUZ DE TENERIFE | E27: 2 | F27: 2 | G27: 1 | H27: 0 | I27: 1.4 | J27: 0 | K27: 1.4 | L27: 0
D28: TOTAL: | E28: 4 | F28: 4 | G28: 1 | H28: 0 | I28: 1.4 | J28: 0 | K28: 1.4 | L28: 0
C29: CASTILLA-LA MANCHA | D29: ALBACETE | E29: 40 | F29: 39 | G29: 0.975 | H29: 1480.9 | I29: 10327.3 | J29: 172.9 | K29: 10796.7 | L29: 1184.4
D30: CIUDAD REAL | E30: 79 | F30: 77 | G30: 0.97468354 | H30: 7141.3 | I30: 72785.1 | J30: 2088.4 | K30: 77146.5 | L30: 4868.3
D31: CUENCA | E31: 26 | F31: 26 | G31: 1 | H31: 511.5 | I31: 5218.6 | J31: 0 | K31: 4914.4 | L31: 815.7
D32: GUADALAJARA | E32: 8 | F32: 7 | G32: 0.875 | H32: 127.4 | I32: 2301.6 | J32: 0 | K32: 1923.2 | L32: 505.8
D33: TOLEDO | E33: 110 | F33: 111 | G33: 1.0090909 | H33: 4740 | I33: 56001.2 | J33: 1282 | K33: 59028.8 | L33: 2994.4
D34: TOTAL: | E34: 263 | F34: 260 | G34: 0.98859316 | H34: 14001.1 | I34: 146633.8 | J34: 3543.3 | K34: 153809.6 | L34: 10368.6
C35: CASTILLA Y LEÓN | D35: ÁVILA | E35: 11 | F35: 11 | G35: 1 | H35: 21.6 | I35: 806.2 | J35: 0 | K35: 819.4 | L35: 8.4
D36: SALAMANCA | E36: 5 | F36: 4 | G36: 0.8 | H36: 3.2 | I36: 206.3 | J36: 0 | K36: 206 | L36: 3.5
D37: SORIA | E37: 1 | F37: 1 | G37: 1 | H37: 0 | I37: 0.4 | J37: 0 | K37: 0.4 | L37: 0
D38: OTRAS | E38: 3 | F38: 3 | G38: 1 | H38: 45.3 | I38: 414.6 | J38: 0 | K38: 321.7 | L38: 138.2
D39: TOTAL: | E39: 20 | F39: 19 | G39: 0.95 | H39: 70.1 | I39: 1427.5 | J39: 0 | K39: 1347.5 | L39: 150.1
C40: CATALUÑA | D40: BARCELONA | E40: 13 | F40: 11 | G40: 0.84615385 | H40: 3.3 | I40: 652.5 | J40: 0 | K40: 643.4 | L40: 12.4
D41: GIRONA | E41: 13 | F41: 13 | G41: 1 | H41: 9.2 | I41: 536.2 | J41: 0 | K41: 525.8 | L41: 19.6
D42: LLEIDA | E42: 57 | F42: 57 | G42: 1 | H42: 290.8 | I42: 8447.2 | J42: 0 | K42: 8434.7 | L42: 303.3
D43: TARRAGONA | E43: 94 | F43: 87 | G43: 0.92553191 | H43: 985.3 | I43: 5685.5 | J43: 50.2 | K43: 6255.4 | L43: 465.6
...

Sheet 07_ALMAZARAS.ACEITE PRODUCIDO
E1: 07_ALMAZARAS_ACEITE PRODUCIDO
E4: COMUNIDAD AUTÓNOMA | F4: PROVINCIA | G4: OCTUBRE | H4: NOVIEMBRE | I4: DICIEMBRE | J4: ENERO | K4: FEBRERO | L4: MARZO | M4: ABRIL | N4: MAYO | O4: AJUSTES | P4: TOTAL
E5: ANDALUCÍA | F5: ALMERÍA | G5: 466.4 | H5: 2166.6 | I5: 1578.4 | J5: 173.7 | K5: 15.8 | L5: 0 | M5: 0 | N5: 0 | O5: 13 | P5: 4413.9
F6: CÁDIZ | G6: 887.1 | H6: 4002.5 | I6: 3021.9 | J6: 475.1 | K6: 16.1 | L6: 0 | M6: 0 | N6: 0 | O6: 14.2 | P6: 8416.9
F7: CÓRDOBA | G7: 5358.3 | H7: 56193 | I7: 115664.6 | J7: 68933.4 | K7: 37384.7 | L7: 5367.1 | M7: 1805.9 | N7: 57.9 | O7: 1056.2 | P7: 291821.1
F8: GRANADA | G8: 315.1 | H8: 15595.4 | I8: 53818.2 | J8: 35775.3 | K8: 15614.7 | L8: 1838 | M8: 516.4 | N8: 114.4 | O8: 799.9 | P8: 124387.4
F9: HUELVA | G9: 963.4 | H9: 4338.7 | I9: 2879.1 | J9: 151.3 | K9: 5.6 | L9: 0 | M9: 0 | N9: 0 | O9: 49.9 | P9: 8388
F10: JAÉN | G10: 5583.8 | H10: 65248.8 | I10: 234272.4 | J10: 172798.4 | K10: 79467.3 | L10: 2956 | M10: 384 | N10: 40.6 | O10: 2342.7 | P10: 563094
F11: MÁLAGA | G11: 1273.8 | H11: 8916.6 | I11: 13633.1 | J11: 7259 | K11: 3272.9 | L11: 564.8 | M11: 353.4 | N11: 7.7 | O11: 195.6 | P11: 35476.9
F12: SEVILLA | G12: 13566 | H12: 36557.2 | I12: 45240.9 | J12: 14028.5 | K12: 1815.6 | L12: 146.6 | M12: 0 | N12: 0 | O12: 521.6 | P12: 111876.4
F13: TOTAL : | G13: 28413.9 | H13: 193018.8 | I13: 470108.6 | J13: 299594.7 | K13: 137592.7 | L13: 10872.5 | M13: 3059.7 | N13: 220.6 | O13: 4993.1 | P13: 1147874.6
E14: ARAGÓN | F14: HUESCA | G14: 77.6 | H14: 1041.3 | I14: 620 | J14: 81.5 | K14: 0 | L14: 0.3 | M14: 0 | N14: 0 | O14: 0.8 | P14: 1821.5
F15: TERUEL | G15: 62.8 | H15: 1019.9 | I15: 395.4 | J15: 198.9 | K15: 16.3 | L15: 0 | M15: 7.7 | N15: 0 | O15: 32 | P15: 1733
F16: ZARAGOZA | G16: 64.9 | H16: 1643 | I16: 1880.1 | J16: 291.4 | K16: 16.9 | L16: 0 | M16: 0 | N16: 0 | O16: 23.8 | P16: 3920.1
F17: TOTAL : | G17: 205.3 | H17: 3704.2 | I17: 2895.5 | J17: 571.8 | K17: 33.2 | L17: 0.3 | M17: 7.7 | N17: 0 | O17: 56.6 | P17: 7474.6
E18: BALEARES | F18: BALEARES | G18: 162.2 | H18: 80 | I18: 2.8 | J18: 0 | K18: 0 | L18: 0 | M18: 0 | N18: 0 | O18: 0 | P18: 245
F19: TOTAL : | G19: 162.2 | H19: 80 | I19: 2.8 | J19: 0 | K19: 0 | L19: 0 | M19: 0 | N19: 0 | O19: 0 | P19: 245
E20: COMUNIDAD VALENCIANA | F20: ALICANTE | G20: 222.8 | H20: 1217.8 | I20: 1337.9 | J20: 777.3 | K20: 180.9 | L20: 22.5 | M20: 0 | N20: 0 | O20: 17.5 | P20: 3776.7
F21: CASTELLÓN | G21: 69 | H21: 150.6 | I21: 31.9 | J21: 1.6 | K21: 0 | L21: 0 | M21: 0 | N21: 0 | O21: 1.9 | P21: 255
F22: VALENCIA | G22: 84.9 | H22: 669.5 | I22: 351.8 | J22: 12.2 | K22: 0 | L22: 0 | M22: 0 | N22: 0 | O22: 2.8 | P22: 1121.2
F23: TOTAL : | G23: 376.7 | H23: 2037.9 | I23: 1721.6 | J23: 791.1 | K23: 180.9 | L23: 22.5 | M23: 0 | N23: 0 | O23: 22.2 | P23: 5152.9
E24: CANARIAS | F24: LAS PALMAS | G24: 0 | H24: 0 | I24: 0 | J24: 0 | K24: 0 | L24: 0 | M24: 0 | N24: 0 | O24: 0 | P24: 0
F25: STA. CRUZ DE TENERIFE | G25: 1.4 | H25: 0 | I25: 0 | J25: 0 | K25: 0 | L25: 0 | M25: 0 | N25: 0 | O25: 0 | P25: 1.4
F26: TOTAL : | G26: 1.4 | H26: 0 | I26: 0 | J26: 0 | K26: 0 | L26: 0 | M26: 0 | N26: 0 | O26: 0 | P26: 1.4
E27: CASTILLA-LA MANCHA | F27: ALBACETE | G27: 109.7 | H27: 3650.2 | I27: 5520.3 | J27: 901.2 | K27: 113.7 | L27: 16.4 | M27: 0 | N27: 0 | O27: 15.8 | P27: 10327.3
F28: CIUDAD REAL | G28: 282.7 | H28: 10917.1 | I28: 36765.7 | J28: 20296.2 | K28: 3896.6 | L28: 37.7 | M28: 0 | N28: 0 | O28: 589.1 | P28: 72785.1
F29: CUENCA | G29: 10.9 | H29: 767.8 | I29: 2881.3 | J29: 1230.2 | K29: 293.1 | L29: 14.8 | M29: 7.4 | N29: 0 | O29: 13.1 | P29: 5218.6
F30: GUADALAJARA | G30: 0 | H30: 202.6 | I30: 889.1 | J30: 637.7 | K30: 462.7 | L30: 94.4 | M30: 15.1 | N30: 0 | O30: 0 | P30: 2301.6
F31: TOLEDO | G31: 270.2 | H31: 5521.2 | I31: 22649.9 | J31: 17203.1 | K31: 8964.5 | L31: 996.2 | M31: 29.3 | N31: 0 | O31: 366.8 | P31: 56001.2
F32: TOTAL : | G32: 673.5 | H32: 21058.9 | I32: 68706.3 | J32: 40268.4 | K32: 13730.6 | L32: 1159.5 | M32: 51.8 | N32: 0 | O32: 984.8 | P32: 146633.8
E33: CASTILLA Y LEÓN | F33: ÁVILA | G33: 0 | H33: 330.2 | I33: 475.2 | J33: 0.7 | K33: 0 | L33: 0 | M33: 0 | N33: 0 | O33: 0.1 | P33: 806.2
F34: SALAMANCA | G34: 10.9 | H34: 175.2 | I34: 19.2 | J34: 0 | K34: 0 | L34: 0 | M34: 0 | N34: 0 | O34: 1 | P34: 206.3
F35: SORIA | G35: 0 | H35: 0.4 | I35: 0 | J35: 0 | K35: 0 | L35: 0 | M35: 0 | N35: 0 | O35: 0 | P35: 0.4
F36: OTRAS | G36: 0 | H36: 330 | I36: 84.6 | J36: 0 | K36: 0 | L36: 0 | M36: 0 | N36: 0 | O36: 0 | P36: 414.6
F37: TOTAL : | G37: 10.9 | H37: 835.8 | I37: 579 | J37: 0.7 | K37: 0 | L37: 0 | M37: 0 | N37: 0 | O37: 1.1 | P37: 1427.5
E38: CATALUÑA | F38: BARCELONA | G38: 84.6 | H38: 381.9 | I38: 157.2 | J38: 14.7 | K38: 0 | L38: 0 | M38: 0 | N38: 0 | O38: 14.1 | P38: 652.5
F39: GIRONA | G39: 58.2 | H39: 303 | I39: 159.7 | J39: 15.3 | K39: 0 | L39: 0 | M39: 0 | N39: 0 | O39: 0 | P39: 536.2
F40: LLEIDA | G40: 438.3 | H40: 4014.1 | I40: 3414.8 | J40: 406.9 | K40: 0 | L40: 0 | M40: 0 | N40: 0 | O40: 173.1 | P40: 8447.2
F41: TARRAGONA | G41: 457 | H41: 3339.7 | I41: 1522.5 | J41: 220.3 | K41: 93.7 | L41: 0 | M41: 0 | N41: 0 | O41: 52.3 | P41: 5685.5
F42: TOTAL : | G42: 1038.1 | H42: 8038.7 | I42: 5254.2 | J42: 657.2 | K42: 93.7 | L42: 0 | M42: 0 | N42: 0 | O42: 239.5 | P42: 15321.4
...

Sheet 08_ALMAZ POR TIPO.PRODUCCIÓN
E2: 08_ALMAZARAS_ALMAZARAS POR TIPO_PRODUCCIÓN
G6: ALMAZARAS Nº | L6: PRODUCCIÓN
G7: TOTALES | H7: COOPERATIVAS | J7: INDUSTRIALES | L7: TOTALES | M7: COOPERATIVAS | O7: INDUSTRIALES
E8: COMUNIDAD AUTÓNOMA | F8: PROVINCIA | G8: Nº | H8: Nº | I8: % | J8: Nº | K8: % | L8: Toneladas | M8: Toneladas | N8: % | O8: Toneladas | P8: %
E9: ANDALUCÍA | F9: ALMERÍA | G9: 28 | H9: 5 | I9: 0.17857143 | J9: 23 | K9: 0.82142857 | L9: 4413.9 | M9: 536.2 | N9: 0.12147987 | O9: 3877.7 | P9: 0.87852013
F10: CÁDIZ | G10: 20 | H10: 4 | I10: 0.2 | J10: 16 | K10: 0.8 | L10: 8416.9 | M10: 6853.9 | N10: 0.81430218 | O10: 1563 | P10: 0.18569782
F11: CÓRDOBA | G11: 187 | H11: 72 | I11: 0.38502674 | J11: 115 | K11: 0.61497326 | L11: 291821.1 | M11: 163627.9 | N11: 0.56071305 | O11: 128193.2 | P11: 0.43928695
F12: GRANADA | G12: 103 | H12: 48 | I12: 0.46601942 | J12: 55 | K12: 0.53398058 | L12: 124387.4 | M12: 82438.7 | N12: 0.66275764 | O12: 41948.7 | P12: 0.33724236
F13: HUELVA | G13: 21 | H13: 15 | I13: 0.71428571 | J13: 6 | K13: 0.28571429 | L13: 8388 | M13: 2674.1 | N13: 0.31880067 | O13: 5713.9 | P13: 0.68119933
F14: JAÉN | G14: 330 | H14: 182 | I14: 0.55151515 | J14: 148 | K14: 0.44848485 | L14: 563094 | M14: 389456.4 | N14: 0.69163657 | O14: 173637.6 | P14: 0.30836343
F15: MÁLAGA | G15: 78 | H15: 41 | I15: 0.52564103 | J15: 37 | K15: 0.47435897 | L15: 35476.9 | M15: 30712.8 | N15: 0.86571262 | O15: 4764.1 | P15: 0.13428738
F16: SEVILLA | G16: 90 | H16: 50 | I16: 0.55555556 | J16: 40 | K16: 0.44444444 | L16: 111876.4 | M16: 66396.6 | N16: 0.59348174 | O16: 45479.8 | P16: 0.40651826
F17: TOTAL CCAA: | G17: 857 | H17: 417 | I17: 0.4865811 | J17: 440 | K17: 0.5134189 | L17: 1147874.6 | M17: 742696.6 | N17: 0.64701893 | O17: 405178 | P17: 0.35298107
E18: ARAGÓN | F18: HUESCA | G18: 27 | H18: 10 | I18: 0.37037037 | J18: 17 | K18: 0.62962963 | L18: 1821.5 | M18: 546.2 | N18: 0.29986275 | O18: 1275.3 | P18: 0.70013725
F19: TERUEL | G19: 27 | H19: 15 | I19: 0.55555556 | J19: 12 | K19: 0.44444444 | L19: 1733 | M19: 316.4 | N19: 0.18257357 | O19: 1416.6 | P19: 0.81742643
F20: ZARAGOZA | G20: 43 | H20: 25 | I20: 0.58139535 | J20: 18 | K20: 0.41860465 | L20: 3920.1 | M20: 1699.4 | N20: 0.43350935 | O20: 2220.7 | P20: 0.56649065
F21: TOTAL CCAA: | G21: 97 | H21: 50 | I21: 0.51546392 | J21: 47 | K21: 0.48453608 | L21: 7474.6 | M21: 2562 | N21: 0.34276082 | O21: 4912.6 | P21: 0.65723918
E22: BALEARES | F22: BALEARES | G22: 23 | H22: 5 | I22: 0.2173913 | J22: 18 | K22: 0.7826087 | L22: 245 | M22: 98.2 | N22: 0.40081633 | O22: 146.8 | P22: 0.59918367
F23: TOTAL CCAA: | G23: 23 | H23: 5 | I23: 0.2173913 | J23: 18 | K23: 0.7826087 | L23: 245 | M23: 98.2 | N23: 0.40081633 | O23: 146.8 | P23: 0.59918367
E24: CANARIAS | F24: LAS PALMAS | G24: 2 | H24: 0 | I24: 0 | J24: 2 | K24: 1 | L24: 0 | M24: 0 | N24: 0 | O24: 0 | P24: 0
F25: STA. CRUZ DE TENERIFE | G25: 2 | H25: 1 | I25: 0.5 | J25: 1 | K25: 0.5 | L25: 1.4 | M25: 1.4 | N25: 1 | O25: 0 | P25: 0
F26: TOTAL CCAA: | G26: 4 | H26: 1 | I26: 0.25 | J26: 3 | K26: 0.75 | L26: 1.4 | M26: 1.4 | N26: 1 | O26: 0 | P26: 0
E27: CASTILLA-LA MANCHA | F27: ALBACETE | G27: 39 | H27: 14 | I27: 0.35897436 | J27: 25 | K27: 0.64102564 | L27: 10327.3 | M27: 4817.9 | N27: 0.46652078 | O27: 5509.4 | P27: 0.53347922
F28: CIUDAD REAL | G28: 79 | H28: 43 | I28: 0.5443038 | J28: 36 | K28: 0.4556962 | L28: 72785.1 | M28: 40578.5 | N28: 0.55751108 | O28: 32206.6 | P28: 0.44248892
F29: CUENCA | G29: 27 | H29: 12 | I29: 0.44444444 | J29: 15 | K29: 0.55555556 | L29: 5218.6 | M29: 2194.3 | N29: 0.42047676 | O29: 3024.3 | P29: 0.57952324
F30: GUADALAJARA | G30: 7 | H30: 1 | I30: 0.14285714 | J30: 6 | K30: 0.85714286 | L30: 2301.6 | M30: 25.1 | N30: 0.010905457 | O30: 2276.5 | P30: 0.98909454
F31: TOLEDO | G31: 112 | H31: 57 | I31: 0.50892857 | J31: 55 | K31: 0.49107143 | L31: 56001.2 | M31: 39134.3 | N31: 0.69881181 | O31: 16866.9 | P31: 0.30118819
F32: TOTAL CCAA: | G32: 264 | H32: 127 | I32: 0.48106061 | J32: 137 | K32: 0.51893939 | L32: 146633.8 | M32: 86750.1 | N32: 0.59161053 | O32: 59883.7 | P32: 0.40838947
E33: CASTILLA Y LEÓN | F33: ÁVILA | G33: 11 | H33: 8 | I33: 0.72727273 | J33: 3 | K33: 0.27272727 | L33: 806.2 | M33: 273.6 | N33: 0.33936988 | O33: 532.6 | P33: 0.66063012
F34: SALAMANCA | G34: 5 | H34: 3 | I34: 0.6 | J34: 2 | K34: 0.4 | L34: 206.3 | M34: 68.8 | N34: 0.33349491 | O34: 137.5 | P34: 0.66650509
F35: SORIA | G35: 1 | H35: 0 | I35: 0 | J35: 1 | K35: 1 | L35: 0.4 | M35: 0 | N35: 0 | O35: 0.4 | P35: 1
F36: OTRAS | G36: 3 | H36: 1 | I36: 0.33333333 | J36: 2 | K36: 0.66666667 | L36: 414.6 | M36: 38 | N36: 0.091654607 | O36: 376.6 | P36: 0.90834539
F37: TOTAL CCAA: | G37: 20 | H37: 12 | I37: 0.6 | J37: 8 | K37: 0.4 | L37: 1427.5 | M37: 380.4 | N37: 0.26647986 | O37: 1047.1 | P37: 0.73352014
E38: CATALUÑA | F38: BARCELONA | G38: 13 | H38: 2 | I38: 0.15384615 | J38: 11 | K38: 0.84615385 | L38: 652.5 | M38: 51.9 | N38: 0.07954023 | O38: 600.6 | P38: 0.92045977
F39: GIRONA | G39: 13 | H39: 3 | I39: 0.23076923 | J39: 10 | K39: 0.76923077 | L39: 536.2 | M39: 311.8 | N39: 0.58149944 | O39: 224.4 | P39: 0.41850056
F40: LLEIDA | G40: 57 | H40: 26 | I40: 0.45614035 | J40: 31 | K40: 0.54385965 | L40: 8447.2 | M40: 5593.1 | N40: 0.66212473 | O40: 2854.1 | P40: 0.33787527
F41: TARRAGONA | G41: 90 | H41: 55 | I41: 0.61111111 | J41: 35 | K41: 0.38888889 | L41: 5685.5 | M41: 4051.2 | N41: 0.71254947 | O41: 1634.3 | P41: 0.28745053
F42: TOTAL CCAA: | G42: 173 | H42: 86 | I42: 0.49710983 | J42: 87 | K42: 0.50289017 | L42: 15321.4 | M42: 10008 | N42: 0.65320402 | O42: 5313.4 | P42: 0.34679598
E43: EXTREMADURA | F43: BADAJOZ | G43: 88 | H43: 40 | I43: 0.45454545 | J43: 48 | K43: 0.54545455 | L43: 70752.3 | M43: 47591.8 | N43: 0.67265375 | O43: 23160.5 | P43: 0.32734625
F44: CÁCERES | G44: 48 | H44: 21 | I44: 0.4375 | J44: 27 | K44: 0.5625 | L44: 7170.4 | M44: 1350.4 | N44: 0.1883298 | O44: 5820 | P44: 0.8116702
...

Sheet 09_ALMAZ.PROD. POR CAMYTIPO 
B4: 09_ALMAZARAS_PRODUCCIÓN POR CAMPAÑAS Y TIPO
B8: ALMAZARAS COOPERATIVAS
B21: Campaña | C21: 20/21 | D21: 21/22 | E21: 22/23 | F21: 23/24 | G21: 24/25
B22: % Nº Empresas | C22: 50.109529 | D22: 49.755302 | E22: 49.89083 | F22: 49.400871 | G22: 49.152542
B23: % Producción | C23: 65.418312 | D23: 64.693101 | E23: 59.039253 | F23: 58.851403 | G23: 63.553335
B26: ALMAZARAS INDUSTRIALES
B39: Campaña | C39: 20/21 | D39: 21/22 | E39: 22/23 | F39: 23/24 | G39: 24/25
B40: % Nº Empresas | C40: 49.890471 | D40: 50.244698 | E40: 50.10917 | F40: 50.599129 | G40: 50.847458
B41: % Producción | C41: 34.581688 | D41: 35.306899 | E41: 40.960747 | F41: 41.148597 | G41: 36.446665
B43: Fuente: SIMO

Sheet 10_ALMAZ.RES.ANUAL SAL.NET.ACEI
D2: 10_ALMAZARAS_RESUMEN ANUAL DE SALIDAS NETAS DE ACEITE
D6: COMUNIDAD AUTÓNOMA | E6: PROVINCIA | F6: OCTUBRE | G6: NOVIEMBRE | H6: DICIEMBRE | I6: ENERO | J6: FEBRERO | K6: MARZO | L6: ABRIL | M6: MAYO | N6: JUNIO | O6: JULIO | P6: AGOSTO | Q6: SEPTIEMBRE | R6: TOTAL
D7: ANDALUCÍA | E7: ALMERÍA | F7: 525.2 | G7: 718.8 | H7: 696.8 | I7: 541.4 | J7: 398.5 | K7: 514.8 | L7: 172.3 | M7: 274.4 | N7: 141.1 | O7: 284.4 | P7: 272.3 | Q7: 214.6 | R7: 4754.6
E8: CÁDIZ | F8: 1077.7 | G8: 1078.2 | H8: 963.7 | I8: 824.3 | J8: 530.3 | K8: 661.2 | L8: 485.4 | M8: 1278.9 | N8: 1225.6 | O8: 670.7 | P8: 117.4 | Q8: 310.3 | R8: 9223.7
E9: CÓRDOBA | F9: 10197.6 | G9: 17608 | H9: 35464.8 | I9: 49602.8 | J9: 35457.8 | K9: 32482.5 | L9: 27250.7 | M9: 23693.1 | N9: 21537.3 | O9: 23717.9 | P9: 13944.2 | Q9: 16178.9 | R9: 307135.6
E10: GRANADA | F10: 1923.6 | G10: 3701.8 | H10: 11833.9 | I10: 15314.8 | J10: 12085.1 | K10: 9479.2 | L10: 9594.4 | M10: 11698.8 | N10: 11641.5 | O10: 12903.1 | P10: 5653.7 | Q10: 8494.6 | R10: 114324.5
E11: HUELVA | F11: 979 | G11: 874.5 | H11: 1506.5 | I11: 852.3 | J11: 873.5 | K11: 292.7 | L11: 364.1 | M11: 246.4 | N11: 251.9 | O11: 668.4 | P11: 562.6 | Q11: 411.8 | R11: 7883.7
E12: JAÉN | F12: 22149.6 | G12: 20097 | H12: 38963.6 | I12: 60772.7 | J12: 52795.2 | K12: 46725.7 | L12: 41779 | M12: 46695.5 | N12: 49429.4 | O12: 61430.2 | P12: 48130.8 | Q12: 61375.5 | R12: 550344.2
E13: MÁLAGA | F13: 1322.2 | G13: 2846.1 | H13: 5294.5 | I13: 5295.5 | J13: 3703.5 | K13: 4078.8 | L13: 3910.8 | M13: 3404.9 | N13: 2003.4 | O13: 2023.7 | P13: 701.5 | Q13: 1020.9 | R13: 35605.8
E14: SEVILLA | F14: 10784.2 | G14: 14566.2 | H14: 14480.9 | I14: 12495.2 | J14: 10188 | K14: 10905.6 | L14: 9660.9 | M14: 10182.3 | N14: 8752.6 | O14: 5721.7 | P14: 3705.6 | Q14: 3425.9 | R14: 114869.1
E15: TOTAL: | F15: 48959.1 | G15: 61490.6 | H15: 109204.7 | I15: 145699 | J15: 116031.9 | K15: 105140.5 | L15: 93217.6 | M15: 97474.3 | N15: 94982.8 | O15: 107420.1 | P15: 73088.1 | Q15: 91432.5 | R15: 1144141.2
D16: ARAGÓN | E16: HUESCA | F16: 78.5 | G16: 683.1 | H16: 513.3 | I16: 221.4 | J16: 100.1 | K16: 30.5 | L16: 24.5 | M16: 19.9 | N16: 20.3 | O16: 9.5 | P16: 48.8 | Q16: 78.8 | R16: 1828.7
E17: TERUEL | F17: 495.4 | G17: 304.5 | H17: 307.3 | I17: 215.5 | J17: 251.8 | K17: 120.4 | L17: 66 | M17: 86.9 | N17: 177.2 | O17: 379.5 | P17: 93.4 | Q17: 119.3 | R17: 2617.2
E18: ZARAGOZA | F18: 92.6 | G18: 211.9 | H18: 426.3 | I18: 679 | J18: 557.1 | K18: 368.1 | L18: 435.9 | M18: 339.7 | N18: 215.3 | O18: 167.3 | P18: 74.2 | Q18: 122.8 | R18: 3690.2
E19: TOTAL: | F19: 666.5 | G19: 1199.5 | H19: 1246.9 | I19: 1115.9 | J19: 909 | K19: 519 | L19: 526.4 | M19: 446.5 | N19: 412.8 | O19: 556.3 | P19: 216.4 | Q19: 320.9 | R19: 8136.1
D20: BALEARES | E20: BALEARES | F20: 78.2 | G20: 58.1 | H20: 12.5 | I20: 19.4 | J20: 17.6 | K20: 15.2 | L20: 18.8 | M20: 15.3 | N20: 14.9 | O20: 15.3 | P20: 12 | Q20: 25.2 | R20: 302.5
E21: TOTAL: | F21: 78.2 | G21: 58.1 | H21: 12.5 | I21: 19.4 | J21: 17.6 | K21: 15.2 | L21: 18.8 | M21: 15.3 | N21: 14.9 | O21: 15.3 | P21: 12 | Q21: 25.2 | R21: 302.5
D22: COMUNIDAD VALENCIANA | E22: ALICANTE | F22: 101.5 | G22: 439.6 | H22: 532 | I22: 658.7 | J22: 266.5 | K22: 357.4 | L22: 520.9 | M22: 443.2 | N22: 235.1 | O22: 124.9 | P22: 59.7 | Q22: 74.5 | R22: 3814
E23: CASTELLÓN | F23: 271.9 | G23: 178.7 | H23: 90.5 | I23: 49.1 | J23: 66.8 | K23: 15.5 | L23: 7.5 | M23: 7.7 | N23: 3.4 | O23: 6.3 | P23: 4.3 | Q23: 40.8 | R23: 742.5
E24: VALENCIA | F24: 94.5 | G24: 206 | H24: 295.9 | I24: 190.7 | J24: 151.5 | K24: 146.8 | L24: 84.9 | M24: 43.3 | N24: 51.2 | O24: 25.2 | P24: 13.9 | Q24: 24.5 | R24: 1328.4
E25: TOTAL: | F25: 467.9 | G25: 824.3 | H25: 918.4 | I25: 898.5 | J25: 484.8 | K25: 519.7 | L25: 613.3 | M25: 494.2 | N25: 289.7 | O25: 156.4 | P25: 77.9 | Q25: 139.8 | R25: 5884.9
D26: CANARIAS | E26: LAS PALMAS | F26: 0 | G26: 0 | H26: 0 | I26: 0 | J26: 0 | K26: 0 | L26: 0 | M26: 0 | N26: 0 | O26: 0 | P26: 0 | Q26: 0 | R26: 0
E27: STA. CRUZ DE TENERIFE | F27: 1.4 | G27: 0 | H27: 0 | I27: 0 | J27: 0 | K27: 0 | L27: 0 | M27: 0 | N27: 0 | O27: 0 | P27: 0 | Q27: 0 | R27: 1.4
E28: TOTAL: | F28: 1.4 | G28: 0 | H28: 0 | I28: 0 | J28: 0 | K28: 0 | L28: 0 | M28: 0 | N28: 0 | O28: 0 | P28: 0 | Q28: 0 | R28: 1.4
D29: CASTILLA-LA MANCHA | E29: ALBACETE | F29: 702.6 | G29: 868.1 | H29: 1430.1 | I29: 1465.9 | J29: 1039.2 | K29: 1355 | L29: 982.5 | M29: 499.5 | N29: 620.5 | O29: 777.6 | P29: 478.8 | Q29: 576.9 | R29: 10796.7
E30: CIUDAD REAL | F30: 3796.8 | G30: 3212.5 | H30: 9715.4 | I30: 9466.5 | J30: 6868.7 | K30: 8152.5 | L30: 7995.7 | M30: 5728.6 | N30: 6020.7 | O30: 8272.9 | P30: 4023.9 | Q30: 3892.3 | R30: 77146.5
E31: CUENCA | F31: 182.1 | G31: 147.1 | H31: 318.5 | I31: 500.7 | J31: 653.4 | K31: 520.5 | L31: 729.8 | M31: 466.8 | N31: 394.7 | O31: 467.6 | P31: 260.5 | Q31: 272.7 | R31: 4914.4
E32: GUADALAJARA | F32: 19.1 | G32: 22.9 | H32: 115.2 | I32: 309.9 | J32: 173.3 | K32: 292.4 | L32: 93.3 | M32: 47.6 | N32: 307.1 | O32: 184.4 | P32: 114.2 | Q32: 243.8 | R32: 1923.2
E33: TOLEDO | F33: 3005.5 | G33: 2451.9 | H33: 3961.3 | I33: 7588.1 | J33: 6563.8 | K33: 4783.4 | L33: 3603.3 | M33: 5344.6 | N33: 6134.5 | O33: 7665.7 | P33: 3966.9 | Q33: 3959.8 | R33: 59028.8
E34: TOTAL: | F34: 7706.1 | G34: 6702.5 | H34: 15540.5 | I34: 19331.1 | J34: 15298.4 | K34: 15103.8 | L34: 13404.6 | M34: 12087.1 | N34: 13477.5 | O34: 17368.2 | P34: 8844.3 | Q34: 8945.5 | R34: 153809.6
D35: CASTILLA Y LEÓN | E35: ÁVILA | F35: 0 | G35: 3.4 | H35: 89.4 | I35: 430.2 | J35: 29.8 | K35: 27 | L35: 7.7 | M35: 127.6 | N35: 7.3 | O35: 68.5 | P35: 1.1 | Q35: 27.4 | R35: 819.4
E36: SALAMANCA | F36: 0.5 | G36: 0.3 | H36: 28.7 | I36: 82.8 | J36: 0.1 | K36: 67.3 | L36: 19.5 | M36: 2 | N36: 1.6 | O36: 1.3 | P36: 1.3 | Q36: 0.6 | R36: 206
E37: SORIA | F37: 0 | G37: 0 | H37: 0 | I37: 0 | J37: 0.2 | K37: 0.2 | L37: 0 | M37: 0 | N37: 0 | O37: 0 | P37: 0 | Q37: 0 | R37: 0.4
E38: OTRAS | F38: 19.9 | G38: 8.8 | H38: 13.2 | I38: 13.8 | J38: 10.7 | K38: 23.1 | L38: 10.3 | M38: 48.1 | N38: 95.1 | O38: 5.8 | P38: 8.1 | Q38: 64.8 | R38: 321.7
E39: TOTAL: | F39: 20.4 | G39: 12.5 | H39: 131.3 | I39: 526.8 | J39: 40.8 | K39: 117.6 | L39: 37.5 | M39: 177.7 | N39: 104 | O39: 75.6 | P39: 10.5 | Q39: 92.8 | R39: 1347.5
D40: CATALUÑA | E40: BARCELONA | F40: 82.8 | G40: 371.4 | H40: 145.1 | I40: 25.9 | J40: 2.2 | K40: 3.9 | L40: 2.9 | M40: 1.9 | N40: 1.7 | O40: 2.5 | P40: 1.2 | Q40: 1.9 | R40: 643.4
E41: GIRONA | F41: 29 | G41: 173.3 | H41: 149.4 | I41: 51.2 | J41: 16.3 | K41: 13 | L41: 12.4 | M41: 11.7 | N41: 21.2 | O41: 15 | P41: 16.8 | Q41: 16.5 | R41: 525.8
E42: LLEIDA | F42: 345.2 | G42: 1736.6 | H42: 1860.3 | I42: 975.6 | J42: 752.5 | K42: 650.2 | L42: 339.3 | M42: 587.7 | N42: 444.7 | O42: 301.9 | P42: 128.5 | Q42: 312.2 | R42: 8434.7
E43: TARRAGONA | F43: 606.1 | G43: 1893.5 | H43: 1348.5 | I43: 665.1 | J43: 509.8 | K43: 347.7 | L43: 192.6 | M43: 131.4 | N43: 128.8 | O43: 134.3 | P43: 67.8 | Q43: 229.8 | R43: 6255.4
E44: TOTAL: | F44: 1063.1 | G44: 4174.8 | H44: 3503.3 | I44: 1717.8 | J44: 1280.8 | K44: 1014.8 | L44: 547.2 | M44: 732.7 | N44: 596.4 | O44: 453.7 | P44: 214.3 | Q44: 560.4 | R44: 15859.3
...

Sheet 11_ALMAZARAS.ACEITUNA MOLTURADA
B5: 11_ALMAZARAS_ACEITUNA MOLTURADA
B9: COMUNIDAD AUTÓNOMA | C9: PROVINCIA | D9: OCTUBRE | E9: NOVIEMBRE | F9: DICIEMBRE | G9: ENERO | H9: FEBRERO | I9: MARZO | J9: ABRIL | K9: MAYO | L9: TOTAL
B10: ANDALUCÍA | C10: ALMERÍA | D10: 2601.3 | E10: 12795.5 | F10: 8542.7 | G10: 770.9 | H10: 63.4 | I10: 0 | J10: 0 | K10: 0 | L10: 24773.8
C11: CÁDIZ | D11: 6040.3 | E11: 27410.9 | F11: 18220.2 | G11: 2575.1 | H11: 105.9 | I11: 0 | J11: 0 | K11: 0 | L11: 54352.4
C12: CÓRDOBA | D12: 37720.2 | E12: 399895.3 | F12: 701593.5 | G12: 350624.6 | H12: 182482.7 | I12: 25256.9 | J12: 7728.1 | K12: 206.1 | L12: 1705507.4
C13: GRANADA | D13: 2025.4 | E13: 88008.4 | F13: 261931.2 | G13: 159563 | H13: 67386.1 | I13: 8052.1 | J13: 2246.1 | K13: 336.4 | L13: 589548.7
C14: HUELVA | D14: 7105.4 | E14: 29633.5 | F14: 15804.6 | G14: 728.9 | H14: 26.8 | I14: 0 | J14: 0 | K14: 0 | L14: 53299.2
C15: JAÉN | D15: 41626.1 | E15: 412552 | F15: 1232238.4 | G15: 796995.1 | H15: 354592.8 | I15: 12493.4 | J15: 1481.3 | K15: 134.9 | L15: 2852114
C16: MÁLAGA | D16: 10072.1 | E16: 60124.4 | F16: 78927.1 | G16: 36746 | H16: 15837 | I16: 2846.3 | J16: 1801.8 | K16: 30.9 | L16: 206385.6
C17: SEVILLA | D17: 95190.8 | E17: 266170.3 | F17: 291326.1 | G17: 74293.6 | H17: 9206.1 | I17: 578.8 | J17: 0 | K17: 0 | L17: 736765.7
C18: TOTAL: | D18: 202381.6 | E18: 1296590.3 | F18: 2608583.8 | G18: 1422297.2 | H18: 629700.8 | I18: 49227.5 | J18: 13257.3 | K18: 708.3 | L18: 6222746.8
B19: ARAGÓN | C19: HUESCA | D19: 627.3 | E19: 8086.6 | F19: 3707.2 | G19: 501.8 | H19: 0 | I19: 1.7 | J19: 0 | K19: 0 | L19: 12924.6
C20: TERUEL | D20: 455.7 | E20: 7608.9 | F20: 2340.9 | G20: 1079.3 | H20: 80.4 | I20: 0 | J20: 31.2 | K20: 0 | L20: 11596.4
C21: ZARAGOZA | D21: 497.5 | E21: 12207.7 | F21: 11485.6 | G21: 1502.4 | H21: 75.1 | I21: 0 | J21: 0 | K21: 0 | L21: 25768.3
C22: TOTAL: | D22: 1580.5 | E22: 27903.2 | F22: 17533.7 | G22: 3083.5 | H22: 155.5 | I22: 1.7 | J22: 31.2 | K22: 0 | L22: 50289.3
B23: BALEARES | C23: BALEARES | D23: 1163.2 | E23: 748.7 | F23: 18.2 | G23: 0 | H23: 0 | I23: 0 | J23: 0 | K23: 0 | L23: 1930.1
C24: TOTAL: | D24: 1163.2 | E24: 748.7 | F24: 18.2 | G24: 0 | H24: 0 | I24: 0 | J24: 0 | K24: 0 | L24: 1930.1
B25: CANARIAS | C25: LAS PALMAS | D25: 0 | E25: 0 | F25: 0 | G25: 0 | H25: 0 | I25: 0 | J25: 0 | K25: 0 | L25: 0
C26: STA. CRUZ DE TENERIFE | D26: 13.5 | E26: 0.3 | F26: 0 | G26: 0 | H26: 0 | I26: 0 | J26: 0 | K26: 0 | L26: 13.8
C27: TOTAL: | D27: 13.5 | E27: 0.3 | F27: 0 | G27: 0 | H27: 0 | I27: 0 | J27: 0 | K27: 0 | L27: 13.8
B28: CASTILLA-LA MANCHA | C28: ALBACETE | D28: 858.7 | E28: 21910.7 | F28: 29034.2 | G28: 4057.3 | H28: 554.6 | I28: 78.6 | J28: 0 | K28: 0 | L28: 56494.1
C29: CIUDAD REAL | D29: 2402.1 | E29: 67549.7 | F29: 184995.4 | G29: 91964.7 | H29: 17572.5 | I29: 164.8 | J29: 0 | K29: 0 | L29: 364649.2
C30: CUENCA | D30: 113.7 | E30: 4581.5 | F30: 15455.8 | G30: 5424.7 | H30: 1571.4 | I30: 76.9 | J30: 32.8 | K30: 0 | L30: 27256.8
C31: GUADALAJARA | D31: 0 | E31: 1317.8 | F31: 4619.9 | G31: 2859.9 | H31: 1863.4 | I31: 357.3 | J31: 62.7 | K31: 0 | L31: 11081
C32: TOLEDO | D32: 2338 | E32: 38125.8 | F32: 119786 | G32: 79159.9 | H32: 41422.6 | I32: 4525.9 | J32: 137.5 | K32: 0 | L32: 285495.7
C33: TOTAL: | D33: 5712.5 | E33: 133485.5 | F33: 353891.3 | G33: 183466.5 | H33: 62984.5 | I33: 5203.5 | J33: 233 | K33: 0 | L33: 744976.8
B34: CASTILLA Y LEÓN | C34: ÁVILA | D34: 0 | E34: 2212.2 | F34: 3276.8 | G34: 6 | H34: 0 | I34: 0 | J34: 0 | K34: 0 | L34: 5495
C35: SALAMANCA | D35: 148.1 | E35: 2150.1 | F35: 149.7 | G35: 0 | H35: 0 | I35: 0 | J35: 0 | K35: 0 | L35: 2447.9
C36: SORIA | D36: 0 | E36: 2 | F36: 0 | G36: 0 | H36: 0 | I36: 0 | J36: 0 | K36: 0 | L36: 2
C37: OTRAS | D37: 0 | E37: 2207.1 | F37: 693.4 | G37: 0 | H37: 0 | I37: 0 | J37: 0 | K37: 0 | L37: 2900.5
C38: TOTAL: | D38: 148.1 | E38: 6571.4 | F38: 4119.9 | G38: 6 | H38: 0 | I38: 0 | J38: 0 | K38: 0 | L38: 10845.4
B39: CATALUÑA | C39: BARCELONA | D39: 743.3 | E39: 3124.8 | F39: 1049.7 | G39: 83.3 | H39: 0 | I39: 0 | J39: 0 | K39: 0 | L39: 5001.1
C40: GIRONA | D40: 500.6 | E40: 2659.3 | F40: 1153.6 | G40: 89.6 | H40: 0 | I40: 0 | J40: 0 | K40: 0 | L40: 4403.1
C41: LLEIDA | D41: 3418.9 | E41: 32817.8 | F41: 22417.9 | G41: 2239.9 | H41: 0 | I41: 0 | J41: 0 | K41: 0 | L41: 60894.5
C42: TARRAGONA | D42: 3700.9 | E42: 26567 | F42: 9608.6 | G42: 1117.8 | H42: 403.2 | I42: 0 | J42: 0 | K42: 0 | L42: 41397.5
