Workbook

Sheet Informe Mensual Julio 2026
D10: INFORME MENSUAL DE LA SITUACIÓN DE MERCADO DEL SECTOR DEL ACEITE DE OLIVA Y LA ACEITUNA DE MESA
G15: CAMPAÑA 2025/26
E18: Datos a 31 de julio de 2026
A24: El Sistema de Información de los Mercados Oleícolas (SIMO) es un sistema de información en base informática, gestionado por el MAPA a través de la Agencia de Información y Control Alimentarios (AICA), que contiene el censo nacional de instalaciones y operadores oleícolas y la información de mercados resultante de las declaraciones obligatorias establecidas en el Real Decreto 861/2018, de 13 de julio. El presente INFORME MENSUAL pone a disposición de la totalidad del sector olivarero los datos consolidados de mercado de aceite de oliva, aceite de orujo de oliva y aceituna de mesa relativos al mes anterior al que se realiza esta publicación.
A36: Aviso legal: Esta información puede ser utilizada en parte o en su integridad, sin necesidad de autorización expresa, siempre que se cite la fuente de los documentos objeto de la reutilización.
A38: Elaboración: Subdirección General de Cultivos Herbáceos, Industriales y Aceite de Oliva. Dirección General de Producciones y Mercados Agrarios. Ministerio de Agricultura, Pesca y Alimentación.
A42: Título: Informe Mensual de Situación de Mercado del Aceite de Oliva y la Aceituna de Mesa.
A43: NIPO: 003-25-020-0
A44: Catálogo de Publicaciones de la Administración General del Estado: https://cpage.mpr.gob.es/

Sheet 01_BALANCE EXISTENCIAS FÍSICAS
D2: 01_BALANCE DE EXISTENCIAS FÍSICAS
B6: MES | C6: EXIST. INICIALES | D6: PRODUCCION | E6: IMPORTACIONES | F6: CONSUMO INTERIOR | G6: EXPORTACIONES | H6: EXIST. FINALES
B8: OCTUBRE | C8: 289.67157 | D8: 43.145437 | E8: 9.142 | F8: 37.725167 | G8: 77.968 | H8: 226.26584
B9: NOVIEMBRE | C9: 226.26584 | D9: 260.50073 | E9: 25.176 | F9: 46.124202 | G9: 72.297 | H9: 393.52137
B10: DICIEMBRE | C10: 393.52137 | D10: 425.2894 | E10: 27.878 | F10: 46.919313 | G10: 72.192 | H10: 727.57746
B11: ENERO | C11: 727.57746 | D11: 329.97485 | E11: 18.731 | F11: 41.017115 | G11: 79.191 | H11: 956.07519
B12: FEBRERO | C12: 956.07519 | D12: 143.39104 | E12: 21.02 | F12: 45.615915 | G12: 89.276 | H12: 985.59432
B13: MARZO | C13: 985.59432 | D13: 84.993297 | E13: 27.547 | F13: 48.161457 | G13: 97.917 | H13: 952.05616
B14: ABRIL | C14: 952.05616 | D14: 12.211432 | E14: 23.062 | F14: 32.422952 | G14: 86.625 | H14: 868.28164
B15: MAYO | C15: 868.28164 | D15: 1.4293088 | E15: 24.994 | F15: 30.781539 | G15: 85.095 | H15: 778.82841
B16: JUNIO | C16: 778.82841 | E16: 23.636 | F16: 34.92359 | G16: 83.879 | H16: 683.66182
B17: JULIO | C17: 683.66182 | E17: 16 | F17: 41.37513 | G17: 89 | H17: 569.28669
B18: AGOSTO
B19: SEPTIEMBRE
D20: =SUM(D8:D15) -> 1300.9355 | E20: =+SUM(E8:E19) -> 217.186 | F20: =+SUM(F8:F19) -> 405.06638 | G20: =+SUM(G8:G19) -> 833.44
C22: DATOS PROVISIONALES | F22: TOTAL MERCADO: | G22: =F20+G20 -> 1238.5064
B24: EXPORTACIONES | E24: EXPORTACIONES
C25: EXPORTACIONES | E25: PAÍSES TERCEROS | F25: UE
F26: ITALIA | G26: OTROS
B27: OCTUBRE | C27: 77.968 | E27: 36.524 | F27: 18.109 | G27: 23.335
B28: NOVIEMBRE | C28: 72.297 | E28: 32.292 | F28: 21.965 | G28: 18.04
B29: DICIEMBRE | C29: 72.192 | E29: 29.43 | F29: 24.281 | G29: 18.481
B30: ENERO | C30: 79.191 | E30: 26.315 | F30: 28.772 | G30: 24.104
B31: FEBRERO | C31: 89.276 | E31: 33.022 | F31: 32.152 | G31: 24.102
B32: MARZO | C32: 97.917 | E32: 38.976 | F32: 30.74 | G32: 28.201
B33: ABRIL | C33: 86.625 | E33: 36.085 | F33: 25.295 | G33: 25.245
B34: MAYO | C34: 85.095 | E34: 39.058 | F34: 24.12 | G34: 21.917
B35: JUNIO | C35: 83.879 | E35: 38.14 | F35: 23.023 | G35: 22.716
B36: JULIO | C36: 89
B37: AGOSTO
B38: SEPTIEMBRE
C39: =SUM(C27:C38) -> 833.44 | E39: =SUM(E27:E38) -> 309.842 | F39: =SUM(F27:F38) -> 228.457 | G39: =SUM(G27:G38) -> 206.141
E40: =SUM(E39:G39) -> 744.44
B43: TOTAL MERCADO INTERIOR APARENTE | E43: IMPORTACIONES
C44: TOTAL | E44: PAÍSES TERCEROS | F44: UE
F45: ITALIA | G45: OTROS
B46: OCTUBRE | C46: 37.725167 | E46: 5.243 | F46: 0.609 | G46: 3.29
B47: NOVIEMBRE | C47: 46.124202 | E47: 8.75 | F47: 0.908 | G47: 15.518
B48: DICIEMBRE | C48: 46.919313 | E48: 11.292 | F48: 1.824 | G48: 14.762
B49: ENERO | C49: 41.017115 | E49: 10.442 | F49: 0.976 | G49: 7.313
...

Sheet 02_CUADRYGRÁF.COMP.ÚLT.5 CAMP.
D2: 02_CUADROS Y GRÁFICOS COMPARATIVOS
C6: PRODUCCIÓN | I6: PRODUCCIÓN
C7: 2021/22 | D7: 2022/23 | E7: 2023/24 | F7: 2024/25 | G7: 2025/26
B8: OCTUBRE | C8: 51.3461 | D8: 30.6714 | E8: 38.6693 | F8: 36.869638 | G8: 43.145437
B9: NOVIEMBRE | C9: 288.1698 | D9: 169.0176 | E9: 230.0143 | F9: 266.67029 | G9: 260.50073
B10: DICIEMBRE | C10: 542.71 | D10: 238.8635 | E10: 328.4806 | F10: 596.431 | G10: 425.2894
B11: ENERO | C11: 471.1874 | D11: 182.3524 | E11: 188.1869 | F11: 351.4809 | G11: 329.97485
B12: FEBRERO | C12: 108.8072 | D12: 36.0774 | E12: 53.142 | F12: 154.0704 | G12: 143.39104
B13: MARZO | C13: 20.7576 | D13: 8.0173 | E13: 14.0971 | F13: 12.203774 | G13: 84.993297
B14: ABRIL | C14: 7.1167 | D14: 0.9722 | E14: 2.7941 | F14: 3.1651061 | G14: 12.211432
B15: MAYO | C15: 2.9136 | D15: 0.0409 | E15: 0.1924 | F15: 0.22164383 | G15: 1.4293088
B16: JUNIO
B17: JULIO
B18: AGOSTO
B19: SEPTIEMBRE
C20: =+SUM(C8:C19) -> 1493.0084 | D20: =+SUM(D8:D19) -> 666.0127 | E20: =+SUM(E8:E19) -> 855.5767 | F20: =+SUM(F8:F19) -> 1421.1127 | G20: =+SUM(G8:G19) -> 1300.9355
C23: IMPORTACIONES | I23: IMPORTACIONES
C24: 2021/22 | D24: 2022/23 | E24: 2023/24 | F24: 2024/25 | G24: 2025/26
B25: OCTUBRE | C25: 12.69769 | D25: 13.250511 | E25: 14.465849 | F25: 15.916 | G25: 9.142
B26: NOVIEMBRE | C26: 18.94698 | D26: 22.196355 | E26: 28.280685 | F26: 23.576 | G26: 25.176
B27: DICIEMBRE | C27: 35.59424 | D27: 35.413639 | E27: 26.757532 | F27: 30.592 | G27: 27.878
B28: ENERO | C28: 12.83714 | D28: 13.040041 | E28: 18.214635 | F28: 17.385 | G28: 18.731
B29: FEBRERO | C29: 17.4196 | D29: 19.216602 | E29: 20.514472 | F29: 19.042 | G29: 21.02
B30: MARZO | C30: 12.03758 | D30: 17.429422 | E30: 21.408031 | F30: 22.052 | G30: 27.547
B31: ABRIL | C31: 21.93187 | D31: 10.323654 | E31: 23.6309 | F31: 16.635 | G31: 23.062
B32: MAYO | C32: 20.42955 | D32: 14.328993 | E32: 20.321337 | F32: 15.277 | G32: 24.994
B33: JUNIO | C33: 16.47469 | D33: 16.168545 | E33: 17.351097 | F33: 14.541 | G33: 23.636
B34: JULIO | C34: 12.6548 | D34: 19.188001 | E34: 21.684971 | F34: 13.11 | G34: 16
B35: AGOSTO | C35: 20.24787 | D35: 14.861437 | E35: 15.398776 | F35: 6.765
B36: SEPTIEMBRE | C36: 11.52141 | D36: 19.744252 | E36: 15.20674 | F36: 11.168
C37: =+SUM(C25:C36) -> 212.79342 | D37: =+SUM(D25:D36) -> 215.16145 | E37: =+SUM(E25:E36) -> 243.23502 | F37: =+SUM(F25:F36) -> 206.059 | G37: =+SUM(G25:G36) -> 217.186
C40: EXPORTACIONES | I40: EXPORTACIONES
C41: 2021/22 | D41: 2022/23 | E41: 2023/24 | F41: 2024/25 | G41: 2025/26
B42: OCTUBRE | C42: 83.49778 | D42: 88.527712 | E42: 55.755136 | F42: 60.278 | G42: 77.968
B43: NOVIEMBRE | C43: 83.40845 | D43: 67.690599 | E43: 52.714599 | F43: 59.937 | G43: 72.297
B44: DICIEMBRE | C44: 81.42683 | D44: 63.56878 | E44: 59.829063 | F44: 69.723 | G44: 72.192
B45: ENERO | C45: 73.74592 | D45: 55.971191 | E45: 69.545024 | F45: 89.304 | G45: 79.191
B46: FEBRERO | C46: 88.32957 | D46: 48.263341 | E46: 64.995784 | F46: 90.628 | G46: 89.276
B47: MARZO | C47: 78.29797 | D47: 64.195956 | E47: 60.61064 | F47: 96.981 | G47: 97.917
B48: ABRIL | C48: 107.33327 | D48: 51.589896 | E48: 74.409194 | F48: 98.778 | G48: 86.625
...

Sheet 03_CUADRYGRÁF.COMP.5 ÚLT.CAMP.
G2: 03_CUADROS Y GRÁFICOS COMPARATIVOS
F6: EXISTENCIAS EN ALMAZARAS Y PATRIMONIO | L6: EXISTENCIAS EN ALMAZARAS Y PATRIMONIO
F7: 2021/22 | G7: 2022/23 | H7: 2023/24 | I7: 2024/25 | J7: 2025/26
E8: OCTUBRE | F8: 171.77332 | G8: 155.70437 | H8: 82.32439 | I8: 54.82129 | J8: 97.73275
E9: NOVIEMBRE | F9: 345.36574 | G9: 234.30274 | H9: 236.68863 | I9: 236.50213 | J9: 258.26741
E10: DICIEMBRE | F10: 740.3346 | G10: 396.56389 | H10: 471.98805 | I10: 697.73919 | J10: 562.22155
E11: ENERO | F11: 1055.0071 | G11: 503.45074 | H11: 554.38471 | I11: 888.37991 | J11: 740.16749
E12: FEBRERO | F12: 1024.6867 | G12: 474.38193 | H12: 527.90193 | I12: 905.64439 | J12: 749.92599
E13: MARZO | F13: 931.13413 | G13: 409.40063 | H13: 474.62288 | I13: 788.05705 | J13: 703.55987
E14: ABRIL | F14: 796.21762 | G14: 350.80297 | H14: 399.02365 | I14: 678.02169 | J14: 609.79009
E15: MAYO | F15: 664.7652 | G15: 271.39996 | H15: 320.47839 | I15: 563.77397 | J15: 513.94209
E16: JUNIO | F16: 534.84076 | G16: 211.13154 | H16: 252.31005 | I16: 449.60961 | J16: 424.58381
E17: JULIO | F17: 425.1501 | G17: 159.67197 | H17: 189.36771 | I17: 321.44963 | J17: 333.51109
E18: AGOSTO | F18: 331.1421 | G18: 125.4556 | H18: 139.47251 | I18: 239.81247
E19: SEPTIEMBRE | F19: 227.69511 | G19: 84.41313 | H19: 78.30593 | I19: 141.15647
F23: EXISTENCIAS EN ENVASADORAS | L23: EXISTENCIAS EN ENVASADORAS
F24: 2021/22 | G24: 2022/23 | H24: 2023/24 | I24: 2024/25 | J24: 2025/26
E25: OCTUBRE | F25: 192.8152 | G25: 212.1038 | H25: 137.9716 | I25: 86.1281 | J25: 128.53309
E26: NOVIEMBRE | F26: 195.1934 | G26: 217.5282 | H26: 142.2327 | I26: 94.3178 | J26: 135.25396
E27: DICIEMBRE | F27: 245.3619 | G27: 242.4611 | H27: 165.082 | I27: 136.1557 | J27: 165.35591
E28: ENERO | F28: 286.8885 | G28: 260.6573 | H28: 180.8159 | I28: 175.6466 | J28: 215.9077
E29: FEBRERO | F29: 310.8052 | G29: 266.7058 | H29: 184.7597 | I29: 200.2976 | J29: 235.66833
E30: MARZO | F30: 288.1855 | G30: 262.414 | H30: 183.4505 | I30: 211.5532 | J30: 248.49629
E31: ABRIL | F31: 288.609 | G31: 259.055 | H31: 177.3172 | I31: 206.9377 | J31: 258.49155
E32: MAYO | F32: 284.6648 | G32: 260.2675 | H32: 170.4718 | I32: 200.4743 | J32: 264.88632
E33: JUNIO | F33: 274.2026 | G33: 245.4191 | H33: 162.5891 | I33: 196.7411 | J33: 259.07801
E34: JULIO | F34: 272.5664 | G34: 223.768 | H34: 152.9032 | I34: 189.2779 | J34: 235.7756
E35: AGOSTO | F35: 249.8163 | G35: 195.6963 | H35: 132.1592 | I35: 166.1164
E36: SEPTIEMBRE | F36: 226.9114 | G36: 163.8269 | H36: 108.563 | I36: 148.5159
F40: EXISTENCIAS TOTALES | L40: EXISTENCIAS TOTALES
F41: 2021/22 | G41: 2022/23 | H41: 2023/24 | I41: 2024/25 | J41: 2025/26
E42: OCTUBRE | F42: 364.58852 | G42: 367.80817 | H42: 220.29599 | I42: 140.94939 | J42: 226.26584
E43: NOVIEMBRE | F43: 540.55914 | G43: 451.83094 | H43: 378.92133 | I43: 330.81993 | J43: 393.52137
E44: DICIEMBRE | F44: 985.6965 | G44: 639.02499 | H44: 637.07005 | I44: 833.89489 | J44: 727.57746
E45: ENERO | F45: 1341.8956 | G45: 764.10804 | H45: 735.20061 | I45: 1064.0265 | J45: 956.07519
E46: FEBRERO | F46: 1335.4919 | G46: 741.08773 | H46: 712.66163 | I46: 1105.942 | J46: 985.59432
E47: MARZO | F47: 1219.3196 | G47: 671.81463 | H47: 658.07338 | I47: 999.61025 | J47: 952.05616
E48: ABRIL | F48: 1084.8266 | G48: 609.85797 | H48: 576.34085 | I48: 884.95939 | J48: 868.28164
E49: MAYO | F49: 949.43 | G49: 531.66746 | H49: 490.95019 | I49: 764.24827 | J49: 778.82841
E50: JUNIO | F50: 809.04336 | G50: 456.55064 | H50: 414.89915 | I50: 646.35071 | J50: 683.66182
...

Sheet 04_CUADROS ACUMULADOS
E2: 04_CUADROS ACUMULADOS
D6: PRODUCCIÓN ACUMULADA
D7: 2021/22 | E7: 2022/23 | F7: 2023/24 | G7: 2024/25 | H7: 2025/26 | I7: % 2025 s. 2024 | J7: % 2025 s. Media tres | K7: % 2025 s. Media cuatro
C8: OCTUBRE | D8: =+'02_CUADRYGRÁF.COMP.ÚLT.5 CAMP.'!C8 -> 51.3461 | E8: =+'02_CUADRYGRÁF.COMP.ÚLT.5 CAMP.'!D8 -> 30.6714 | F8: =+'02_CUADRYGRÁF.COMP.ÚLT.5 CAMP.'!E8 -> 38.6693 | G8: =+'02_CUADRYGRÁF.COMP.ÚLT.5 CAMP.'!F8 -> 36.869638 | H8: =+IF(ISNUMBER('02_CUADRYGRÁF.COMP.ÚLT.5 CAMP.'!G8),'02_CUADRYGRÁF.COMP.ÚLT.5 CAMP.'!G8,NA()) -> 43.145437 | I8: =IF(ISNUMBER(H8),H8/G8-1,"") -> 0.1702159 | J8: =IF(ISNUMBER(H8),H8/AVERAGE(E8:G8)-1,"") -> 0.21867902 | K8: =IF(ISNUMBER(H8),H8/AVERAGE(D8:G8)-1,"") -> 0.095364617
C9: NOVIEMBRE | D9: =+'02_CUADRYGRÁF.COMP.ÚLT.5 CAMP.'!C9+'04_CUADROS ACUMULADOS'!D8 -> 339.5159 | E9: =+'02_CUADRYGRÁF.COMP.ÚLT.5 CAMP.'!D9+'04_CUADROS ACUMULADOS'!E8 -> 199.689 | F9: =+'02_CUADRYGRÁF.COMP.ÚLT.5 CAMP.'!E9+'04_CUADROS ACUMULADOS'!F8 -> 268.6836 | G9: =+'02_CUADRYGRÁF.COMP.ÚLT.5 CAMP.'!F9+'04_CUADROS ACUMULADOS'!G8 -> 303.53993 | H9: =+IF(ISNUMBER('02_CUADRYGRÁF.COMP.ÚLT.5 CAMP.'!G9),('02_CUADRYGRÁF.COMP.ÚLT.5 CAMP.'!G9+H8),NA()) -> 303.64617 | I9: =IF(ISNUMBER(H9),H9/G9-1,"") -> 0.00035001425 | J9: =IF(ISNUMBER(H9),H9/AVERAGE(E9:G9)-1,"") -> 0.18010587 | K9: =IF(ISNUMBER(H9),H9/AVERAGE(D9:G9)-1,"") -> 0.092814118
C10: DICIEMBRE | D10: =+'02_CUADRYGRÁF.COMP.ÚLT.5 CAMP.'!C10+'04_CUADROS ACUMULADOS'!D9 -> 882.2259 | E10: =+'02_CUADRYGRÁF.COMP.ÚLT.5 CAMP.'!D10+'04_CUADROS ACUMULADOS'!E9 -> 438.5525 | F10: =+'02_CUADRYGRÁF.COMP.ÚLT.5 CAMP.'!E10+'04_CUADROS ACUMULADOS'!F9 -> 597.1642 | G10: =+'02_CUADRYGRÁF.COMP.ÚLT.5 CAMP.'!F10+'04_CUADROS ACUMULADOS'!G9 -> 899.97093 | H10: =+IF(ISNUMBER('02_CUADRYGRÁF.COMP.ÚLT.5 CAMP.'!G10),('02_CUADRYGRÁF.COMP.ÚLT.5 CAMP.'!G10+H9),NA()) -> 728.93557 | I10: =IF(ISNUMBER(H10),H10/G10-1,"") -> -0.19004542 | J10: =IF(ISNUMBER(H10),H10/AVERAGE(E10:G10)-1,"") -> 0.12973121 | K10: =IF(ISNUMBER(H10),H10/AVERAGE(D10:G10)-1,"") -> 0.034716736
C11: ENERO | D11: =+'02_CUADRYGRÁF.COMP.ÚLT.5 CAMP.'!C11+'04_CUADROS ACUMULADOS'!D10 -> 1353.4133 | E11: =+'02_CUADRYGRÁF.COMP.ÚLT.5 CAMP.'!D11+'04_CUADROS ACUMULADOS'!E10 -> 620.9049 | F11: =+'02_CUADRYGRÁF.COMP.ÚLT.5 CAMP.'!E11+'04_CUADROS ACUMULADOS'!F10 -> 785.3511 | G11: =+'02_CUADRYGRÁF.COMP.ÚLT.5 CAMP.'!F11+'04_CUADROS ACUMULADOS'!G10 -> 1251.4518 | H11: =+IF(ISNUMBER('02_CUADRYGRÁF.COMP.ÚLT.5 CAMP.'!G11),('02_CUADRYGRÁF.COMP.ÚLT.5 CAMP.'!G11+H10),NA()) -> 1058.9104 | I11: =IF(ISNUMBER(H11),H11/G11-1,"") -> -0.15385443 | J11: =IF(ISNUMBER(H11),H11/AVERAGE(E11:G11)-1,"") -> 0.19528987 | K11: =IF(ISNUMBER(H11),H11/AVERAGE(D11:G11)-1,"") -> 0.05597451
C12: FEBRERO | D12: =+'02_CUADRYGRÁF.COMP.ÚLT.5 CAMP.'!C12+'04_CUADROS ACUMULADOS'!D11 -> 1462.2205 | E12: =+'02_CUADRYGRÁF.COMP.ÚLT.5 CAMP.'!D12+'04_CUADROS ACUMULADOS'!E11 -> 656.9823 | F12: =+'02_CUADRYGRÁF.COMP.ÚLT.5 CAMP.'!E12+'04_CUADROS ACUMULADOS'!F11 -> 838.4931 | G12: =+'02_CUADRYGRÁF.COMP.ÚLT.5 CAMP.'!F12+'04_CUADROS ACUMULADOS'!G11 -> 1405.5222 | H12: =+IF(ISNUMBER('02_CUADRYGRÁF.COMP.ÚLT.5 CAMP.'!G12),('02_CUADRYGRÁF.COMP.ÚLT.5 CAMP.'!G12+H11),NA()) -> 1202.3015 | I12: =IF(ISNUMBER(H12),H12/G12-1,"") -> -0.14458737 | J12: =IF(ISNUMBER(H12),H12/AVERAGE(E12:G12)-1,"") -> 0.24333241 | K12: =IF(ISNUMBER(H12),H12/AVERAGE(D12:G12)-1,"") -> 0.10221532
C13: MARZO | D13: =+'02_CUADRYGRÁF.COMP.ÚLT.5 CAMP.'!C13+'04_CUADROS ACUMULADOS'!D12 -> 1482.9781 | E13: =+'02_CUADRYGRÁF.COMP.ÚLT.5 CAMP.'!D13+'04_CUADROS ACUMULADOS'!E12 -> 664.9996 | F13: =+'02_CUADRYGRÁF.COMP.ÚLT.5 CAMP.'!E13+'04_CUADROS ACUMULADOS'!F12 -> 852.5902 | G13: =+'02_CUADRYGRÁF.COMP.ÚLT.5 CAMP.'!F13+'04_CUADROS ACUMULADOS'!G12 -> 1417.726 | H13: =+IF(ISNUMBER('02_CUADRYGRÁF.COMP.ÚLT.5 CAMP.'!G13),('02_CUADRYGRÁF.COMP.ÚLT.5 CAMP.'!G13+H12),NA()) -> 1287.2948 | I13: =IF(ISNUMBER(H13),H13/G13-1,"") -> -0.092000317 | J13: =IF(ISNUMBER(H13),H13/AVERAGE(E13:G13)-1,"") -> 0.31566228 | K13: =IF(ISNUMBER(H13),H13/AVERAGE(D13:G13)-1,"") -> 0.16542248
C14: ABRIL | D14: =+'02_CUADRYGRÁF.COMP.ÚLT.5 CAMP.'!C14+'04_CUADROS ACUMULADOS'!D13 -> 1490.0948 | E14: =+'02_CUADRYGRÁF.COMP.ÚLT.5 CAMP.'!D14+'04_CUADROS ACUMULADOS'!E13 -> 665.9718 | F14: =+'02_CUADRYGRÁF.COMP.ÚLT.5 CAMP.'!E14+'04_CUADROS ACUMULADOS'!F13 -> 855.3843 | G14: =+'02_CUADRYGRÁF.COMP.ÚLT.5 CAMP.'!F14+'04_CUADROS ACUMULADOS'!G13 -> 1420.8911 | H14: =+IF(ISNUMBER('02_CUADRYGRÁF.COMP.ÚLT.5 CAMP.'!G14),('02_CUADRYGRÁF.COMP.ÚLT.5 CAMP.'!G14+H13),NA()) -> 1299.5062 | I14: =IF(ISNUMBER(H14),H14/G14-1,"") -> -0.085428725 | J14: =IF(ISNUMBER(H14),H14/AVERAGE(E14:G14)-1,"") -> 0.32501394 | K14: =IF(ISNUMBER(H14),H14/AVERAGE(D14:G14)-1,"") -> 0.17274902
C15: MAYO | D15: =+'02_CUADRYGRÁF.COMP.ÚLT.5 CAMP.'!C15+'04_CUADROS ACUMULADOS'!D14 -> 1493.0084 | E15: =+'02_CUADRYGRÁF.COMP.ÚLT.5 CAMP.'!D15+'04_CUADROS ACUMULADOS'!E14 -> 666.0127 | F15: =+'02_CUADRYGRÁF.COMP.ÚLT.5 CAMP.'!E15+'04_CUADROS ACUMULADOS'!F14 -> 855.5767 | G15: =+'02_CUADRYGRÁF.COMP.ÚLT.5 CAMP.'!F15+'04_CUADROS ACUMULADOS'!G14 -> 1421.1127 | H15: =+IF(ISNUMBER('02_CUADRYGRÁF.COMP.ÚLT.5 CAMP.'!G15),('02_CUADRYGRÁF.COMP.ÚLT.5 CAMP.'!G15+H14),NA()) -> 1300.9355 | I15: =IF(ISNUMBER(H15),H15/G15-1,"") -> -0.084565598 | J15: =IF(ISNUMBER(H15),H15/AVERAGE(E15:G15)-1,"") -> 0.32626623 | K15: =IF(ISNUMBER(H15),H15/AVERAGE(D15:G15)-1,"") -> 0.17314733
C16: JUNIO | D16: =+'02_CUADRYGRÁF.COMP.ÚLT.5 CAMP.'!C16+'04_CUADROS ACUMULADOS'!D15 -> 1493.0084 | E16: =+'02_CUADRYGRÁF.COMP.ÚLT.5 CAMP.'!D16+'04_CUADROS ACUMULADOS'!E15 -> 666.0127 | F16: =+'02_CUADRYGRÁF.COMP.ÚLT.5 CAMP.'!E16+'04_CUADROS ACUMULADOS'!F15 -> 855.5767 | G16: =+'02_CUADRYGRÁF.COMP.ÚLT.5 CAMP.'!F16+'04_CUADROS ACUMULADOS'!G15 -> 1421.1127 | H16: =+IF(ISNUMBER('02_CUADRYGRÁF.COMP.ÚLT.5 CAMP.'!G16),('02_CUADRYGRÁF.COMP.ÚLT.5 CAMP.'!G16+H15),NA()) -> #N/A | I16: =IF(ISNUMBER(H16),H16/G16-1,"") | J16: =IF(ISNUMBER(H16),H16/AVERAGE(E16:G16)-1,"") | K16: =IF(ISNUMBER(H16),H16/AVERAGE(D16:G16)-1,"")
C17: JULIO | D17: =+'02_CUADRYGRÁF.COMP.ÚLT.5 CAMP.'!C17+'04_CUADROS ACUMULADOS'!D16 -> 1493.0084 | E17: =+'02_CUADRYGRÁF.COMP.ÚLT.5 CAMP.'!D17+'04_CUADROS ACUMULADOS'!E16 -> 666.0127 | F17: =+'02_CUADRYGRÁF.COMP.ÚLT.5 CAMP.'!E17+'04_CUADROS ACUMULADOS'!F16 -> 855.5767 | G17: =+'02_CUADRYGRÁF.COMP.ÚLT.5 CAMP.'!F17+'04_CUADROS ACUMULADOS'!G16 -> 1421.1127 | H17: =+IF(ISNUMBER('02_CUADRYGRÁF.COMP.ÚLT.5 CAMP.'!G17),('02_CUADRYGRÁF.COMP.ÚLT.5 CAMP.'!G17+H16),NA()) -> #N/A | I17: =IF(ISNUMBER(H17),H17/G17-1,"") | J17: =IF(ISNUMBER(H17),H17/AVERAGE(E17:G17)-1,"") | K17: =IF(ISNUMBER(H17),H17/AVERAGE(D17:G17)-1,"")
C18: AGOSTO | D18: =+'02_CUADRYGRÁF.COMP.ÚLT.5 CAMP.'!C18+'04_CUADROS ACUMULADOS'!D17 -> 1493.0084 | E18: =+'02_CUADRYGRÁF.COMP.ÚLT.5 CAMP.'!D18+'04_CUADROS ACUMULADOS'!E17 -> 666.0127 | F18: =+'02_CUADRYGRÁF.COMP.ÚLT.5 CAMP.'!E18+'04_CUADROS ACUMULADOS'!F17 -> 855.5767 | G18: =+'02_CUADRYGRÁF.COMP.ÚLT.5 CAMP.'!F18+'04_CUADROS ACUMULADOS'!G17 -> 1421.1127 | H18: =+IF(ISNUMBER('02_CUADRYGRÁF.COMP.ÚLT.5 CAMP.'!G18),('02_CUADRYGRÁF.COMP.ÚLT.5 CAMP.'!G18+H17),NA()) -> #N/A | I18: =IF(ISNUMBER(H18),H18/G18-1,"") | J18: =IF(ISNUMBER(H18),H18/AVERAGE(E18:G18)-1,"") | K18: =IF(ISNUMBER(H18),H18/AVERAGE(D18:G18)-1,"")
C19: SEPTIEMBRE | D19: =+'02_CUADRYGRÁF.COMP.ÚLT.5 CAMP.'!C19+'04_CUADROS ACUMULADOS'!D18 -> 1493.0084 | E19: =+'02_CUADRYGRÁF.COMP.ÚLT.5 CAMP.'!D19+'04_CUADROS ACUMULADOS'!E18 -> 666.0127 | F19: =+'02_CUADRYGRÁF.COMP.ÚLT.5 CAMP.'!E19+'04_CUADROS ACUMULADOS'!F18 -> 855.5767 | G19: =+'02_CUADRYGRÁF.COMP.ÚLT.5 CAMP.'!F19+'04_CUADROS ACUMULADOS'!G18 -> 1421.1127 | H19: =+IF(ISNUMBER('02_CUADRYGRÁF.COMP.ÚLT.5 CAMP.'!G19),('02_CUADRYGRÁF.COMP.ÚLT.5 CAMP.'!G19+H18),NA()) -> #N/A | I19: =IF(ISNUMBER(H19),H19/G19-1,"") | J19: =IF(ISNUMBER(H19),H19/AVERAGE(E19:G19)-1,"") | K19: =IF(ISNUMBER(H19),H19/AVERAGE(D19:G19)-1,"")
D22: IMPORTACIÓN ACUMULADA
D23: 2021/22 | E23: 2022/23 | F23: 2023/24 | G23: 2024/25 | H23: 2025/26 | I23: % 2025 s. 2024 | J23: % 2025 s. Media tres | K23: % 2025 s. Media cuatro
C24: OCTUBRE | D24: =+'02_CUADRYGRÁF.COMP.ÚLT.5 CAMP.'!C25 -> 12.69769 | E24: =+'02_CUADRYGRÁF.COMP.ÚLT.5 CAMP.'!D25 -> 13.250511 | F24: =+'02_CUADRYGRÁF.COMP.ÚLT.5 CAMP.'!E25 -> 14.465849 | G24: =+'02_CUADRYGRÁF.COMP.ÚLT.5 CAMP.'!F25 -> 15.916 | H24: =+IF(ISNUMBER('02_CUADRYGRÁF.COMP.ÚLT.5 CAMP.'!G25),'02_CUADRYGRÁF.COMP.ÚLT.5 CAMP.'!G25,NA()) -> 9.142 | I24: =IF(ISNUMBER(H24),H24/G24-1,"") -> -0.42560945 | J24: =IF(ISNUMBER(H24),H24/AVERAGE(E24:G24)-1,"") -> -0.37142983 | K24: =IF(ISNUMBER(H24),H24/AVERAGE(D24:G24)-1,"") -> -0.35082607
C25: NOVIEMBRE | D25: =+'02_CUADRYGRÁF.COMP.ÚLT.5 CAMP.'!C26+'04_CUADROS ACUMULADOS'!D24 -> 31.64467 | E25: =+'02_CUADRYGRÁF.COMP.ÚLT.5 CAMP.'!D26+'04_CUADROS ACUMULADOS'!E24 -> 35.446866 | F25: =+'02_CUADRYGRÁF.COMP.ÚLT.5 CAMP.'!E26+'04_CUADROS ACUMULADOS'!F24 -> 42.746534 | G25: =+'02_CUADRYGRÁF.COMP.ÚLT.5 CAMP.'!F26+'04_CUADROS ACUMULADOS'!G24 -> 39.492 | H25: =+IF(ISNUMBER('02_CUADRYGRÁF.COMP.ÚLT.5 CAMP.'!G26),('02_CUADRYGRÁF.COMP.ÚLT.5 CAMP.'!G26+H24),NA()) -> 34.318 | I25: =IF(ISNUMBER(H25),H25/G25-1,"") -> -0.13101388 | J25: =IF(ISNUMBER(H25),H25/AVERAGE(E25:G25)-1,"") -> -0.12517611 | K25: =IF(ISNUMBER(H25),H25/AVERAGE(D25:G25)-1,"") -> -0.080747769
C26: DICIEMBRE | D26: =+'02_CUADRYGRÁF.COMP.ÚLT.5 CAMP.'!C27+'04_CUADROS ACUMULADOS'!D25 -> 67.23891 | E26: =+'02_CUADRYGRÁF.COMP.ÚLT.5 CAMP.'!D27+'04_CUADROS ACUMULADOS'!E25 -> 70.860505 | F26: =+'02_CUADRYGRÁF.COMP.ÚLT.5 CAMP.'!E27+'04_CUADROS ACUMULADOS'!F25 -> 69.504066 | G26: =+'02_CUADRYGRÁF.COMP.ÚLT.5 CAMP.'!F27+'04_CUADROS ACUMULADOS'!G25 -> 70.084 | H26: =+IF(ISNUMBER('02_CUADRYGRÁF.COMP.ÚLT.5 CAMP.'!G27),('02_CUADRYGRÁF.COMP.ÚLT.5 CAMP.'!G27+H25),NA()) -> 62.196 | I26: =IF(ISNUMBER(H26),H26/G26-1,"") -> -0.11255065 | J26: =IF(ISNUMBER(H26),H26/AVERAGE(E26:G26)-1,"") -> -0.11337958 | K26: =IF(ISNUMBER(H26),H26/AVERAGE(D26:G26)-1,"") -> -0.10408637
C27: ENERO | D27: =+'02_CUADRYGRÁF.COMP.ÚLT.5 CAMP.'!C28+'04_CUADROS ACUMULADOS'!D26 -> 80.07605 | E27: =+'02_CUADRYGRÁF.COMP.ÚLT.5 CAMP.'!D28+'04_CUADROS ACUMULADOS'!E26 -> 83.900546 | F27: =+'02_CUADRYGRÁF.COMP.ÚLT.5 CAMP.'!E28+'04_CUADROS ACUMULADOS'!F26 -> 87.718701 | G27: =+'02_CUADRYGRÁF.COMP.ÚLT.5 CAMP.'!F28+'04_CUADROS ACUMULADOS'!G26 -> 87.469 | H27: =+IF(ISNUMBER('02_CUADRYGRÁF.COMP.ÚLT.5 CAMP.'!G28),('02_CUADRYGRÁF.COMP.ÚLT.5 CAMP.'!G28+H26),NA()) -> 80.927 | I27: =IF(ISNUMBER(H27),H27/G27-1,"") -> -0.074792212 | J27: =IF(ISNUMBER(H27),H27/AVERAGE(E27:G27)-1,"") -> -0.062940898 | K27: =IF(ISNUMBER(H27),H27/AVERAGE(D27:G27)-1,"") -> -0.04557171
C28: FEBRERO | D28: =+'02_CUADRYGRÁF.COMP.ÚLT.5 CAMP.'!C29+'04_CUADROS ACUMULADOS'!D27 -> 97.49565 | E28: =+'02_CUADRYGRÁF.COMP.ÚLT.5 CAMP.'!D29+'04_CUADROS ACUMULADOS'!E27 -> 103.11715 | F28: =+'02_CUADRYGRÁF.COMP.ÚLT.5 CAMP.'!E29+'04_CUADROS ACUMULADOS'!F27 -> 108.23317 | G28: =+'02_CUADRYGRÁF.COMP.ÚLT.5 CAMP.'!F29+'04_CUADROS ACUMULADOS'!G27 -> 106.511 | H28: =+IF(ISNUMBER('02_CUADRYGRÁF.COMP.ÚLT.5 CAMP.'!G29),('02_CUADRYGRÁF.COMP.ÚLT.5 CAMP.'!G29+H27),NA()) -> 101.947 | I28: =IF(ISNUMBER(H28),H28/G28-1,"") -> -0.042850034 | J28: =IF(ISNUMBER(H28),H28/AVERAGE(E28:G28)-1,"") -> -0.037816243 | K28: =IF(ISNUMBER(H28),H28/AVERAGE(D28:G28)-1,"") -> -0.01822281
C29: MARZO | D29: =+'02_CUADRYGRÁF.COMP.ÚLT.5 CAMP.'!C30+'04_CUADROS ACUMULADOS'!D28 -> 109.53323 | E29: =+'02_CUADRYGRÁF.COMP.ÚLT.5 CAMP.'!D30+'04_CUADROS ACUMULADOS'!E28 -> 120.54657 | F29: =+'02_CUADRYGRÁF.COMP.ÚLT.5 CAMP.'!E30+'04_CUADROS ACUMULADOS'!F28 -> 129.6412 | G29: =+'02_CUADRYGRÁF.COMP.ÚLT.5 CAMP.'!F30+'04_CUADROS ACUMULADOS'!G28 -> 128.563 | H29: =+IF(ISNUMBER('02_CUADRYGRÁF.COMP.ÚLT.5 CAMP.'!G30),('02_CUADRYGRÁF.COMP.ÚLT.5 CAMP.'!G30+H28),NA()) -> 129.494 | I29: =IF(ISNUMBER(H29),H29/G29-1,"") -> 0.0072415858 | J29: =IF(ISNUMBER(H29),H29/AVERAGE(E29:G29)-1,"") -> 0.025692953 | K29: =IF(ISNUMBER(H29),H29/AVERAGE(D29:G29)-1,"") -> 0.060808865
C30: ABRIL | D30: =+'02_CUADRYGRÁF.COMP.ÚLT.5 CAMP.'!C31+'04_CUADROS ACUMULADOS'!D29 -> 131.4651 | E30: =+'02_CUADRYGRÁF.COMP.ÚLT.5 CAMP.'!D31+'04_CUADROS ACUMULADOS'!E29 -> 130.87022 | F30: =+'02_CUADRYGRÁF.COMP.ÚLT.5 CAMP.'!E31+'04_CUADROS ACUMULADOS'!F29 -> 153.2721 | G30: =+'02_CUADRYGRÁF.COMP.ÚLT.5 CAMP.'!F31+'04_CUADROS ACUMULADOS'!G29 -> 145.198 | H30: =+IF(ISNUMBER('02_CUADRYGRÁF.COMP.ÚLT.5 CAMP.'!G31),('02_CUADRYGRÁF.COMP.ÚLT.5 CAMP.'!G31+H29),NA()) -> 152.556 | I30: =IF(ISNUMBER(H30),H30/G30-1,"") -> 0.050675629 | J30: =IF(ISNUMBER(H30),H30/AVERAGE(E30:G30)-1,"") -> 0.065979528 | K30: =IF(ISNUMBER(H30),H30/AVERAGE(D30:G30)-1,"") -> 0.088120709
C31: MAYO | D31: =+'02_CUADRYGRÁF.COMP.ÚLT.5 CAMP.'!C32+'04_CUADROS ACUMULADOS'!D30 -> 151.89465 | E31: =+'02_CUADRYGRÁF.COMP.ÚLT.5 CAMP.'!D32+'04_CUADROS ACUMULADOS'!E30 -> 145.19922 | F31: =+'02_CUADRYGRÁF.COMP.ÚLT.5 CAMP.'!E32+'04_CUADROS ACUMULADOS'!F30 -> 173.59344 | G31: =+'02_CUADRYGRÁF.COMP.ÚLT.5 CAMP.'!F32+'04_CUADROS ACUMULADOS'!G30 -> 160.475 | H31: =+IF(ISNUMBER('02_CUADRYGRÁF.COMP.ÚLT.5 CAMP.'!G32),('02_CUADRYGRÁF.COMP.ÚLT.5 CAMP.'!G32+H30),NA()) -> 177.55 | I31: =IF(ISNUMBER(H31),H31/G31-1,"") -> 0.10640287 | J31: =IF(ISNUMBER(H31),H31/AVERAGE(E31:G31)-1,"") -> 0.11138315 | K31: =IF(ISNUMBER(H31),H31/AVERAGE(D31:G31)-1,"") -> 0.12522562
C32: JUNIO | D32: =+'02_CUADRYGRÁF.COMP.ÚLT.5 CAMP.'!C33+'04_CUADROS ACUMULADOS'!D31 -> 168.36934 | E32: =+'02_CUADRYGRÁF.COMP.ÚLT.5 CAMP.'!D33+'04_CUADROS ACUMULADOS'!E31 -> 161.36776 | F32: =+'02_CUADRYGRÁF.COMP.ÚLT.5 CAMP.'!E33+'04_CUADROS ACUMULADOS'!F31 -> 190.94454 | G32: =+'02_CUADRYGRÁF.COMP.ÚLT.5 CAMP.'!F33+'04_CUADROS ACUMULADOS'!G31 -> 175.016 | H32: =+IF(ISNUMBER('02_CUADRYGRÁF.COMP.ÚLT.5 CAMP.'!G33),('02_CUADRYGRÁF.COMP.ÚLT.5 CAMP.'!G33+H31),NA()) -> 201.186 | I32: =IF(ISNUMBER(H32),H32/G32-1,"") -> 0.14952919 | J32: =IF(ISNUMBER(H32),H32/AVERAGE(E32:G32)-1,"") -> 0.14455833 | K32: =IF(ISNUMBER(H32),H32/AVERAGE(D32:G32)-1,"") -> 0.1567439
C33: JULIO | D33: =+'02_CUADRYGRÁF.COMP.ÚLT.5 CAMP.'!C34+'04_CUADROS ACUMULADOS'!D32 -> 181.02414 | E33: =+'02_CUADRYGRÁF.COMP.ÚLT.5 CAMP.'!D34+'04_CUADROS ACUMULADOS'!E32 -> 180.55576 | F33: =+'02_CUADRYGRÁF.COMP.ÚLT.5 CAMP.'!E34+'04_CUADROS ACUMULADOS'!F32 -> 212.62951 | G33: =+'02_CUADRYGRÁF.COMP.ÚLT.5 CAMP.'!F34+'04_CUADROS ACUMULADOS'!G32 -> 188.126 | H33: =+IF(ISNUMBER('02_CUADRYGRÁF.COMP.ÚLT.5 CAMP.'!G34),('02_CUADRYGRÁF.COMP.ÚLT.5 CAMP.'!G34+H32),NA()) -> 217.186 | I33: =IF(ISNUMBER(H33),H33/G33-1,"") -> 0.15447094 | J33: =IF(ISNUMBER(H33),H33/AVERAGE(E33:G33)-1,"") -> 0.12084185 | K33: =IF(ISNUMBER(H33),H33/AVERAGE(D33:G33)-1,"") -> 0.13958238
C34: AGOSTO | D34: =+'02_CUADRYGRÁF.COMP.ÚLT.5 CAMP.'!C35+'04_CUADROS ACUMULADOS'!D33 -> 201.27201 | E34: =+'02_CUADRYGRÁF.COMP.ÚLT.5 CAMP.'!D35+'04_CUADROS ACUMULADOS'!E33 -> 195.4172 | F34: =+'02_CUADRYGRÁF.COMP.ÚLT.5 CAMP.'!E35+'04_CUADROS ACUMULADOS'!F33 -> 228.02828 | G34: =+'02_CUADRYGRÁF.COMP.ÚLT.5 CAMP.'!F35+'04_CUADROS ACUMULADOS'!G33 -> 194.891 | H34: =+IF(ISNUMBER('02_CUADRYGRÁF.COMP.ÚLT.5 CAMP.'!G35),('02_CUADRYGRÁF.COMP.ÚLT.5 CAMP.'!G35+H33),NA()) -> #N/A | I34: =IF(ISNUMBER(H34),H34/G34-1,"") | J34: =IF(ISNUMBER(H34),H34/AVERAGE(E34:G34)-1,"") | K34: =IF(ISNUMBER(H34),H34/AVERAGE(D34:G34)-1,"")
C35: SEPTIEMBRE | D35: =+'02_CUADRYGRÁF.COMP.ÚLT.5 CAMP.'!C36+'04_CUADROS ACUMULADOS'!D34 -> 212.79342 | E35: =+'02_CUADRYGRÁF.COMP.ÚLT.5 CAMP.'!D36+'04_CUADROS ACUMULADOS'!E34 -> 215.16145 | F35: =+'02_CUADRYGRÁF.COMP.ÚLT.5 CAMP.'!E36+'04_CUADROS ACUMULADOS'!F34 -> 243.23502 | G35: =+'02_CUADRYGRÁF.COMP.ÚLT.5 CAMP.'!F36+'04_CUADROS ACUMULADOS'!G34 -> 206.059 | H35: =+IF(ISNUMBER('02_CUADRYGRÁF.COMP.ÚLT.5 CAMP.'!G36),('02_CUADRYGRÁF.COMP.ÚLT.5 CAMP.'!G36+H34),NA()) -> #N/A | I35: =IF(ISNUMBER(H35),H35/G35-1,"") | J35: =IF(ISNUMBER(H35),H35/AVERAGE(E35:G35)-1,"") | K35: =IF(ISNUMBER(H35),H35/AVERAGE(D35:G35)-1,"")
D38: EXPORTACIÓN ACUMULADA
D39: 2021/22 | E39: 2022/23 | F39: 2023/24 | G39: 2024/25 | H39: 2025/26 | I39: % 2025 s. 2024 | J39: % 2025 s. Media tres | K39: % 2025 s. Media cuatro
C40: OCTUBRE | D40: =+'02_CUADRYGRÁF.COMP.ÚLT.5 CAMP.'!C42 -> 83.49778 | E40: =+'02_CUADRYGRÁF.COMP.ÚLT.5 CAMP.'!D42 -> 88.527712 | F40: =+'02_CUADRYGRÁF.COMP.ÚLT.5 CAMP.'!E42 -> 55.755136 | G40: =+'02_CUADRYGRÁF.COMP.ÚLT.5 CAMP.'!F42 -> 60.278 | H40: =+IF(ISNUMBER('02_CUADRYGRÁF.COMP.ÚLT.5 CAMP.'!G42),'02_CUADRYGRÁF.COMP.ÚLT.5 CAMP.'!G42,NA()) -> 77.968 | I40: =IF(ISNUMBER(H40),H40/G40-1,"") -> 0.29347357 | J40: =IF(ISNUMBER(H40),H40/AVERAGE(E40:G40)-1,"") -> 0.14344461 | K40: =IF(ISNUMBER(H40),H40/AVERAGE(D40:G40)-1,"") -> 0.082668491
C41: NOVIEMBRE | D41: =+'02_CUADRYGRÁF.COMP.ÚLT.5 CAMP.'!C43+'04_CUADROS ACUMULADOS'!D40 -> 166.90623 | E41: =+'02_CUADRYGRÁF.COMP.ÚLT.5 CAMP.'!D43+'04_CUADROS ACUMULADOS'!E40 -> 156.21831 | F41: =+'02_CUADRYGRÁF.COMP.ÚLT.5 CAMP.'!E43+'04_CUADROS ACUMULADOS'!F40 -> 108.46974 | G41: =+'02_CUADRYGRÁF.COMP.ÚLT.5 CAMP.'!F43+'04_CUADROS ACUMULADOS'!G40 -> 120.215 | H41: =+IF(ISNUMBER('02_CUADRYGRÁF.COMP.ÚLT.5 CAMP.'!G43),('02_CUADRYGRÁF.COMP.ÚLT.5 CAMP.'!G43+H40),NA()) -> 150.265 | I41: =IF(ISNUMBER(H41),H41/G41-1,"") -> 0.24996881 | J41: =IF(ISNUMBER(H41),H41/AVERAGE(E41:G41)-1,"") -> 0.17119104 | K41: =IF(ISNUMBER(H41),H41/AVERAGE(D41:G41)-1,"") -> 0.089253164
C42: DICIEMBRE | D42: =+'02_CUADRYGRÁF.COMP.ÚLT.5 CAMP.'!C44+'04_CUADROS ACUMULADOS'!D41 -> 248.33306 | E42: =+'02_CUADRYGRÁF.COMP.ÚLT.5 CAMP.'!D44+'04_CUADROS ACUMULADOS'!E41 -> 219.78709 | F42: =+'02_CUADRYGRÁF.COMP.ÚLT.5 CAMP.'!E44+'04_CUADROS ACUMULADOS'!F41 -> 168.2988 | G42: =+'02_CUADRYGRÁF.COMP.ÚLT.5 CAMP.'!F44+'04_CUADROS ACUMULADOS'!G41 -> 189.938 | H42: =+IF(ISNUMBER('02_CUADRYGRÁF.COMP.ÚLT.5 CAMP.'!G44),('02_CUADRYGRÁF.COMP.ÚLT.5 CAMP.'!G44+H41),NA()) -> 222.457 | I42: =IF(ISNUMBER(H42),H42/G42-1,"") -> 0.1712085 | J42: =IF(ISNUMBER(H42),H42/AVERAGE(E42:G42)-1,"") -> 0.15457339 | K42: =IF(ISNUMBER(H42),H42/AVERAGE(D42:G42)-1,"") -> 0.076808274
C43: ENERO | D43: =+'02_CUADRYGRÁF.COMP.ÚLT.5 CAMP.'!C45+'04_CUADROS ACUMULADOS'!D42 -> 322.07898 | E43: =+'02_CUADRYGRÁF.COMP.ÚLT.5 CAMP.'!D45+'04_CUADROS ACUMULADOS'!E42 -> 275.75828 | F43: =+'02_CUADRYGRÁF.COMP.ÚLT.5 CAMP.'!E45+'04_CUADROS ACUMULADOS'!F42 -> 237.84382 | G43: =+'02_CUADRYGRÁF.COMP.ÚLT.5 CAMP.'!F45+'04_CUADROS ACUMULADOS'!G42 -> 279.242 | H43: =+IF(ISNUMBER('02_CUADRYGRÁF.COMP.ÚLT.5 CAMP.'!G45),('02_CUADRYGRÁF.COMP.ÚLT.5 CAMP.'!G45+H42),NA()) -> 301.648 | I43: =IF(ISNUMBER(H43),H43/G43-1,"") -> 0.080238646 | J43: =IF(ISNUMBER(H43),H43/AVERAGE(E43:G43)-1,"") -> 0.14138958 | K43: =IF(ISNUMBER(H43),H43/AVERAGE(D43:G43)-1,"") -> 0.082219946
C44: FEBRERO | D44: =+'02_CUADRYGRÁF.COMP.ÚLT.5 CAMP.'!C46+'04_CUADROS ACUMULADOS'!D43 -> 410.40855 | E44: =+'02_CUADRYGRÁF.COMP.ÚLT.5 CAMP.'!D46+'04_CUADROS ACUMULADOS'!E43 -> 324.02162 | F44: =+'02_CUADRYGRÁF.COMP.ÚLT.5 CAMP.'!E46+'04_CUADROS ACUMULADOS'!F43 -> 302.83961 | G44: =+'02_CUADRYGRÁF.COMP.ÚLT.5 CAMP.'!F46+'04_CUADROS ACUMULADOS'!G43 -> 369.87 | H44: =+IF(ISNUMBER('02_CUADRYGRÁF.COMP.ÚLT.5 CAMP.'!G46),('02_CUADRYGRÁF.COMP.ÚLT.5 CAMP.'!G46+H43),NA()) -> 390.924 | I44: =IF(ISNUMBER(H44),H44/G44-1,"") -> 0.056922703 | J44: =IF(ISNUMBER(H44),H44/AVERAGE(E44:G44)-1,"") -> 0.1766181 | K44: =IF(ISNUMBER(H44),H44/AVERAGE(D44:G44)-1,"") -> 0.11125847
C45: MARZO | D45: =+'02_CUADRYGRÁF.COMP.ÚLT.5 CAMP.'!C47+'04_CUADROS ACUMULADOS'!D44 -> 488.70652 | E45: =+'02_CUADRYGRÁF.COMP.ÚLT.5 CAMP.'!D47+'04_CUADROS ACUMULADOS'!E44 -> 388.21758 | F45: =+'02_CUADRYGRÁF.COMP.ÚLT.5 CAMP.'!E47+'04_CUADROS ACUMULADOS'!F44 -> 363.45025 | G45: =+'02_CUADRYGRÁF.COMP.ÚLT.5 CAMP.'!F47+'04_CUADROS ACUMULADOS'!G44 -> 466.851 | H45: =+IF(ISNUMBER('02_CUADRYGRÁF.COMP.ÚLT.5 CAMP.'!G47),('02_CUADRYGRÁF.COMP.ÚLT.5 CAMP.'!G47+H44),NA()) -> 488.841 | I45: =IF(ISNUMBER(H45),H45/G45-1,"") -> 0.047102823 | J45: =IF(ISNUMBER(H45),H45/AVERAGE(E45:G45)-1,"") -> 0.20352921 | K45: =IF(ISNUMBER(H45),H45/AVERAGE(D45:G45)-1,"") -> 0.14534616
C46: ABRIL | D46: =+'02_CUADRYGRÁF.COMP.ÚLT.5 CAMP.'!C48+'04_CUADROS ACUMULADOS'!D45 -> 596.03979 | E46: =+'02_CUADRYGRÁF.COMP.ÚLT.5 CAMP.'!D48+'04_CUADROS ACUMULADOS'!E45 -> 439.80748 | F46: =+'02_CUADRYGRÁF.COMP.ÚLT.5 CAMP.'!E48+'04_CUADROS ACUMULADOS'!F45 -> 437.85944 | G46: =+'02_CUADRYGRÁF.COMP.ÚLT.5 CAMP.'!F48+'04_CUADROS ACUMULADOS'!G45 -> 565.629 | H46: =+IF(ISNUMBER('02_CUADRYGRÁF.COMP.ÚLT.5 CAMP.'!G48),('02_CUADRYGRÁF.COMP.ÚLT.5 CAMP.'!G48+H45),NA()) -> 575.466 | I46: =IF(ISNUMBER(H46),H46/G46-1,"") -> 0.017391258 | J46: =IF(ISNUMBER(H46),H46/AVERAGE(E46:G46)-1,"") -> 0.19614972 | K46: =IF(ISNUMBER(H46),H46/AVERAGE(D46:G46)-1,"") -> 0.12873226
C47: MAYO | D47: =+'02_CUADRYGRÁF.COMP.ÚLT.5 CAMP.'!C49+'04_CUADROS ACUMULADOS'!D46 -> 713.85813 | E47: =+'02_CUADRYGRÁF.COMP.ÚLT.5 CAMP.'!D49+'04_CUADROS ACUMULADOS'!E46 -> 508.06014 | F47: =+'02_CUADRYGRÁF.COMP.ÚLT.5 CAMP.'!E49+'04_CUADROS ACUMULADOS'!F46 -> 510.14425 | G47: =+'02_CUADRYGRÁF.COMP.ÚLT.5 CAMP.'!F49+'04_CUADROS ACUMULADOS'!G46 -> 664.953 | H47: =+IF(ISNUMBER('02_CUADRYGRÁF.COMP.ÚLT.5 CAMP.'!G49),('02_CUADRYGRÁF.COMP.ÚLT.5 CAMP.'!G49+H46),NA()) -> 660.561 | I47: =IF(ISNUMBER(H47),H47/G47-1,"") -> -0.0066049781 | J47: =IF(ISNUMBER(H47),H47/AVERAGE(E47:G47)-1,"") -> 0.17736049 | K47: =IF(ISNUMBER(H47),H47/AVERAGE(D47:G47)-1,"") -> 0.10230576
C48: JUNIO | D48: =+'02_CUADRYGRÁF.COMP.ÚLT.5 CAMP.'!C50+'04_CUADROS ACUMULADOS'!D47 -> 817.30445 | E48: =+'02_CUADRYGRÁF.COMP.ÚLT.5 CAMP.'!D50+'04_CUADROS ACUMULADOS'!E47 -> 573.12506 | F48: =+'02_CUADRYGRÁF.COMP.ÚLT.5 CAMP.'!E50+'04_CUADROS ACUMULADOS'!F47 -> 576.72214 | G48: =+'02_CUADRYGRÁF.COMP.ÚLT.5 CAMP.'!F50+'04_CUADROS ACUMULADOS'!G47 -> 759.436 | H48: =+IF(ISNUMBER('02_CUADRYGRÁF.COMP.ÚLT.5 CAMP.'!G50),('02_CUADRYGRÁF.COMP.ÚLT.5 CAMP.'!G50+H47),NA()) -> 744.44 | I48: =IF(ISNUMBER(H48),H48/G48-1,"") -> -0.019746233 | J48: =IF(ISNUMBER(H48),H48/AVERAGE(E48:G48)-1,"") -> 0.16971647 | K48: =IF(ISNUMBER(H48),H48/AVERAGE(D48:G48)-1,"") -> 0.092119669
...

Sheet 05_GRÁF.COMP.MEDIA 4 ÚLT.CAMPAÑ
B2: 05_GRÁFICOS COMPARATIVOS CON LA MEDIA DE LAS ÚLTIMAS CAMPAÑAS
B6: PRODUCCIÓN | I6: IMPORTACIONES
B7: GRÁFICO PRODUCCIÓN | I7: GRÁFICO IMPORTACIONES
C8: Mes | D8: =+'04_CUADROS ACUMULADOS'!$H$7 -> 2025/26 | E8: Media 4 últimas campañas | J8: Mes | K8: =+'04_CUADROS ACUMULADOS'!$H$7 -> 2025/26 | L8: Media 4 últimas campañas
C9: Oct | D9: =+IF('02_CUADRYGRÁF.COMP.ÚLT.5 CAMP.'!G8<>0,'02_CUADRYGRÁF.COMP.ÚLT.5 CAMP.'!G8,NA()) -> 43.145437 | E9: =+AVERAGE('02_CUADRYGRÁF.COMP.ÚLT.5 CAMP.'!C8:F8) -> 39.38911 | J9: Oct | K9: =+IF('02_CUADRYGRÁF.COMP.ÚLT.5 CAMP.'!G25<>0,'02_CUADRYGRÁF.COMP.ÚLT.5 CAMP.'!G25,NA()) -> 9.142 | L9: =+AVERAGE('02_CUADRYGRÁF.COMP.ÚLT.5 CAMP.'!C25:F25) -> 14.082512
C10: Nov | D10: =+IF('02_CUADRYGRÁF.COMP.ÚLT.5 CAMP.'!G9<>0,'02_CUADRYGRÁF.COMP.ÚLT.5 CAMP.'!G9,NA()) -> 260.50073 | E10: =+AVERAGE('02_CUADRYGRÁF.COMP.ÚLT.5 CAMP.'!C9:F9) -> 238.468 | J10: Nov | K10: =+IF('02_CUADRYGRÁF.COMP.ÚLT.5 CAMP.'!G26<>0,'02_CUADRYGRÁF.COMP.ÚLT.5 CAMP.'!G26,NA()) -> 25.176 | L10: =+AVERAGE('02_CUADRYGRÁF.COMP.ÚLT.5 CAMP.'!C26:F26) -> 23.250005
C11: Dic | D11: =+IF('02_CUADRYGRÁF.COMP.ÚLT.5 CAMP.'!G10<>0,'02_CUADRYGRÁF.COMP.ÚLT.5 CAMP.'!G10,NA()) -> 425.2894 | E11: =+AVERAGE('02_CUADRYGRÁF.COMP.ÚLT.5 CAMP.'!C10:F10) -> 426.62127 | J11: Dic | K11: =+IF('02_CUADRYGRÁF.COMP.ÚLT.5 CAMP.'!G27<>0,'02_CUADRYGRÁF.COMP.ÚLT.5 CAMP.'!G27,NA()) -> 27.878 | L11: =+AVERAGE('02_CUADRYGRÁF.COMP.ÚLT.5 CAMP.'!C27:F27) -> 32.089353
C12: Ene | D12: =+IF('02_CUADRYGRÁF.COMP.ÚLT.5 CAMP.'!G11<>0,'02_CUADRYGRÁF.COMP.ÚLT.5 CAMP.'!G11,NA()) -> 329.97485 | E12: =+AVERAGE('02_CUADRYGRÁF.COMP.ÚLT.5 CAMP.'!C11:F11) -> 298.3019 | J12: Ene | K12: =+IF('02_CUADRYGRÁF.COMP.ÚLT.5 CAMP.'!G28<>0,'02_CUADRYGRÁF.COMP.ÚLT.5 CAMP.'!G28,NA()) -> 18.731 | L12: =+AVERAGE('02_CUADRYGRÁF.COMP.ÚLT.5 CAMP.'!C28:F28) -> 15.369204
C13: Feb | D13: =+IF('02_CUADRYGRÁF.COMP.ÚLT.5 CAMP.'!G12<>0,'02_CUADRYGRÁF.COMP.ÚLT.5 CAMP.'!G12,NA()) -> 143.39104 | E13: =+AVERAGE('02_CUADRYGRÁF.COMP.ÚLT.5 CAMP.'!C12:F12) -> 88.024249 | J13: Feb | K13: =+IF('02_CUADRYGRÁF.COMP.ÚLT.5 CAMP.'!G29<>0,'02_CUADRYGRÁF.COMP.ÚLT.5 CAMP.'!G29,NA()) -> 21.02 | L13: =+AVERAGE('02_CUADRYGRÁF.COMP.ÚLT.5 CAMP.'!C29:F29) -> 19.048168
C14: Mar | D14: =+IF('02_CUADRYGRÁF.COMP.ÚLT.5 CAMP.'!G13<>0,'02_CUADRYGRÁF.COMP.ÚLT.5 CAMP.'!G13,NA()) -> 84.993297 | E14: =+AVERAGE('02_CUADRYGRÁF.COMP.ÚLT.5 CAMP.'!C13:F13) -> 13.768943 | J14: Mar | K14: =+IF('02_CUADRYGRÁF.COMP.ÚLT.5 CAMP.'!G30<>0,'02_CUADRYGRÁF.COMP.ÚLT.5 CAMP.'!G30,NA()) -> 27.547 | L14: =+AVERAGE('02_CUADRYGRÁF.COMP.ÚLT.5 CAMP.'!C30:F30) -> 18.231758
C15: Abr | D15: =+IF('02_CUADRYGRÁF.COMP.ÚLT.5 CAMP.'!G14<>0,'02_CUADRYGRÁF.COMP.ÚLT.5 CAMP.'!G14,NA()) -> 12.211432 | E15: =+AVERAGE('02_CUADRYGRÁF.COMP.ÚLT.5 CAMP.'!C14:F14) -> 3.5120265 | J15: Abr | K15: =+IF('02_CUADRYGRÁF.COMP.ÚLT.5 CAMP.'!G31<>0,'02_CUADRYGRÁF.COMP.ÚLT.5 CAMP.'!G31,NA()) -> 23.062 | L15: =+AVERAGE('02_CUADRYGRÁF.COMP.ÚLT.5 CAMP.'!C31:F31) -> 18.130356
C16: May | D16: =+IF('02_CUADRYGRÁF.COMP.ÚLT.5 CAMP.'!G15<>0,'02_CUADRYGRÁF.COMP.ÚLT.5 CAMP.'!G15,NA()) -> 1.4293088 | E16: =+AVERAGE('02_CUADRYGRÁF.COMP.ÚLT.5 CAMP.'!C15:F15) -> 0.84213596 | J16: May | K16: =+IF('02_CUADRYGRÁF.COMP.ÚLT.5 CAMP.'!G32<>0,'02_CUADRYGRÁF.COMP.ÚLT.5 CAMP.'!G32,NA()) -> 24.994 | L16: =+AVERAGE('02_CUADRYGRÁF.COMP.ÚLT.5 CAMP.'!C32:F32) -> 17.58922
C17: Jun | J17: Jun | K17: =+IF('02_CUADRYGRÁF.COMP.ÚLT.5 CAMP.'!G33<>0,'02_CUADRYGRÁF.COMP.ÚLT.5 CAMP.'!G33,NA()) -> 23.636 | L17: =+AVERAGE('02_CUADRYGRÁF.COMP.ÚLT.5 CAMP.'!C33:F33) -> 16.133833
C18: Jul | J18: Jul | K18: =+IF('02_CUADRYGRÁF.COMP.ÚLT.5 CAMP.'!G34<>0,'02_CUADRYGRÁF.COMP.ÚLT.5 CAMP.'!G34,NA()) -> 16 | L18: =+AVERAGE('02_CUADRYGRÁF.COMP.ÚLT.5 CAMP.'!C34:F34) -> 16.659443
C19: Ago | J19: Ago | K19: =+IF('02_CUADRYGRÁF.COMP.ÚLT.5 CAMP.'!G35<>0,'02_CUADRYGRÁF.COMP.ÚLT.5 CAMP.'!G35,NA()) -> #N/A | L19: =+AVERAGE('02_CUADRYGRÁF.COMP.ÚLT.5 CAMP.'!C35:F35) -> 14.318271
C20: Sep | J20: Sep | K20: =+IF('02_CUADRYGRÁF.COMP.ÚLT.5 CAMP.'!G36<>0,'02_CUADRYGRÁF.COMP.ÚLT.5 CAMP.'!G36,NA()) -> #N/A | L20: =+AVERAGE('02_CUADRYGRÁF.COMP.ÚLT.5 CAMP.'!C36:F36) -> 14.410101
C21: Acumulado | D21: =SUMIF(D9:D20, "<>#N/D") -> 1300.9355 | E21: =SUMIF(D9:D20,"<>#N/D",E9:E20) -> 1108.9276 | J21: Acumulado | K21: =SUMIF(K9:K20, "<>#N/D") -> 217.186 | L21: =SUMIF(K9:K20,"<>#N/D",L9:L20) -> 190.58385
C22: % VARIACIÓN: | D22: =+D21/E21-1 -> 0.17314733 | J22: % VARIACIÓN: | K22: =+K21/L21-1 -> 0.13958238
B24: MERCADO INTERIOR APARENTE | I24: EXPORTACIONES
B25: GRÁFICO MERCADO INTERIOR APARENTE | I25: GRÁFICO EXPORTACIONES
C26: Mes | D26: =+'04_CUADROS ACUMULADOS'!$H$7 -> 2025/26 | E26: Media 4 últimas campañas | J26: Mes | K26: =+'04_CUADROS ACUMULADOS'!$H$7 -> 2025/26 | L26: Media 4 últimas campañas
C27: Oct | D27: =+IF('02_CUADRYGRÁF.COMP.ÚLT.5 CAMP.'!G59<>0,'02_CUADRYGRÁF.COMP.ÚLT.5 CAMP.'!G59,NA()) -> 37.725167 | E27: =+AVERAGE('02_CUADRYGRÁF.COMP.ÚLT.5 CAMP.'!C59:F59) -> 36.375521 | J27: Oct | K27: =+IF('02_CUADRYGRÁF.COMP.ÚLT.5 CAMP.'!G42<>0,'02_CUADRYGRÁF.COMP.ÚLT.5 CAMP.'!G42,NA()) -> 77.968 | L27: =+AVERAGE('02_CUADRYGRÁF.COMP.ÚLT.5 CAMP.'!C42:F42) -> 72.014657
C28: Nov | D28: =+IF('02_CUADRYGRÁF.COMP.ÚLT.5 CAMP.'!G60<>0,'02_CUADRYGRÁF.COMP.ÚLT.5 CAMP.'!G60,NA()) -> 46.124202 | E28: =+AVERAGE('02_CUADRYGRÁF.COMP.ÚLT.5 CAMP.'!C60:F60) -> 43.644797 | J28: Nov | K28: =+IF('02_CUADRYGRÁF.COMP.ÚLT.5 CAMP.'!G43<>0,'02_CUADRYGRÁF.COMP.ÚLT.5 CAMP.'!G43,NA()) -> 72.297 | L28: =+AVERAGE('02_CUADRYGRÁF.COMP.ÚLT.5 CAMP.'!C43:F43) -> 65.937662
C29: Dic | D29: =+IF('02_CUADRYGRÁF.COMP.ÚLT.5 CAMP.'!G61<>0,'02_CUADRYGRÁF.COMP.ÚLT.5 CAMP.'!G61,NA()) -> 46.919313 | E29: =+AVERAGE('02_CUADRYGRÁF.COMP.ÚLT.5 CAMP.'!C61:F61) -> 41.624837 | J29: Dic | K29: =+IF('02_CUADRYGRÁF.COMP.ÚLT.5 CAMP.'!G44<>0,'02_CUADRYGRÁF.COMP.ÚLT.5 CAMP.'!G44,NA()) -> 72.192 | L29: =+AVERAGE('02_CUADRYGRÁF.COMP.ÚLT.5 CAMP.'!C44:F44) -> 68.636918
C30: Ene | D30: =+IF('02_CUADRYGRÁF.COMP.ÚLT.5 CAMP.'!G62<>0,'02_CUADRYGRÁF.COMP.ÚLT.5 CAMP.'!G62,NA()) -> 41.017115 | E30: =+AVERAGE('02_CUADRYGRÁF.COMP.ÚLT.5 CAMP.'!C62:F62) -> 39.137916 | J30: Ene | K30: =+IF('02_CUADRYGRÁF.COMP.ÚLT.5 CAMP.'!G45<>0,'02_CUADRYGRÁF.COMP.ÚLT.5 CAMP.'!G45,NA()) -> 79.191 | L30: =+AVERAGE('02_CUADRYGRÁF.COMP.ÚLT.5 CAMP.'!C45:F45) -> 72.141534
C31: Feb | D31: =+IF('02_CUADRYGRÁF.COMP.ÚLT.5 CAMP.'!G63<>0,'02_CUADRYGRÁF.COMP.ÚLT.5 CAMP.'!G63,NA()) -> 45.615915 | E31: =+AVERAGE('02_CUADRYGRÁF.COMP.ÚLT.5 CAMP.'!C63:F63) -> 36.517599 | J31: Feb | K31: =+IF('02_CUADRYGRÁF.COMP.ÚLT.5 CAMP.'!G46<>0,'02_CUADRYGRÁF.COMP.ÚLT.5 CAMP.'!G46,NA()) -> 89.276 | L31: =+AVERAGE('02_CUADRYGRÁF.COMP.ÚLT.5 CAMP.'!C46:F46) -> 73.054174
C32: Mar | D32: =+IF('02_CUADRYGRÁF.COMP.ÚLT.5 CAMP.'!G64<>0,'02_CUADRYGRÁF.COMP.ÚLT.5 CAMP.'!G64,NA()) -> 48.161457 | E32: =+AVERAGE('02_CUADRYGRÁF.COMP.ÚLT.5 CAMP.'!C64:F64) -> 43.56912 | J32: Mar | K32: =+IF('02_CUADRYGRÁF.COMP.ÚLT.5 CAMP.'!G47<>0,'02_CUADRYGRÁF.COMP.ÚLT.5 CAMP.'!G47,NA()) -> 97.917 | L32: =+AVERAGE('02_CUADRYGRÁF.COMP.ÚLT.5 CAMP.'!C47:F47) -> 75.021391
C33: Abr | D33: =+IF('02_CUADRYGRÁF.COMP.ÚLT.5 CAMP.'!G65<>0,'02_CUADRYGRÁF.COMP.ÚLT.5 CAMP.'!G65,NA()) -> 32.422952 | E33: =+AVERAGE('02_CUADRYGRÁF.COMP.ÚLT.5 CAMP.'!C65:F65) -> 36.831208 | J33: Abr | K33: =+IF('02_CUADRYGRÁF.COMP.ÚLT.5 CAMP.'!G48<>0,'02_CUADRYGRÁF.COMP.ÚLT.5 CAMP.'!G48,NA()) -> 86.625 | L33: =+AVERAGE('02_CUADRYGRÁF.COMP.ÚLT.5 CAMP.'!C48:F48) -> 83.02759
C34: May | D34: =+IF('02_CUADRYGRÁF.COMP.ÚLT.5 CAMP.'!G66<>0,'02_CUADRYGRÁF.COMP.ÚLT.5 CAMP.'!G66,NA()) -> 30.781539 | E34: =+AVERAGE('02_CUADRYGRÁF.COMP.ÚLT.5 CAMP.'!C66:F66) -> 33.933956 | J34: May | K34: =+IF('02_CUADRYGRÁF.COMP.ÚLT.5 CAMP.'!G49<>0,'02_CUADRYGRÁF.COMP.ÚLT.5 CAMP.'!G49,NA()) -> 85.095 | L34: =+AVERAGE('02_CUADRYGRÁF.COMP.ÚLT.5 CAMP.'!C49:F49) -> 89.419953
C35: Jun | D35: =+IF('02_CUADRYGRÁF.COMP.ÚLT.5 CAMP.'!G67<>0,'02_CUADRYGRÁF.COMP.ÚLT.5 CAMP.'!G67,NA()) -> 34.92359 | E35: =+AVERAGE('02_CUADRYGRÁF.COMP.ÚLT.5 CAMP.'!C67:F67) -> 36.105815 | J35: Jun | K35: =+IF('02_CUADRYGRÁF.COMP.ÚLT.5 CAMP.'!G50<>0,'02_CUADRYGRÁF.COMP.ÚLT.5 CAMP.'!G50,NA()) -> 83.879 | L35: =+AVERAGE('02_CUADRYGRÁF.COMP.ÚLT.5 CAMP.'!C50:F50) -> 82.393033
C36: Jul | D36: =+IF('02_CUADRYGRÁF.COMP.ÚLT.5 CAMP.'!G68<>0,'02_CUADRYGRÁF.COMP.ÚLT.5 CAMP.'!G68,NA()) -> 41.37513 | E36: =+AVERAGE('02_CUADRYGRÁF.COMP.ÚLT.5 CAMP.'!C68:F68) -> 34.894653 | J36: Jul | K36: =+IF('02_CUADRYGRÁF.COMP.ÚLT.5 CAMP.'!G51<>0,'02_CUADRYGRÁF.COMP.ÚLT.5 CAMP.'!G51,NA()) -> 89 | L36: =+AVERAGE('02_CUADRYGRÁF.COMP.ÚLT.5 CAMP.'!C51:F51) -> 79.940827
C37: Ago | D37: =+IF('02_CUADRYGRÁF.COMP.ÚLT.5 CAMP.'!G69<>0,'02_CUADRYGRÁF.COMP.ÚLT.5 CAMP.'!G69,NA()) -> #N/A | E37: =+AVERAGE('02_CUADRYGRÁF.COMP.ÚLT.5 CAMP.'!C69:F69) -> 37.317361 | J37: Ago | K37: =+IF('02_CUADRYGRÁF.COMP.ÚLT.5 CAMP.'!G52<>0,'02_CUADRYGRÁF.COMP.ÚLT.5 CAMP.'!G52,NA()) -> #N/A | L37: =+AVERAGE('02_CUADRYGRÁF.COMP.ÚLT.5 CAMP.'!C52:F52) -> 65.598268
C38: Sep | D38: =+IF('02_CUADRYGRÁF.COMP.ÚLT.5 CAMP.'!G70<>0,'02_CUADRYGRÁF.COMP.ÚLT.5 CAMP.'!G70,NA()) -> #N/A | E38: =+AVERAGE('02_CUADRYGRÁF.COMP.ÚLT.5 CAMP.'!C70:F70) -> 36.522567 | J38: Sep | K38: =+IF('02_CUADRYGRÁF.COMP.ÚLT.5 CAMP.'!G53<>0,'02_CUADRYGRÁF.COMP.ÚLT.5 CAMP.'!G53,NA()) -> #N/A | L38: =+AVERAGE('02_CUADRYGRÁF.COMP.ÚLT.5 CAMP.'!C53:F53) -> 78.061543
C39: Acumulado | D39: =SUMIF(D27:D38, "<>#N/D") -> 405.06638 | E39: =SUMIF(D27:D38,"<>#N/D",E27:E38) -> 382.63542 | J39: Acumulado | K39: =SUMIF(K27:K38, "<>#N/D") -> 833.44 | L39: =SUMIF(K27:K38,"<>#N/D",L27:L38) -> 761.58774
C40: % VARIACIÓN: | D40: =+D39/E39-1 -> 0.058622272 | I40: % VARIACION : | K40: =+K39/L39-1 -> 0.094345349
B42: EXISTENCIAS ALMAZARAS (INCLUIDO FPCO) | I42: EXISTENCIAS TOTALES
B43: GRÁFICO EXISTENCIAS ALMAZARAS (INCLUIDO FPCO) | I43: GRÁFICO EXISTENCIAS TOTALES
C44: Mes | D44: =+'04_CUADROS ACUMULADOS'!$H$7 -> 2025/26 | E44: Media 4 últimas campañas | J44: Mes | K44: =+'04_CUADROS ACUMULADOS'!$H$7 -> 2025/26 | L44: Media 4 últimas campañas
C45: Oct | D45: =+IF('03_CUADRYGRÁF.COMP.5 ÚLT.CAMP.'!J8<>0,'03_CUADRYGRÁF.COMP.5 ÚLT.CAMP.'!J8,NA()) -> 97.73275 | E45: =+AVERAGE('03_CUADRYGRÁF.COMP.5 ÚLT.CAMP.'!F8:I8) -> 116.15584 | J45: Oct | K45: =+IF('03_CUADRYGRÁF.COMP.5 ÚLT.CAMP.'!J42<>0,'03_CUADRYGRÁF.COMP.5 ÚLT.CAMP.'!J42,NA()) -> 226.26584 | L45: =+AVERAGE('03_CUADRYGRÁF.COMP.5 ÚLT.CAMP.'!F42:I42) -> 273.41052
C46: Nov | D46: =+IF('03_CUADRYGRÁF.COMP.5 ÚLT.CAMP.'!J9<>0,'03_CUADRYGRÁF.COMP.5 ÚLT.CAMP.'!J9,NA()) -> 258.26741 | E46: =+AVERAGE('03_CUADRYGRÁF.COMP.5 ÚLT.CAMP.'!F9:I9) -> 263.21481 | J46: Nov | K46: =+IF('03_CUADRYGRÁF.COMP.5 ÚLT.CAMP.'!J43<>0,'03_CUADRYGRÁF.COMP.5 ÚLT.CAMP.'!J43,NA()) -> 393.52137 | L46: =+AVERAGE('03_CUADRYGRÁF.COMP.5 ÚLT.CAMP.'!F43:I43) -> 425.53283
...

Sheet 06_ALMAZARAS.BALANCE DE CAMPAÑA
C1: 06_ALMAZARAS_BALANCE DE CAMPAÑA
C4: COMUNIDAD AUTÓNOMA | D4: PROVINCIA | E4: ALMAZARAS | H4: EXISTENCIAS A 1 DE OCTUBRE | I4: ENTRADAS | K4: SALIDAS TOTALES | L4: EXISTENCIAS FINALES
E6: *Nº TOTAL | F6: **Nº DATOS | G6: **DATOS (-%) | I6: PRODUCCIÓN | J6: OTRAS E.
C7: ANDALUCÍA | D7: ALMERÍA | E7: 30 | F7: 26 | G7: 0.86666667 | H7: 252.8 | I7: 16130 | J7: 0 | K7: 13478.7 | L7: 2904.1
D8: CÁDIZ | E8: 20 | F8: 18 | G8: 0.9 | H8: 262.1 | I8: 15013 | J8: 116.8 | K8: 11852.7 | L8: 3539.2
D9: CÓRDOBA | E9: 183 | F9: 174 | G9: 0.95081967 | H9: 19870.7 | I9: 246735.4 | J9: 17863.4 | K9: 225685.8 | L9: 58783.7
D10: GRANADA | E10: 108 | F10: 100 | G10: 0.92592593 | H10: 16528.6 | I10: 107297.8 | J10: 1388.4 | K10: 93154.8 | L10: 32060
D11: HUELVA | E11: 21 | F11: 20 | G11: 0.95238095 | H11: 1874.8 | I11: 15212.4 | J11: 0 | K11: 13048.9 | L11: 4038.3
D12: JAÉN | E12: 330 | F12: 309 | G12: 0.93636364 | H12: 77650.2 | I12: 389086.1 | J12: 33537.2 | K12: 372356.9 | L12: 127916.6
D13: MÁLAGA | E13: 79 | F13: 76 | G13: 0.96202532 | H13: 1204.4 | I13: 59163.6 | J13: 202 | K13: 54623.7 | L13: 5946.3
D14: SEVILLA | E14: 92 | F14: 88 | G14: 0.95652174 | H14: 3642.4 | I14: 126002.3 | J14: 1465.7 | K14: 104412.1 | L14: 26698.3
D15: TOTAL: | E15: 863 | F15: 811 | G15: 0.93974508 | H15: 121286 | I15: 974640.6 | J15: 54573.5 | K15: 888613.6 | L15: 261886.5
C16: ARAGÓN | D16: HUESCA | E16: 27 | F16: 27 | G16: 1 | H16: 85.8 | I16: 2175.8 | J16: 0 | K16: 2051.4 | L16: 210.2
D17: TERUEL | E17: 26 | F17: 26 | G17: 1 | H17: 226.4 | I17: 9289.1 | J17: 0 | K17: 7549 | L17: 1966.5
D18: ZARAGOZA | E18: 41 | F18: 41 | G18: 1 | H18: 613.3 | I18: 5650.1 | J18: 0 | K18: 4827.1 | L18: 1436.3
D19: TOTAL: | E19: 94 | F19: 94 | G19: 1 | H19: 925.5 | I19: 17115 | J19: 0 | K19: 14427.5 | L19: 3613
C20: BALEARES | D20: BALEARES | E20: 26 | F20: 24 | G20: 0.92307692 | H20: 11 | I20: 989.6 | J20: 0 | K20: 837 | L20: 163.6
D21: TOTAL: | E21: 26 | F21: 24 | G21: 0.92307692 | H21: 11 | I21: 989.6 | J21: 0 | K21: 837 | L21: 163.6
C22: COMUNIDAD VALENCIANA | D22: ALICANTE | E22: 44 | F22: 42 | G22: 0.95454545 | H22: 269.8 | I22: 9735.4 | J22: 12.8 | K22: 8878 | L22: 1140
D23: CASTELLÓN | E23: 46 | F23: 44 | G23: 0.95652174 | H23: 24.3 | I23: 5498.5 | J23: 0 | K23: 5164.7 | L23: 358.1
D24: VALENCIA | E24: 52 | F24: 50 | G24: 0.96153846 | H24: 98.3 | I24: 8142.3 | J24: 12.3 | K24: 7565.9 | L24: 687
D25: TOTAL: | E25: 142 | F25: 136 | G25: 0.95774648 | H25: 392.4 | I25: 23376.2 | J25: 25.1 | K25: 21608.6 | L25: 2185.1
C26: CANARIAS | D26: LAS PALMAS | E26: 9 | F26: 8 | G26: 0.88888889 | H26: 0 | I26: 15.7 | J26: 0 | K26: 15 | L26: 0.7
D27: STA. CRUZ DE TENERIFE | E27: 4 | F27: 4 | G27: 1 | H27: 0 | I27: 18 | J27: 0 | K27: 18.1 | L27: -0.1
D28: TOTAL: | E28: 13 | F28: 12 | G28: 0.92307692 | H28: 0 | I28: 33.7 | J28: 0 | K28: 33.1 | L28: 0.6
C29: CASTILLA-LA MANCHA | D29: ALBACETE | E29: 40 | F29: 38 | G29: 0.95 | H29: 1184.5 | I29: 17777.5 | J29: 0 | K29: 14062.9 | L29: 4899.1
D30: CIUDAD REAL | E30: 81 | F30: 77 | G30: 0.95061728 | H30: 4868.3 | I30: 69079.3 | J30: 2136.5 | K30: 58478.2 | L30: 17605.9
D31: CUENCA | E31: 26 | F31: 24 | G31: 0.92307692 | H31: 815.9 | I31: 6652.1 | J31: 0 | K31: 5871.3 | L31: 1596.7
D32: GUADALAJARA | E32: 7 | F32: 7 | G32: 1 | H32: 505.8 | I32: 1941.4 | J32: 0 | K32: 1581.6 | L32: 865.6
D33: TOLEDO | E33: 113 | F33: 109 | G33: 0.96460177 | H33: 2995.8 | I33: 43223.4 | J33: 515.3 | K33: 32157.3 | L33: 14577.2
D34: TOTAL: | E34: 267 | F34: 255 | G34: 0.95505618 | H34: 10370.3 | I34: 138673.7 | J34: 2651.8 | K34: 112151.3 | L34: 39544.5
C35: CASTILLA Y LEÓN | D35: ÁVILA | E35: 11 | F35: 10 | G35: 0.90909091 | H35: 8.3 | I35: 1609.1 | J35: 0 | K35: 1569.4 | L35: 48
D36: LEÓN | E36: 1 | F36: 0 | G36: 0 | H36: 0 | I36: 0 | J36: 0 | K36: 0 | L36: 0
D37: SALAMANCA | E37: 5 | F37: 4 | G37: 0.8 | H37: 3.5 | I37: 170 | J37: 0 | K37: 161.2 | L37: 12.3
D38: SORIA | E38: 1 | F38: 1 | G38: 1 | H38: 0 | I38: 0.3 | J38: 0 | K38: 0.3 | L38: 0
D39: OTRAS | E39: 4 | F39: 4 | G39: 1 | H39: 138.1 | I39: 270.4 | J39: 0 | K39: 165.1 | L39: 243.4
D40: TOTAL: | E40: 22 | F40: 19 | G40: 0.86363636 | H40: 149.9 | I40: 2049.8 | J40: 0 | K40: 1896 | L40: 303.7
C41: CATALUÑA | D41: BARCELONA | E41: 13 | F41: 11 | G41: 0.84615385 | H41: 12.2 | I41: 854.9 | J41: 0 | K41: 813.3 | L41: 53.8
D42: GIRONA | E42: 13 | F42: 13 | G42: 1 | H42: 19.7 | I42: 924.2 | J42: 20.5 | K42: 855.3 | L42: 109.1
D43: LLEIDA | E43: 57 | F43: 56 | G43: 0.98245614 | H43: 307.5 | I43: 11948.9 | J43: 79.9 | K43: 10425.9 | L43: 1910.4
...

Sheet 07_ALMAZARAS.ACEITE PRODUCIDO
E1: 07_ALMAZARAS_ACEITE PRODUCIDO
E4: COMUNIDAD AUTÓNOMA | F4: PROVINCIA | G4: OCTUBRE | H4: NOVIEMBRE | I4: DICIEMBRE | J4: ENERO | K4: FEBRERO | L4: MARZO | M4: ABRIL | N4: MAYO | O4: AJUSTES | P4: TOTAL
E5: ANDALUCÍA | F5: ALMERÍA | G5: 1165.7 | H5: 6188.1 | I5: 5991.3 | J5: 2309.8 | K5: 372 | L5: 83.7 | M5: 1.1 | N5: 0 | O5: 18.3 | P5: 16130
F6: CÁDIZ | G6: 1904.2 | H6: 4946.2 | I6: 4357.7 | J6: 2541.7 | K6: 785.2 | L6: 478 | M6: 0 | N6: 0 | O6: 0 | P6: 15013
F7: CÓRDOBA | G7: 5193.6 | H7: 44016.3 | I7: 72185 | J7: 59909.6 | K7: 31301.6 | L7: 27566.9 | M7: 5416.5 | N7: 636.9 | O7: 509 | P7: 246735.4
F8: GRANADA | G8: 468.2 | H8: 14139.6 | I8: 34947.7 | J8: 30291.8 | K8: 12929.8 | L8: 11103.6 | M8: 2608.6 | N8: 435.7 | O8: 372.8 | P8: 107297.8
F9: HUELVA | G9: 807.8 | H9: 6218.1 | I9: 5783.9 | J9: 1914.5 | K9: 251.8 | L9: 128.3 | M9: 108 | N9: 0 | O9: 0 | P9: 15212.4
F10: JAÉN | G10: 5396.4 | H10: 40573.4 | I10: 122674.9 | J10: 125605 | K10: 64211.2 | L10: 29012.1 | M10: 613.1 | N10: 67 | O10: 933 | P10: 389086.1
F11: MÁLAGA | G11: 2475.7 | H11: 12109 | I11: 13939.5 | J11: 12638.2 | K11: 6995.3 | L11: 7702.7 | M11: 2884.3 | N11: 286 | O11: 132.9 | P11: 59163.6
F12: SEVILLA | G12: 10889.2 | H12: 34992.9 | I12: 39841.6 | J12: 26548.4 | K12: 9537.9 | L12: 3447.4 | M12: 255.8 | N12: 0 | O12: 489.1 | P12: 126002.3
F13: TOTAL : | G13: 28300.8 | H13: 163183.6 | I13: 299721.6 | J13: 261759 | K13: 126384.8 | L13: 79522.7 | M13: 11887.4 | N13: 1425.6 | O13: 2455.1 | P13: 974640.6
E14: ARAGÓN | F14: HUESCA | G14: 134.9 | H14: 1262.2 | I14: 669.1 | J14: 69.1 | K14: 27.8 | L14: 0 | M14: 0 | N14: 0 | O14: 12.7 | P14: 2175.8
F15: TERUEL | G15: 480.8 | H15: 1916.7 | I15: 2968.1 | J15: 1810 | K15: 1107.2 | L15: 856.1 | M15: 99.2 | N15: 0 | O15: 51 | P15: 9289.1
F16: ZARAGOZA | G16: 261.7 | H16: 2049.3 | I16: 1814 | J16: 734.1 | K16: 362.2 | L16: 345.1 | M16: 67 | N16: 0 | O16: 16.7 | P16: 5650.1
F17: TOTAL : | G17: 877.4 | H17: 5228.2 | I17: 5451.2 | J17: 2613.2 | K17: 1497.2 | L17: 1201.2 | M17: 166.2 | N17: 0 | O17: 80.4 | P17: 17115
E18: BALEARES | F18: BALEARES | G18: 433.4 | H18: 430.9 | I18: 123.9 | J18: 0.8 | K18: 0.6 | L18: 0 | M18: 0 | N18: 0 | O18: 0 | P18: 989.6
F19: TOTAL : | G19: 433.4 | H19: 430.9 | I19: 123.9 | J19: 0.8 | K19: 0.6 | L19: 0 | M19: 0 | N19: 0 | O19: 0 | P19: 989.6
E20: COMUNIDAD VALENCIANA | F20: ALICANTE | G20: 559.3 | H20: 3147.4 | I20: 3524.3 | J20: 1979.1 | K20: 357.4 | L20: 133.1 | M20: 0 | N20: 0 | O20: 34.8 | P20: 9735.4
F21: CASTELLÓN | G21: 538.9 | H21: 2565.2 | I21: 985.1 | J21: 771.9 | K21: 531.1 | L21: 75.3 | M21: 3.9 | N21: 0 | O21: 27.1 | P21: 5498.5
F22: VALENCIA | G22: 399.3 | H22: 4131.9 | I22: 2774.8 | J22: 675.2 | K22: 40.1 | L22: 106.8 | M22: 0 | N22: 0 | O22: 14.2 | P22: 8142.3
F23: TOTAL : | G23: 1497.5 | H23: 9844.5 | I23: 7284.2 | J23: 3426.2 | K23: 928.6 | L23: 315.2 | M23: 3.9 | N23: 0 | O23: 76.1 | P23: 23376.2
E24: CANARIAS | F24: LAS PALMAS | G24: 13.3 | H24: 0.6 | I24: 0.9 | J24: 0.8 | K24: 0 | L24: 0 | M24: 0 | N24: 0.1 | O24: 0 | P24: 15.7
F25: STA. CRUZ DE TENERIFE | G25: 15.6 | H25: 2.3 | I25: 0.1 | J25: 0 | K25: 0 | L25: 0 | M25: 0 | N25: 0 | O25: 0 | P25: 18
F26: TOTAL : | G26: 28.9 | H26: 2.9 | I26: 1 | J26: 0.8 | K26: 0 | L26: 0 | M26: 0 | N26: 0.1 | O26: 0 | P26: 33.7
E27: CASTILLA-LA MANCHA | F27: ALBACETE | G27: 115.3 | H27: 4789 | I27: 7942.2 | J27: 4498.5 | K27: 300.1 | L27: 89 | M27: 2.5 | N27: 0 | O27: 40.9 | P27: 17777.5
F28: CIUDAD REAL | G28: 253.5 | H28: 10245.8 | I28: 31546.8 | J28: 21200.7 | K28: 4546.1 | L28: 1023.5 | M28: 29.6 | N28: 0 | O28: 233.3 | P28: 69079.3
F29: CUENCA | G29: 28.5 | H29: 738.1 | I29: 3251.7 | J29: 2034.1 | K29: 424.2 | L29: 130.1 | M29: 0 | N29: 0 | O29: 45.4 | P29: 6652.1
F30: GUADALAJARA | G30: 16.5 | H30: 281.4 | I30: 661.6 | J30: 634 | K30: 233.9 | L30: 114 | M30: 0 | N30: 0 | O30: 0 | P30: 1941.4
F31: TOLEDO | G31: 459.8 | H31: 6219.4 | I31: 17061.7 | J31: 13716.1 | K31: 4260.3 | L31: 1356.2 | M31: 7 | N31: 0 | O31: 142.9 | P31: 43223.4
F32: TOTAL : | G32: 873.6 | H32: 22273.7 | I32: 60464 | J32: 42083.4 | K32: 9764.6 | L32: 2712.8 | M32: 39.1 | N32: 0 | O32: 462.5 | P32: 138673.7
E33: CASTILLA Y LEÓN | F33: ÁVILA | G33: 0.6 | H33: 826.1 | I33: 662.7 | J33: 107.9 | K33: 11.6 | L33: 0 | M33: 0 | N33: 0 | O33: 0.2 | P33: 1609.1
F34: LEÓN | G34: 0 | H34: 0 | I34: 0 | J34: 0 | K34: 0 | L34: 0 | M34: 0 | N34: 0 | O34: 0 | P34: 0
F35: SALAMANCA | G35: 2.1 | H35: 156.4 | I35: 11.3 | J35: 0 | K35: 0 | L35: 0 | M35: 0 | N35: 0 | O35: 0.2 | P35: 170
F36: SORIA | G36: 0 | H36: 0.3 | I36: 0 | J36: 0 | K36: 0 | L36: 0 | M36: 0 | N36: 0 | O36: 0 | P36: 0.3
F37: OTRAS | G37: 0 | H37: 230.3 | I37: 40.1 | J37: 0 | K37: 0 | L37: 0 | M37: 0 | N37: 0 | O37: 0 | P37: 270.4
F38: TOTAL : | G38: 2.7 | H38: 1213.1 | I38: 714.1 | J38: 107.9 | K38: 11.6 | L38: 0 | M38: 0 | N38: 0 | O38: 0.4 | P38: 2049.8
E39: CATALUÑA | F39: BARCELONA | G39: 266 | H39: 460.6 | I39: 124.5 | J39: 3.8 | K39: 0 | L39: 0 | M39: 0 | N39: 0 | O39: 0 | P39: 854.9
F40: GIRONA | G40: 130.1 | H40: 559.6 | I40: 215.2 | J40: 19.3 | K40: 0 | L40: 0 | M40: 0 | N40: 0 | O40: 0 | P40: 924.2
F41: LLEIDA | G41: 944.8 | H41: 6028.1 | I41: 3896.4 | J41: 1010 | K41: 12.7 | L41: 0 | M41: 0 | N41: 0 | O41: 56.9 | P41: 11948.9
F42: TARRAGONA | G42: 2277 | H42: 8841.1 | I42: 6006 | J42: 4673.8 | K42: 2746.3 | L42: 616.5 | M42: 82 | N42: 0 | O42: 40.4 | P42: 25283.1
...

Sheet 08_ALMAZ POR TIPO.PRODUCCIÓN
E2: 08_ALMAZARAS_ALMAZARAS POR TIPO_PRODUCCIÓN
G6: ALMAZARAS Nº | L6: PRODUCCIÓN
G7: TOTALES | H7: COOPERATIVAS | J7: INDUSTRIALES | L7: TOTALES | M7: COOPERATIVAS | O7: INDUSTRIALES
E8: COMUNIDAD AUTÓNOMA | F8: PROVINCIA | G8: Nº | H8: Nº | I8: % | J8: Nº | K8: % | L8: Toneladas | M8: Toneladas | N8: % | O8: Toneladas | P8: %
E9: ANDALUCÍA | F9: ALMERÍA | G9: 28 | H9: 5 | I9: 0.17857143 | J9: 23 | K9: 0.82142857 | L9: 16130 | M9: 2666 | N9: 0.16528208 | O9: 13464 | P9: 0.83471792
F10: CÁDIZ | G10: 20 | H10: 4 | I10: 0.2 | J10: 16 | K10: 0.8 | L10: 15013 | M10: 11948.9 | N10: 0.79590355 | O10: 3064.1 | P10: 0.20409645
F11: CÓRDOBA | G11: 179 | H11: 70 | I11: 0.39106145 | J11: 109 | K11: 0.60893855 | L11: 246735.4 | M11: 134527.2 | N11: 0.54522861 | O11: 112208.2 | P11: 0.45477139
F12: GRANADA | G12: 104 | H12: 47 | I12: 0.45192308 | J12: 57 | K12: 0.54807692 | L12: 107297.8 | M12: 72882.7 | N12: 0.67925624 | O12: 34415.1 | P12: 0.32074376
F13: HUELVA | G13: 20 | H13: 14 | I13: 0.7 | J13: 6 | K13: 0.3 | L13: 15212.4 | M13: 5826.4 | N13: 0.38300334 | O13: 9386 | P13: 0.61699666
F14: JAÉN | G14: 323 | H14: 179 | I14: 0.55417957 | J14: 144 | K14: 0.44582043 | L14: 389086.1 | M14: 269642.8 | N14: 0.69301576 | O14: 119443.3 | P14: 0.30698424
F15: MÁLAGA | G15: 79 | H15: 41 | I15: 0.51898734 | J15: 38 | K15: 0.48101266 | L15: 59163.6 | M15: 50969.5 | N15: 0.86150099 | O15: 8194.1 | P15: 0.13849901
F16: SEVILLA | G16: 89 | H16: 49 | I16: 0.5505618 | J16: 40 | K16: 0.4494382 | L16: 126002.3 | M16: 83299.2 | N16: 0.66109269 | O16: 42703.1 | P16: 0.33890731
F17: TOTAL CCAA: | G17: 842 | H17: 409 | I17: 0.48574822 | J17: 433 | K17: 0.51425178 | L17: 974640.6 | M17: 631762.7 | N17: 0.64820068 | O17: 342877.9 | P17: 0.35179932
E18: ARAGÓN | F18: HUESCA | G18: 27 | H18: 10 | I18: 0.37037037 | J18: 17 | K18: 0.62962963 | L18: 2175.8 | M18: 654.8 | N18: 0.30094678 | O18: 1521 | P18: 0.69905322
F19: TERUEL | G19: 28 | H19: 14 | I19: 0.5 | J19: 14 | K19: 0.5 | L19: 9289.1 | M19: 4473.7 | N19: 0.48160748 | O19: 4815.4 | P19: 0.51839252
F20: ZARAGOZA | G20: 41 | H20: 24 | I20: 0.58536585 | J20: 17 | K20: 0.41463415 | L20: 5650.1 | M20: 2627.1 | N20: 0.46496522 | O20: 3023 | P20: 0.53503478
F21: TOTAL CCAA: | G21: 96 | H21: 48 | I21: 0.5 | J21: 48 | K21: 0.5 | L21: 17115 | M21: 7755.6 | N21: 0.45314636 | O21: 9359.4 | P21: 0.54685364
E22: BALEARES | F22: BALEARES | G22: 25 | H22: 5 | I22: 0.2 | J22: 20 | K22: 0.8 | L22: 989.6 | M22: 400.8 | N22: 0.40501213 | O22: 588.8 | P22: 0.59498787
F23: TOTAL CCAA: | G23: 25 | H23: 5 | I23: 0.2 | J23: 20 | K23: 0.8 | L23: 989.6 | M23: 400.8 | N23: 0.40501213 | O23: 588.8 | P23: 0.59498787
E24: CANARIAS | F24: LAS PALMAS | G24: 8 | H24: 0 | I24: 0 | J24: 8 | K24: 1 | L24: 15.7 | M24: 0 | N24: 0 | O24: 15.7 | P24: 1
F25: STA. CRUZ DE TENERIFE | G25: 4 | H25: 1 | I25: 0.25 | J25: 3 | K25: 0.75 | L25: 18 | M25: 16.2 | N25: 0.9 | O25: 1.8 | P25: 0.1
F26: TOTAL CCAA: | G26: 12 | H26: 1 | I26: 0.083333333 | J26: 11 | K26: 0.91666667 | L26: 33.7 | M26: 16.2 | N26: 0.48071217 | O26: 17.5 | P26: 0.51928783
E27: CASTILLA-LA MANCHA | F27: ALBACETE | G27: 39 | H27: 14 | I27: 0.35897436 | J27: 25 | K27: 0.64102564 | L27: 17777.5 | M27: 7674.6 | N27: 0.431703 | O27: 10102.9 | P27: 0.568297
F28: CIUDAD REAL | G28: 78 | H28: 43 | I28: 0.55128205 | J28: 35 | K28: 0.44871795 | L28: 69079.3 | M28: 38091.1 | N28: 0.5514112 | O28: 30988.2 | P28: 0.4485888
F29: CUENCA | G29: 26 | H29: 12 | I29: 0.46153846 | J29: 14 | K29: 0.53846154 | L29: 6652.1 | M29: 2908.2 | N29: 0.43718525 | O29: 3743.9 | P29: 0.56281475
F30: GUADALAJARA | G30: 7 | H30: 1 | I30: 0.14285714 | J30: 6 | K30: 0.85714286 | L30: 1941.4 | M30: 31.6 | N30: 0.016276914 | O30: 1909.8 | P30: 0.98372309
F31: TOLEDO | G31: 112 | H31: 57 | I31: 0.50892857 | J31: 55 | K31: 0.49107143 | L31: 43223.4 | M31: 28306.7 | N31: 0.65489295 | O31: 14916.7 | P31: 0.34510705
F32: TOTAL CCAA: | G32: 262 | H32: 127 | I32: 0.48473282 | J32: 135 | K32: 0.51526718 | L32: 138673.7 | M32: 77012.2 | N32: 0.55534827 | O32: 61661.5 | P32: 0.44465173
E33: CASTILLA Y LEÓN | F33: ÁVILA | G33: 11 | H33: 8 | I33: 0.72727273 | J33: 3 | K33: 0.27272727 | L33: 1609.1 | M33: 612.4 | N33: 0.38058542 | O33: 996.7 | P33: 0.61941458
F34: LEÓN | G34: 1 | H34: 0 | I34: 0 | J34: 1 | K34: 1 | L34: 0 | M34: 0 | N34: 0 | O34: 0 | P34: 0
F35: SALAMANCA | G35: 5 | H35: 3 | I35: 0.6 | J35: 2 | K35: 0.4 | L35: 170 | M35: 75 | N35: 0.44117647 | O35: 95 | P35: 0.55882353
F36: SORIA | G36: 1 | H36: 0 | I36: 0 | J36: 1 | K36: 1 | L36: 0.3 | M36: 0 | N36: 0 | O36: 0.3 | P36: 1
F37: OTRAS | G37: 4 | H37: 1 | I37: 0.25 | J37: 3 | K37: 0.75 | L37: 270.4 | M37: 10 | N37: 0.036982249 | O37: 260.4 | P37: 0.96301775
F38: TOTAL CCAA: | G38: 22 | H38: 12 | I38: 0.54545455 | J38: 10 | K38: 0.45454545 | L38: 2049.8 | M38: 697.4 | N38: 0.34022831 | O38: 1352.4 | P38: 0.65977169
E39: CATALUÑA | F39: BARCELONA | G39: 13 | H39: 2 | I39: 0.15384615 | J39: 11 | K39: 0.84615385 | L39: 854.9 | M39: 60 | N39: 0.070183647 | O39: 794.9 | P39: 0.92981635
F40: GIRONA | G40: 13 | H40: 3 | I40: 0.23076923 | J40: 10 | K40: 0.76923077 | L40: 924.2 | M40: 540.5 | N40: 0.58483012 | O40: 383.7 | P40: 0.41516988
F41: LLEIDA | G41: 57 | H41: 26 | I41: 0.45614035 | J41: 31 | K41: 0.54385965 | L41: 11948.9 | M41: 8125 | N41: 0.67997891 | O41: 3823.9 | P41: 0.32002109
F42: TARRAGONA | G42: 88 | H42: 51 | I42: 0.57954545 | J42: 37 | K42: 0.42045455 | L42: 25283.1 | M42: 16414.2 | N42: 0.64921627 | O42: 8868.9 | P42: 0.35078373
F43: TOTAL CCAA: | G43: 171 | H43: 82 | I43: 0.47953216 | J43: 89 | K43: 0.52046784 | L43: 39011.1 | M43: 25139.7 | N43: 0.64442428 | O43: 13871.4 | P43: 0.35557572
E44: EXTREMADURA | F44: BADAJOZ | G44: 92 | H44: 42 | I44: 0.45652174 | J44: 50 | K44: 0.54347826 | L44: 67507 | M44: 45211.3 | N44: 0.66972758 | O44: 22295.7 | P44: 0.33027242
...

Sheet 09_ALMAZ.PROD. POR CAMYTIPO 
B4: 09_ALMAZARAS_PRODUCCIÓN POR CAMPAÑAS Y TIPO
B8: ALMAZARAS COOPERATIVAS
B21: Campaña | C21: 21/22 | D21: 22/23 | E21: 23/24 | F21: 24/25 | G21: 25/26
B22: % Nº Empresas | C22: 49.755302 | D22: 49.89083 | E22: 49.400871 | F22: 49.125683 | G22: 48.332422
B23: % Producción | C23: 64.693101 | D23: 59.039253 | E23: 58.851403 | F23: 63.551506 | G23: 62.888265
B26: ALMAZARAS INDUSTRIALES
B39: Campaña | C39: 21/22 | D39: 22/23 | E39: 23/24 | F39: 24/25 | G39: 25/26
